Workbook

Sheet ESTOQUE BXD2 (2)
A1: ✏️ Manual | B1: ✏️ Manual | C1: ✏️ Manual | D1: ✅ Fórmula | E1: ✅ Fórmula | F1: ✅ Fórmula | G1: ✏️ Manual
A2: Cod.SAP | C2: unidade | D2: Entrada | E2: Saída | F2: Saldo Estoque | G2: ATUALIZAÇÃO
A3: =_xlfn.XLOOKUP(B3,'Entrada de Materiais'!C:C,'Entrada de Materiais'!B:B) -> 4010017 | B3: *ROLAMENTO ESF RIG 6226/C3 SKF | C3: UND | D3: =SUMIFS('Entrada de Materiais'!D:D, 'Entrada de Materiais'!C:C, B3) -> 4 | E3: =SUMIFS('SAIDA DE MATERIAIS'!F:F,'SAIDA DE MATERIAIS'!C:C,B3) -> 2 | F3: =+D3-E3 -> 2
A4: =_xlfn.XLOOKUP(B4,'Entrada de Materiais'!C:C,'Entrada de Materiais'!B:B) -> 5532022 | B4: _CHAVE SECCIONADORA POTENCIA - 160 A | C4: UND | D4: =SUMIFS('Entrada de Materiais'!D:D, 'Entrada de Materiais'!C:C, B4) -> 1 | E4: =SUMIFS('SAIDA DE MATERIAIS'!F:F,'SAIDA DE MATERIAIS'!C:C,B4) -> 0 | F4: =+D4-E4 -> 1
A5: =_xlfn.XLOOKUP(B5,'Entrada de Materiais'!C:C,'Entrada de Materiais'!B:B) -> 5532023 | B5: _CHAVE SECCIONADORA POTENCIA - 250 A | C5: UND | D5: =SUMIFS('Entrada de Materiais'!D:D, 'Entrada de Materiais'!C:C, B5) -> 2 | E5: =SUMIFS('SAIDA DE MATERIAIS'!F:F,'SAIDA DE MATERIAIS'!C:C,B5) -> 0 | F5: =+D5-E5 -> 2
A6: =_xlfn.XLOOKUP(B6,'Entrada de Materiais'!C:C,'Entrada de Materiais'!B:B) -> 5532024 | B6: _CHAVE SECCIONADORA POTENCIA - 400 A | C6: UND | D6: =SUMIFS('Entrada de Materiais'!D:D, 'Entrada de Materiais'!C:C, B6) -> 2 | E6: =SUMIFS('SAIDA DE MATERIAIS'!F:F,'SAIDA DE MATERIAIS'!C:C,B6) -> 0 | F6: =+D6-E6 -> 2
A7: =_xlfn.XLOOKUP(B7,'Entrada de Materiais'!C:C,'Entrada de Materiais'!B:B) -> 5532025 | B7: _CHAVE SECCIONADORA POTENCIA - 630 A | C7: UND | D7: =SUMIFS('Entrada de Materiais'!D:D, 'Entrada de Materiais'!C:C, B7) -> 2 | E7: =SUMIFS('SAIDA DE MATERIAIS'!F:F,'SAIDA DE MATERIAIS'!C:C,B7) -> 0 | F7: =+D7-E7 -> 2
A8: =_xlfn.XLOOKUP(B8,'Entrada de Materiais'!C:C,'Entrada de Materiais'!B:B) -> 5532031 | B8: _CHAVE SECCIONADORA PUNHO 3P 250A C/FUS | C8: UND | D8: =SUMIFS('Entrada de Materiais'!D:D, 'Entrada de Materiais'!C:C, B8) -> 1 | E8: =SUMIFS('SAIDA DE MATERIAIS'!F:F,'SAIDA DE MATERIAIS'!C:C,B8) -> 0 | F8: =+D8-E8 -> 1
A9: =_xlfn.XLOOKUP(B9,'Entrada de Materiais'!C:C,'Entrada de Materiais'!B:B) -> 5028401 | B9: _CONTATOR 3P 220V CA 1NA 80A | C9: UND | D9: =SUMIFS('Entrada de Materiais'!D:D, 'Entrada de Materiais'!C:C, B9) -> 2 | E9: =SUMIFS('SAIDA DE MATERIAIS'!F:F,'SAIDA DE MATERIAIS'!C:C,B9) -> 0 | F9: =+D9-E9 -> 2
A10: =_xlfn.XLOOKUP(B10,'Entrada de Materiais'!C:C,'Entrada de Materiais'!B:B) -> 5029619 | B10: _RELE SOBRECARGA TERMICO REG 95-120A | C10: UND | D10: =SUMIFS('Entrada de Materiais'!D:D, 'Entrada de Materiais'!C:C, B10) -> 1 | E10: =SUMIFS('SAIDA DE MATERIAIS'!F:F,'SAIDA DE MATERIAIS'!C:C,B10) -> 0 | F10: =+D10-E10 -> 1
A11: =_xlfn.XLOOKUP(B11,'Entrada de Materiais'!C:C,'Entrada de Materiais'!B:B) -> #N/A | B11: _TRANSMISSOR PRESSAO AI A1 TIPO G 0-6BAR | C11: UND | D11: =SUMIFS('Entrada de Materiais'!D:D, 'Entrada de Materiais'!C:C, B11) -> 0 | E11: =SUMIFS('SAIDA DE MATERIAIS'!F:F,'SAIDA DE MATERIAIS'!C:C,B11) -> 0 | F11: =+D11-E11 -> 0
A12: =_xlfn.XLOOKUP(B12,'Entrada de Materiais'!C:C,'Entrada de Materiais'!B:B) -> 3009327 | B12: ABRACADEIRA BAP AC GALV 1200MM 33 FUROS | C12: UND | D12: =SUMIFS('Entrada de Materiais'!D:D, 'Entrada de Materiais'!C:C, B12) -> 23 | E12: =SUMIFS('SAIDA DE MATERIAIS'!F:F,'SAIDA DE MATERIAIS'!C:C,B12) -> 1 | F12: =+D12-E12 -> 22
A13: =_xlfn.XLOOKUP(B13,'Entrada de Materiais'!C:C,'Entrada de Materiais'!B:B) -> 3000011 | B13: ABRACADEIRA COP AC 1020 CZ 1POL 25,4MM | C13: UND | D13: =SUMIFS('Entrada de Materiais'!D:D, 'Entrada de Materiais'!C:C, B13) -> 3 | E13: =SUMIFS('SAIDA DE MATERIAIS'!F:F,'SAIDA DE MATERIAIS'!C:C,B13) -> 0 | F13: =+D13-E13 -> 3
A14: =_xlfn.XLOOKUP(B14,'Entrada de Materiais'!C:C,'Entrada de Materiais'!B:B) -> 3000010 | B14: ABRACADEIRA COP AC 1020 NAT 3/4POL | C14: UND | D14: =SUMIFS('Entrada de Materiais'!D:D, 'Entrada de Materiais'!C:C, B14) -> 3 | E14: =SUMIFS('SAIDA DE MATERIAIS'!F:F,'SAIDA DE MATERIAIS'!C:C,B14) -> 0 | F14: =+D14-E14 -> 3
... A97: =_xlfn.XLOOKUP(B97,'Entrada de Materiais'!C:C,'Entrada de Materiais'!B:B) -> 5000800 | B97: BUCHA RED PVC-R AF DE2X1POL | C97: UNID | D97: =SUMIFS('Entrada de Materiais'!D:D, 'Entrada de Materiais'!C:C, B97) -> 15 | E97: =SUMIFS('SAIDA DE MATERIAIS'!F:F,'SAIDA DE MATERIAIS'!C:C,B97) -> 0 | F97: =+D97-E97 -> 15
A98: 5000699 | B98: BUCHA RED PVC-R AF DE3/4X1/2POL | C98: UND | D98: =SUMIFS('Entrada de Materiais'!D:D, 'Entrada de Materiais'!C:C, B98) -> 30 | E98: =SUMIFS('SAIDA DE MATERIAIS'!F:F,'SAIDA DE MATERIAIS'!C:C,B98) -> 4 | F98: =+D98-E98 -> 26
A99: =_xlfn.XLOOKUP(B99,'Entrada de Materiais'!C:C,'Entrada de Materiais'!B:B) -> 5510706 | B99: BUCHA REDUCAO LAT 1/2POL 1/4POL ( MANOMETRO ) | C99: UND | D99: =SUMIFS('Entrada de Materiais'!D:D, 'Entrada de Materiais'!C:C, B99) -> 20 | E99: =SUMIFS('SAIDA DE MATERIAIS'!F:F,'SAIDA DE MATERIAIS'!C:C,B99) -> 0 | F99: =+D99-E99 -> 20
A100: =_xlfn.XLOOKUP(B100,'Entrada de Materiais'!C:C,'Entrada de Materiais'!B:B) -> 5025191 | B100: CABO AUTOMACAO PVC 70GRC PT 4VIAS 26AWG | C100: UND | D100: =SUMIFS('Entrada de Materiais'!D:D, 'Entrada de Materiais'!C:C, B100) -> 500 | E100: =SUMIFS('SAIDA DE MATERIAIS'!F:F,'SAIDA DE MATERIAIS'!C:C,B100) -> 22 | F100: =+D100-E100 -> 478
A101: =_xlfn.XLOOKUP(B101,'Entrada de Materiais'!C:C,'Entrada de Materiais'!B:B) -> 5021081 | B101: CABO COB PP 1KV 3X10MM2 PT | C101: UND | D101: =SUMIFS('Entrada de Materiais'!D:D, 'Entrada de Materiais'!C:C, B101) -> 50 | E101: =SUMIFS('SAIDA DE MATERIAIS'!F:F,'SAIDA DE MATERIAIS'!C:C,B101) -> 50 | F101: =+D101-E101 -> 0
A102: =_xlfn.XLOOKUP(B102,'Entrada de Materiais'!C:C,'Entrada de Materiais'!B:B) -> 5014924 | B102: CABO COB PP 1KV 3X2,5MM2 PT | C102: UND | D102: =SUMIFS('Entrada de Materiais'!D:D, 'Entrada de Materiais'!C:C, B102) -> 555 | E102: =SUMIFS('SAIDA DE MATERIAIS'!F:F,'SAIDA DE MATERIAIS'!C:C,B102) -> 0 | F102: =+D102-E102 -> 555
A103: =_xlfn.XLOOKUP(B103,'Entrada de Materiais'!C:C,'Entrada de Materiais'!B:B) -> 5001053 | B103: CABO COBRE NU TMD CL2A 1X16MM | C103: UND | D103: =SUMIFS('Entrada de Materiais'!D:D, 'Entrada de Materiais'!C:C, B103) -> 350 | E103: =SUMIFS('SAIDA DE MATERIAIS'!F:F,'SAIDA DE MATERIAIS'!C:C,B103) -> 0 | F103: =+D103-E103 -> 350
A104: =_xlfn.XLOOKUP(B104,'Entrada de Materiais'!C:C,'Entrada de Materiais'!B:B) -> 5001073 | B104: CABO ELE PP 450/ 750V 1X4MM | C104: M | D104: =SUMIFS('Entrada de Materiais'!D:D, 'Entrada de Materiais'!C:C, B104) -> 2 | E104: =SUMIFS('SAIDA DE MATERIAIS'!F:F,'SAIDA DE MATERIAIS'!C:C,B104) -> 2 | F104: =+D104-E104 -> 0
A105: =_xlfn.XLOOKUP(B105,'Entrada de Materiais'!C:C,'Entrada de Materiais'!B:B) -> 5027101 | B105: CABO ELET 0,6/1KV 240MM CL4 PT | C105: UND | D105: =SUMIFS('Entrada de Materiais'!D:D, 'Entrada de Materiais'!C:C, B105) -> 26.9 | E105: =SUMIFS('SAIDA DE MATERIAIS'!F:F,'SAIDA DE MATERIAIS'!C:C,B105) -> 0 | F105: =+D105-E105 -> 26.9
A106: =_xlfn.XLOOKUP(B106,'Entrada de Materiais'!C:C,'Entrada de Materiais'!B:B) -> 5017911 | B106: CABO ELET FLEX 0,6/1KV 1 X 4MM2 PT | C106: M | D106: =SUMIFS('Entrada de Materiais'!D:D, 'Entrada de Materiais'!C:C, B106) -> 0 | E106: =SUMIFS('SAIDA DE MATERIAIS'!F:F,'SAIDA DE MATERIAIS'!C:C,B106) -> 0 | F106: =+D106-E106 -> 0
A107: 5015300 | B107: CABO ELET FLEX 0,6/1KV 10MM2 CL5 PT | C107: UND | D107: =SUMIFS('Entrada de Materiais'!D:D, 'Entrada de Materiais'!C:C, B107) -> 300 | E107: =SUMIFS('SAIDA DE MATERIAIS'!F:F,'SAIDA DE MATERIAIS'!C:C,B107) -> 0 | F107: =+D107-E107 -> 300
A108: =_xlfn.XLOOKUP(B108,'Entrada de Materiais'!C:C,'Entrada de Materiais'!B:B) -> 5017979 | B108: CABO ELET FLEX 0,6/1KV 1X25MM2 PT | C108: M | D108: =SUMIFS('Entrada de Materiais'!D:D, 'Entrada de Materiais'!C:C, B108) -> 0 | E108: =SUMIFS('SAIDA DE MATERIAIS'!F:F,'SAIDA DE MATERIAIS'!C:C,B108) -> 0 | F108: =+D108-E108 -> 0
A109: =_xlfn.XLOOKUP(B109,'Entrada de Materiais'!C:C,'Entrada de Materiais'!B:B) -> 5016434 | B109: CABO ELET FLEX 0,6/1KV 3 X 25MM2 PT | C109: M | D109: =SUMIFS('Entrada de Materiais'!D:D, 'Entrada de Materiais'!C:C, B109) -> 4 | E109: =SUMIFS('SAIDA DE MATERIAIS'!F:F,'SAIDA DE MATERIAIS'!C:C,B109) -> 4 | F109: =+D109-E109 -> 0
A110: =_xlfn.XLOOKUP(B110,'Entrada de Materiais'!C:C,'Entrada de Materiais'!B:B) -> 5021333 | B110: CABO ELET FLEX 0,6/1KV 70MM2 CL5 PT | C110: M | D110: =SUMIFS('Entrada de Materiais'!D:D, 'Entrada de Materiais'!C:C, B110) -> 0 | E110: =SUMIFS('SAIDA DE MATERIAIS'!F:F,'SAIDA DE MATERIAIS'!C:C,B110) -> 0 | F110: =+D110-E110 -> 0
A111: =_xlfn.XLOOKUP(B111,'Entrada de Materiais'!C:C,'Entrada de Materiais'!B:B) -> 5019991 | B111: CABO ELET FLEX 0,6/1KV1X185MM2 | C111: M | D111: =SUMIFS('Entrada de Materiais'!D:D, 'Entrada de Materiais'!C:C, B111) -> 800 | E111: =SUMIFS('SAIDA DE MATERIAIS'!F:F,'SAIDA DE MATERIAIS'!C:C,B111) -> 18 | F111: =+D111-E111 -> 782
A112: =_xlfn.XLOOKUP(B112,'Entrada de Materiais'!C:C,'Entrada de Materiais'!B:B) -> 5001146 | B112: CABO ELET FLEX 1 X 16MM2 PT | C112: M | D112: =SUMIFS('Entrada de Materiais'!D:D, 'Entrada de Materiais'!C:C, B112) -> 60 | E112: =SUMIFS('SAIDA DE MATERIAIS'!F:F,'SAIDA DE MATERIAIS'!C:C,B112) -> 60 | F112: =+D112-E112 -> 0
A113: =_xlfn.XLOOKUP(B113,'Entrada de Materiais'!C:C,'Entrada de Materiais'!B:B) -> 5001151 | B113: CABO ELET FLEX 1 X 95MM2 PT | C113: M | D113: =SUMIFS('Entrada de Materiais'!D:D, 'Entrada de Materiais'!C:C, B113) -> 200 | E113: =SUMIFS('SAIDA DE MATERIAIS'!F:F,'SAIDA DE MATERIAIS'!C:C,B113) -> 0 | F113: =+D113-E113 -> 200
A114: =_xlfn.XLOOKUP(B114,'Entrada de Materiais'!C:C,'Entrada de Materiais'!B:B) -> 5018072 | B114: CABO ELET FLEX 450/750V 1MM2 CL4 | C114: M | D114: =SUMIFS('Entrada de Materiais'!D:D, 'Entrada de Materiais'!C:C, B114) -> 900 | E114: =SUMIFS('SAIDA DE MATERIAIS'!F:F,'SAIDA DE MATERIAIS'!C:C,B114) -> 102 | F114: =+D114-E114 -> 798
A115: =_xlfn.XLOOKUP(B115,'Entrada de Materiais'!C:C,'Entrada de Materiais'!B:B) -> 5019778 | B115: CABO ELET FLEX 450/750V 1MM2 CL4 CZ | C115: M | D115: =SUMIFS('Entrada de Materiais'!D:D, 'Entrada de Materiais'!C:C, B115) -> 600 | E115: =SUMIFS('SAIDA DE MATERIAIS'!F:F,'SAIDA DE MATERIAIS'!C:C,B115) -> 0 | F115: =+D115-E115 -> 600
A116: =_xlfn.XLOOKUP(B116,'Entrada de Materiais'!C:C,'Entrada de Materiais'!B:B) -> 5019701 | B116: CABO ELET FLEX 750V 1MM2 PT | C116: M | D116: =SUMIFS('Entrada de Materiais'!D:D, 'Entrada de Materiais'!C:C, B116) -> 0 | E116: =SUMIFS('SAIDA DE MATERIAIS'!F:F,'SAIDA DE MATERIAIS'!C:C,B116) -> 0 | F116: =+D116-E116 -> 0
A117: =_xlfn.XLOOKUP(B117,'Entrada de Materiais'!C:C,'Entrada de Materiais'!B:B) -> 5019782 | B117: CABO ELET FLEX 750V 1MM2 CINZA | C117: M | D117: =SUMIFS('Entrada de Materiais'!D:D, 'Entrada de Materiais'!C:C, B117) -> 0 | E117: =SUMIFS('SAIDA DE MATERIAIS'!F:F,'SAIDA DE MATERIAIS'!C:C,B117) -> 0 | F117: =+D117-E117 -> 0
A118: =_xlfn.XLOOKUP(B118,'Entrada de Materiais'!C:C,'Entrada de Materiais'!B:B) -> 5001357 | B118: CABO ELET FLEX 750V 6MM | C118: M | D118: =SUMIFS('Entrada de Materiais'!D:D, 'Entrada de Materiais'!C:C, B118) -> 0 | E118: =SUMIFS('SAIDA DE MATERIAIS'!F:F,'SAIDA DE MATERIAIS'!C:C,B118) -> 0 | F118: =+D118-E118 -> 0
A119: =_xlfn.XLOOKUP(B119,'Entrada de Materiais'!C:C,'Entrada de Materiais'!B:B) -> 5001074 | B119: CABO ELET PP 450 / 750 V 4 X 6MM2 | C119: M | D119: =SUMIFS('Entrada de Materiais'!D:D, 'Entrada de Materiais'!C:C, B119) -> 85 | E119: =SUMIFS('SAIDA DE MATERIAIS'!F:F,'SAIDA DE MATERIAIS'!C:C,B119) -> 85 | F119: =+D119-E119 -> 0
... A131: =_xlfn.XLOOKUP(B131,'Entrada de Materiais'!C:C,'Entrada de Materiais'!B:B) -> 5025952 | B131: CABO FLEX EPR ATOX 0,6/1KV 1X95MM VD | C131: M | D131: =SUMIFS('Entrada de Materiais'!D:D, 'Entrada de Materiais'!C:C, B131) -> 20 | E131: =SUMIFS('SAIDA DE MATERIAIS'!F:F,'SAIDA DE MATERIAIS'!C:C,B131) -> 0 | F131: =+D131-E131 -> 20
A132: 5025965 | B132: CABO FLEX HEPR ATOX 0,6/1KV 1X16MM2 PT | C132: UND | D132: =SUMIFS('Entrada de Materiais'!D:D, 'Entrada de Materiais'!C:C, B132) -> 300 | E132: =SUMIFS('SAIDA DE MATERIAIS'!F:F,'SAIDA DE MATERIAIS'!C:C,B132) -> 0 | F132: =+D132-E132 -> 300
A133: =_xlfn.XLOOKUP(B133,'Entrada de Materiais'!C:C,'Entrada de Materiais'!B:B) -> 5001373 | B133: CABO FLEXIVEL 1KV 150MM *BOBINA +- | C133: M | D133: =SUMIFS('Entrada de Materiais'!D:D, 'Entrada de Materiais'!C:C, B133) -> 0 | E133: =SUMIFS('SAIDA DE MATERIAIS'!F:F,'SAIDA DE MATERIAIS'!C:C,B133) -> 0 | F133: =+D133-E133 -> 0
...

Sheet Entrada de Materiais
A1: Data | B1: Cód.do Material | C1: Descrição do material | D1: Qntd. | E1: Medida | F1: LOCAL | G1: Recebedor | H1: Observações
B2: 4010017 | C2: *ROLAMENTO ESF RIG 6226/C3 SKF | D2: 4 | E2: UN | J2: ANILHA P/IDENTIFICAÇÃO CABOS 1,5-2,5MM LA
B3: 5532022 | C3: _CHAVE SECCIONADORA POTENCIA - 160 A | D3: 1 | E3: UN | J3: ANILHA P/IDENTIFICAÇÃO CABOS N01
B4: 5532023 | C4: _CHAVE SECCIONADORA POTENCIA - 250 A | D4: 2 | E4: UN | J4: ANILHA P/IDENTIFICAÇÃO CABOS N02
B5: 5532024 | C5: _CHAVE SECCIONADORA POTENCIA - 400 A | D5: 2 | E5: UN | J5: ANILHA P/IDENTIFICAÇÃO CABOS N09
B6: 5532025 | C6: _CHAVE SECCIONADORA POTENCIA - 630 A | D6: 2 | E6: UN
B7: 5532031 | C7: _CHAVE SECCIONADORA PUNHO 3P 250A C/FUS | D7: 1 | E7: UN
B8: 5028401 | C8: _CONTATOR 3P 220V CA 1NA 80A | D8: 2 | E8: UN
B9: 5029619 | C9: _RELE SOBRECARGA TERMICO REG 95-120A | D9: 1 | E9: UN
B10: 3009327 | C10: ABRACADEIRA BAP AC GALV 1200MM 33 FUROS | D10: 23 | E10: UN
B11: 3000011 | C11: ABRACADEIRA COP AC 1020 CZ 1POL 25,4MM | D11: 3 | E11: UN
B12: 3000010 | C12: ABRACADEIRA COP AC 1020 NAT 3/4POL | D12: 3 | E12: UN
B13: 3012931 | C13: ABRACADEIRA COPO AC 1/2POL | D13: 0 | E13: UN
B14: 3008944 | C14: ABRACADEIRA NYLON PT 4,8X200MM 100UN | D14: 20 | E14: UN
B15: 3000136 | C15: ABRACADEIRA PRESSAO LAT 1/4POL 10MM 13MM | D15: 12 | E15: UN
A16: 02.02.2026 | B16: 5019622 | C16: ABRACADEIRA REPARO MONO AI DN50 C300 | D16: 1 | E16: UN
B17: 5000071 | C17: ADAPTADOR CT PVC-S AF BRM DE60MMX2POL | D17: 5 | E17: UN
B18: 5024513 | C18: ADESIVO PLAST INCOLOR P/PVC-S AF 175G | D18: 3 | E18: UN
B19: 5024686 | C19: ADESIVO PLAST INCOLOR P/PVC-S AF 75G | D19: 0 | E19: UN
A20: 30.01.2026 | B20: 3009240 | C20: ADESIVO RESINA EPOXI 16G | D20: 10 | E20: UN
A21: 22.01.2026 | B21: 5506313 | C21: ALICATE AMPERIMETRO DIGITAL 20/200/1000A | D21: 7 | E21: UN
B22: 5024567 | C22: ANEL BORR PBA DN50MM | D22: 3 | E22: UN
B23: 5024565 | C23: ANEL BORR PBA DN75MM | D23: 5 | E23: UN
B24: 4009039 | C24: ANILHA P/ IDENTIF CABOS 0,3-1,5MM2 C | D24: 100 | E24: UN
B25: 4009044 | C25: ANILHA P/ IDENTIF CABOS 0,3-1,5MM2 W | D25: 200 | E25: UN
B26: 4009037 | C26: ANILHA P/ IDENTIF CABOS 1,5-2,5MM2 A | D26: 50 | E26: UN
B27: 4004067 | C27: ANILHA P/ IDENTIFICACAO CABOS NUMERO 1 | D27: 0 | E27: UN
B28: 4004068 | C28: ANILHA P/ IDENTIFICACAO CABOS NUMERO 2 | D28: 50 | E28: UN
B29: 4004075 | C29: ANILHA P/ IDENTIFICACAO CABOS NUMERO 9 | D29: 50 | E29: UN
B30: 5000505 | C30: ANTENA WIRELESS 900MHZ 902-928GHZ | D30: 5 | E30: UN
B31: 4000911 | C31: ARMACAO SECUNDARIA ACO C/ISOLAD 110,5MM | D31: 2 | E31: UN
B32: 3000582 | C32: ARRUELA LIS AC 1020 S/ T 5/16POL | D32: 0 | E32: UN
B33: 3000607 | C33: ARRUELA LIS AI S/ T 5/8POL | D33: 0 | E33: UN
B34: 3000466 | C34: ARRUELA LISA AC 1/2POL | D34: 95 | E34: UN
B35: 3000355 | C35: ARRUELA LISA AC 1020 3/16POL | D35: 0 | E35: UN
B36: 3009549 | C36: ARRUELA LISA AC 3/4POL | D36: 0 | E36: UN
B37: 3000581 | C37: ARRUELA LISA AC1020 3/8POL | D37: 44 | E37: UN
B38: 3000439 | C38: ARRUELA LISA AC1020 5/8POL | D38: 70 | E38: UN
B39: 3000479 | C39: ARRUELA LISA AI 1/4POL | D39: 0 | E39: UN
B40: 5025208 | C40: BANCO CAPACITOR TRIF 220V 7,5KVAR | D40: 1 | E40: UN
...

Sheet Planilha1
A1: 3009327 | B1: ABRACADEIRA BAP AC GALV 1200MM 33 FUROS | D1: 3009327 | E1: ABRACADEIRA BAP AC GALV 1200MM 33 FUROS
A2: 3008944 | B2: ABRACADEIRA NYLON PT 4,8X200MM 100UN | D2: 3008944 | E2: ABRACADEIRA NYLON PT 4,8X200MM 100UN
A3: 3000136 | B3: ABRACADEIRA PRESSAO LAT 1/4POL 10MM 13MM | D3: 3000136 | E3: ABRACADEIRA PRESSAO LAT 1/4POL 10MM 13MM
B4: ABRAÇADEIRA SERRA COPO AL 1" | E4: ABRAÇADEIRA SERRA COPO AL 1"
B5: ABRAÇADEIRA SERRA COPO AL 1/2" | E5: ABRAÇADEIRA SERRA COPO AL 1/2"
B6: ABRAÇADEIRA SERRA COPO AL 3/4" | E6: ABRAÇADEIRA SERRA COPO AL 3/4"
B7: ACOPLAMENTO EFLEX E-112MM | E7: ACOPLAMENTO EFLEX E-148MM
B8: ACOPLAMENTO EFLEX E-148MM | E8: ACOPLAMENTO EFLEX E-168MM
B9: ACOPLAMENTO EFLEX E-168MM | D9: 4006867 | E9: LUVA ACOPLAMENTO 194MM
A10: 4006867 | B10: LUVA ACOPLAMENTO 194MM | D10: 5000071 | E10: ADAPTADOR CT PVC-S AF BRM DE60MMX2POL
A11: 5000071 | B11: ADAPTADOR CT PVC-S AF BRM DE60MMX2POL | D11: 5024686 | E11: ADESIVO PLAST INCOLOR P/PVC-S AF 75G
A12: 5024513 | B12: ADESIVO PLAST INCOLOR P/PVC-S AF 175G | D12: 4004067 | E12: ANILHA P/ IDENTIFICACAO CABOS NUMERO 1
A13: 5024686 | B13: ADESIVO PLAST INCOLOR P/PVC-S AF 75G | E13: ARMAÇÃO EM AÇO REX MONOF. C/ ISOLADO DE LOUÇA
B14: AMPERÍMETRO 96X96 - LINHA TFINTERC. 500/5A | E14: ARRUELA GALV LISA 13/16"
A15: 5024567 | B15: ANEL BORR PBA DN50MM | D15: 3000355 | E15: ARRUELA LISA AC 1020 3/16POL | F15: UN
A16: 5024565 | B16: ANEL BORR PBA DN75MM | D16: 3000607 | E16: ARRUELA LIS AI S/ T 5/8POL | F16: UN
A17: 4009039 | B17: ANILHA P/ IDENTIF CABOS 0,3-1,5MM2 C | D17: 3000582 | E17: ARRUELA LIS AC 1020 S/ T 5/16POL | F17: UN
A18: 4009044 | B18: ANILHA P/ IDENTIF CABOS 0,3-1,5MM2 W | D18: 3000466 | E18: ARRUELA LISA AC 1/2POL | F18: UN
A19: 4009037 | B19: ANILHA P/ IDENTIF CABOS 1,5-2,5MM2 A | D19: 3000479 | E19: ARRUELA LISA AI 1/4POL | F19: UN
A20: 4004067 | B20: ANILHA P/ IDENTIFICACAO CABOS NUMERO 1 | E20: ARRUELA GALV LISA 15/16"
A21: 4004068 | B21: ANILHA P/ IDENTIFICACAO CABOS NUMERO 2 | D21: 3009549 | E21: ARRUELA LISA AC 3/4POL | F21: UN
A22: 4004075 | B22: ANILHA P/ IDENTIFICACAO CABOS NUMERO 9 | D22: 3000581 | E22: ARRUELA LIS AC 1020 S/ T 3/8POL | F22: UN
A23: 5513934 | B23: ANTENA WIRELESS 900MHZ 902-928GHZ | E23: ARRUELA GALV PRESSÃO 3/8"
A24: 4000911 | B24: ARMACAO SECUNDARIA ACO C/ISOLAD 110,5MM | E24: ARRUELA GALV PRESSÃO 1/4"
B25: ARMAÇÃO EM AÇO REX MONOF. C/ ISOLADO DE LOUÇA | E25: ARRUELA GALV PRESSÃO 3/16"
B26: ARRUELA GALV LISA 13/16" | D26: 3000439 | E26: ARRUELA LISA AC1020 5/8POL
A27: 3000355 | B27: ARRUELA LISA AC 1020 3/16POL | D27: 5025208 | E27: BANCO CAPACITOR TRIF 220V 7,5KVAR
A28: 3000607 | B28: =_xlfn.XLOOKUP(A28,'Lista de Materiais'!A:A,'Lista de Materiais'!B:B) -> ARRUELA LIS AI S/ T 5/8POL | D28: 5024701 | E28: BARRA ROSCADA AC 1020 1/2POL UNC 1M
A29: 3000582 | B29: ARRUELA LIS AC 1020 S/ T 5/16POL | E29: BARRA ROSCADA DE AÇO 1/4" X 1000
A30: 3000466 | B30: ARRUELA LISA AC 1/2POL | D30: 5024706 | E30: BARRA ROSCADA AC 1020 3/4POL UNC 1M
A31: 3000479 | B31: ARRUELA LISA AI 1/4POL | D31: 5024711 | E31: BARRA ROSCADA AC 1020 5/8POL UNC 1M
B32: ARRUELA GALV LISA 15/16" | D32: 5024713 | E32: BARRA ROSCADA AC 1020 7/8POL UNC 1M
A33: 3009549 | B33: ARRUELA LISA AC 3/4POL | E33: BARRA ROSCADA DE AÇO 7/16" X 1000
A34: 3000581 | B34: =_xlfn.XLOOKUP(A34,'Lista de Materiais'!A:A,'Lista de Materiais'!B:B) -> ARRUELA LIS AC 1020 S/ T 3/8POL | E34: BASE DE INTERFACE 10A RSZE1S48M 250V PRETO
B35: ARRUELA GALV PRESSÃO 3/8" | E35: BASE UNIPOLAR 300A /690
B36: ARRUELA GALV PRESSÃO 1/4" | D36: 5517135 | E36: BOMBA CENTRIFUGA AG 125L/S 82MCA
B37: ARRUELA GALV PRESSÃO 3/16" | E37: BORNE CONECTOR SAK 2 5MM
A38: 3000439 | B38: =_xlfn.XLOOKUP(A38,'Lista de Materiais'!A:A,'Lista de Materiais'!B:B) -> ARRUELA LISA AC1020 5/8POL | D38: 5503631 | E38: BOTAO COMANDO VD FACE 1NA 1NF
A39: 5025208 | B39: BANCO CAPACITOR TRIF 220V 7,5KVAR | D39: 5503633 | E39: BOTAO COMANDO VM FACE 1NA
A40: 5025255 | B40: BARRA ROSCADA AC 1POL UNC 1M | E40: BOTOEIRA LIGA/DESLIGA SP6019
...

Sheet Ajustes de Saida
A1: Data | B1: Cód.do Material | C1: Descrição do material | D1: CONDIÇÃO | E1: Baixa | F1: Qntd. | G1: Medida | H1: Destino | I1: Solicitante | J1: Responsável pela Saída | K1: Observações | M1: _ARRUELA PRESSAO INOX 304 NAT 3/8''
A2: ANTIGO | B2: 3009327 | C2: ABRACADEIRA BAP AC GALV 1200MM 33 FUROS | E2: FALSE | F2: 79 | G2: =_xlfn.XLOOKUP(B:B,'Lista de Materiais'!A:A,'Lista de Materiais'!C:C) -> UN | H2: AJUSTE | M2: _BARRA ROSCADA ACO CARB GALVAN 7/8''
A3: ANTIGO | C3: ABRACADEIRA COP AC 1020 NAT 3/4POL | E3: FALSE | F3: 44 | G3: =_xlfn.XLOOKUP(B:B,'Lista de Materiais'!A:A,'Lista de Materiais'!C:C) -> #N/A | H3: AJUSTE | M3: _CABO PP FLEXIVEL 2X2,5 06/1KV
A4: ANTIGO | C4: ABRACADEIRA COPO AC 1/2POL | E4: FALSE | F4: 7 | G4: =_xlfn.XLOOKUP(B:B,'Lista de Materiais'!A:A,'Lista de Materiais'!C:C) -> #N/A | H4: AJUSTE | M4: _PAINEL PCP - EXT
A5: ANTIGO | C5: ABRACADEIRA COPO AC 1POL | E5: FALSE | F5: 89 | G5: =_xlfn.XLOOKUP(B:B,'Lista de Materiais'!A:A,'Lista de Materiais'!C:C) -> #N/A | H5: AJUSTE | M5: ABRACADEIRA BAP AC GALV 1200MM 33 FUROS
A6: ANTIGO | B6: 3008944 | C6: ABRACADEIRA NYLON PT 4,8X200MM 100UN | E6: FALSE | F6: 10 | G6: =_xlfn.XLOOKUP(B:B,'Lista de Materiais'!A:A,'Lista de Materiais'!C:C) -> UN | H6: AJUSTE | M6: ABRACADEIRA COP AC 1020 NAT 3/4POL
A7: ANTIGO | B7: 3000136 | C7: ABRACADEIRA PRESSAO LAT 1/4POL 10MM 13MM | E7: FALSE | F7: 18 | G7: =_xlfn.XLOOKUP(B:B,'Lista de Materiais'!A:A,'Lista de Materiais'!C:C) -> UN | H7: AJUSTE | M7: ABRACADEIRA COPO AC 1/2POL
A8: ANTIGO | B8: 4006867 | C8: LUVA ACOPLAMENTO 194MM | E8: FALSE | F8: 2 | G8: =_xlfn.XLOOKUP(B:B,'Lista de Materiais'!A:A,'Lista de Materiais'!C:C) -> UN | H8: AJUSTE | M8: ABRACADEIRA COPO AC 1POL
A9: ANTIGO | B9: 5000071 | C9: ADAPTADOR CT PVC-S AF BRM DE60MMX2POL | E9: FALSE | F9: 5 | G9: =_xlfn.XLOOKUP(B:B,'Lista de Materiais'!A:A,'Lista de Materiais'!C:C) -> UN | H9: AJUSTE | M9: ABRACADEIRA NYLON PT 4,8X200MM 100UN
A10: ANTIGO | B10: 5024686 | C10: ADESIVO PLAST INCOLOR P/PVC-S AF 75G | E10: FALSE | F10: 2 | G10: =_xlfn.XLOOKUP(B:B,'Lista de Materiais'!A:A,'Lista de Materiais'!C:C) -> #N/A | H10: AJUSTE | M10: ABRACADEIRA PRESSAO LAT 1/4POL 10MM 13MM
A11: ANTIGO | B11: 4004067 | C11: ANILHA P/ IDENTIFICACAO CABOS NUMERO 1 | E11: FALSE | F11: 60 | G11: =_xlfn.XLOOKUP(B:B,'Lista de Materiais'!A:A,'Lista de Materiais'!C:C) -> UN | H11: AJUSTE | M11: ADAPTADOR CT PVC-S AF BRM DE60MMX2POL
A12: ANTIGO | C12: ARMACAO SECUNDARIA ACO C/ISOLAD 110,5MM | E12: FALSE | F12: 5 | G12: =_xlfn.XLOOKUP(B:B,'Lista de Materiais'!A:A,'Lista de Materiais'!C:C) -> #N/A | H12: AJUSTE | M12: ADESIVO PLAST INCOLOR P/PVC-S AF 175G
A13: ANTIGO | C13: ARRUELA GALV LISA 13/16" | E13: FALSE | F13: 41 | G13: =_xlfn.XLOOKUP(B:B,'Lista de Materiais'!A:A,'Lista de Materiais'!C:C) -> #N/A | H13: AJUSTE | M13: ADESIVO PLAST INCOLOR P/PVC-S AF 75G
A14: ANTIGO | C14: ARRUELA GALV LISA 15/16" | E14: FALSE | F14: 34 | G14: =_xlfn.XLOOKUP(B:B,'Lista de Materiais'!A:A,'Lista de Materiais'!C:C) -> #N/A | H14: AJUSTE | M14: AMPERÍMETRO 96X96 - LINHA TFINTERC. 500/5A
A15: ANTIGO | C15: ARRUELA LISA AC1020 3/8POL | E15: FALSE | F15: 240 | G15: =_xlfn.XLOOKUP(B:B,'Lista de Materiais'!A:A,'Lista de Materiais'!C:C) -> #N/A | H15: AJUSTE | M15: ANEL BORR PBA DN50MM
A16: ANTIGO | C16: ARRUELA LISA AI 1/4POL | E16: FALSE | F16: 666 | G16: =_xlfn.XLOOKUP(B:B,'Lista de Materiais'!A:A,'Lista de Materiais'!C:C) -> #N/A | H16: AJUSTE | M16: ANEL BORR PBA DN75MM
A17: ANTIGO | C17: ARRUELA LISA AC 1020 3/16POL | E17: FALSE | F17: 114 | G17: =_xlfn.XLOOKUP(B:B,'Lista de Materiais'!A:A,'Lista de Materiais'!C:C) -> #N/A | H17: AJUSTE | M17: ANILHA P/ IDENTIF CABOS 0,3-1,5MM2 C
A18: ANTIGO | B18: 3000582 | C18: ARRUELA LIS AC 1020 S/ T 5/16POL | E18: FALSE | F18: 61 | G18: =_xlfn.XLOOKUP(B:B,'Lista de Materiais'!A:A,'Lista de Materiais'!C:C) -> #N/A | H18: AJUSTE | M18: ANILHA P/ IDENTIF CABOS 0,3-1,5MM2 W
A19: ANTIGO | B19: 3000607 | C19: ARRUELA LIS AI S/ T 5/8POL | E19: FALSE | F19: 83 | G19: =_xlfn.XLOOKUP(B:B,'Lista de Materiais'!A:A,'Lista de Materiais'!C:C) -> UN | H19: AJUSTE | M19: ANILHA P/ IDENTIF CABOS 1,5-2,5MM2 A
A20: ANTIGO | B20: 3000466 | C20: ARRUELA LISA AC 1/2POL | E20: FALSE | F20: 132 | G20: =_xlfn.XLOOKUP(B:B,'Lista de Materiais'!A:A,'Lista de Materiais'!C:C) -> #N/A | H20: AJUSTE | M20: ANILHA P/ IDENTIFICACAO CABOS NUMERO 1
A21: ANTIGO | B21: 3000355 | C21: ARRUELA LISA AC 1020 3/16POL | E21: FALSE | F21: 379 | G21: =_xlfn.XLOOKUP(B:B,'Lista de Materiais'!A:A,'Lista de Materiais'!C:C) -> #N/A | H21: AJUSTE | M21: ANILHA P/ IDENTIFICACAO CABOS NUMERO 2
A22: ANTIGO | B22: 3000439 | C22: ARRUELA LISA AC1020 5/8POL | E22: FALSE | F22: 6 | G22: =_xlfn.XLOOKUP(B:B,'Lista de Materiais'!A:A,'Lista de Materiais'!C:C) -> UN | H22: AJUSTE | M22: ANILHA P/ IDENTIFICACAO CABOS NUMERO 9
A23: ANTIGO | B23: 3009549 | C23: ARRUELA LISA AC 3/4POL | E23: FALSE | F23: 11 | G23: =_xlfn.XLOOKUP(B:B,'Lista de Materiais'!A:A,'Lista de Materiais'!C:C) -> #N/A | H23: AJUSTE | M23: ANTENA WIRELESS 900MHZ 902-928GHZ
A24: ANTIGO | B24: 3000581 | C24: ARRUELA LISA AC1020 3/8POL | E24: FALSE | F24: 333 | G24: =_xlfn.XLOOKUP(B:B,'Lista de Materiais'!A:A,'Lista de Materiais'!C:C) -> UN | H24: AJUSTE | M24: ARMACAO SECUNDARIA ACO C/ISOLAD 110,5MM
A25: ANTIGO | B25: 3000479 | C25: ARRUELA LISA AI 1/4POL | E25: FALSE | F25: 608 | G25: =_xlfn.XLOOKUP(B:B,'Lista de Materiais'!A:A,'Lista de Materiais'!C:C) -> #N/A | H25: AJUSTE | M25: ARRUELA GALV PRESSÃO 1/4"
A26: ANTIGO | B26: 5025208 | C26: BANCO CAPACITOR TRIF 220V 7,5KVAR | E26: FALSE | F26: 7 | G26: =_xlfn.XLOOKUP(B:B,'Lista de Materiais'!A:A,'Lista de Materiais'!C:C) -> #N/A | H26: AJUSTE | M26: ARRUELA GALV PRESSÃO 3/16"
A27: ANTIGO | B27: 5024701 | C27: BARRA ROSCADA AC 1020 1/2POL UNC 1M | E27: FALSE | F27: 10 | G27: =_xlfn.XLOOKUP(B:B,'Lista de Materiais'!A:A,'Lista de Materiais'!C:C) -> UN | H27: AJUSTE | M27: ARRUELA LIS AC 1020 S/ T 5/16POL
A28: ANTIGO | C28: BARRA ROSCADA AC 1020 1/4POL UNC 1M | E28: FALSE | F28: 22 | G28: =_xlfn.XLOOKUP(B:B,'Lista de Materiais'!A:A,'Lista de Materiais'!C:C) -> #N/A | H28: AJUSTE | M28: ARRUELA LIS AI S/ T 5/8POL
A29: ANTIGO | B29: 5024706 | C29: BARRA ROSCADA AC 1020 3/4POL UNC 1M | E29: FALSE | F29: 6 | G29: =_xlfn.XLOOKUP(B:B,'Lista de Materiais'!A:A,'Lista de Materiais'!C:C) -> UN | H29: AJUSTE | M29: ARRUELA LISA AC 1/2POL
A30: ANTIGO | B30: 5024711 | C30: BARRA ROSCADA AC 1020 5/8POL UNC 1M | E30: FALSE | F30: 19 | G30: =_xlfn.XLOOKUP(B:B,'Lista de Materiais'!A:A,'Lista de Materiais'!C:C) -> UN | H30: AJUSTE | M30: ARRUELA LISA AC 1020 3/16POL
A31: ANTIGO | B31: 5024713 | C31: BARRA ROSCADA AC 1020 7/8POL UNC 1M | E31: FALSE | F31: 4 | G31: =_xlfn.XLOOKUP(B:B,'Lista de Materiais'!A:A,'Lista de Materiais'!C:C) -> UN | H31: AJUSTE | M31: ARRUELA LISA AC 3/4POL
A32: ANTIGO | C32: BASE DE INTERFACE 10A RSZE1S48M 250V PRETO | E32: FALSE | F32: 117 | G32: =_xlfn.XLOOKUP(B:B,'Lista de Materiais'!A:A,'Lista de Materiais'!C:C) -> #N/A | H32: AJUSTE | M32: ARRUELA LISA AC1020 5/8POL
A33: ANTIGO | C33: BASE UNIPOLAR 300A /690 | E33: FALSE | F33: 5 | G33: =_xlfn.XLOOKUP(B:B,'Lista de Materiais'!A:A,'Lista de Materiais'!C:C) -> #N/A | H33: AJUSTE | M33: ARRUELA LISA AI 1/4POL
A34: ANTIGO | B34: 5517135 | C34: BOMBA CENTRIFUGA AG 125L/S 82MCA | E34: FALSE | F34: 1 | G34: =_xlfn.XLOOKUP(B:B,'Lista de Materiais'!A:A,'Lista de Materiais'!C:C) -> UN | H34: AJUSTE | M34: BANCO CAPACITOR TRIF 220V 7,5KVAR
A35: ANTIGO | C35: BORNE CONECTOR SAK 2 5MM | E35: FALSE | F35: 100 | G35: =_xlfn.XLOOKUP(B:B,'Lista de Materiais'!A:A,'Lista de Materiais'!C:C) -> #N/A | H35: AJUSTE | M35: BARRA ROSCADA AC 1020 1/2POL UNC 1M
A36: ANTIGO | B36: 5503631 | C36: BOTAO COMANDO VD FACE 1NA 1NF | E36: FALSE | F36: 6 | G36: =_xlfn.XLOOKUP(B:B,'Lista de Materiais'!A:A,'Lista de Materiais'!C:C) -> #N/A | H36: AJUSTE | M36: BARRA ROSCADA AC 1020 1/4POL UNC 1M
A37: ANTIGO | B37: 5503633 | C37: BOTAO COMANDO VM FACE 1NA | E37: FALSE | F37: 6 | G37: =_xlfn.XLOOKUP(B:B,'Lista de Materiais'!A:A,'Lista de Materiais'!C:C) -> #N/A | H37: AJUSTE | M37: BARRA ROSCADA AC 1020 3/4POL UNC 1M
A38: ANTIGO | B38: 5508637 | C38: BOTOEIRA MONT ABS 2 BOT | E38: FALSE | F38: 2 | G38: =_xlfn.XLOOKUP(B:B,'Lista de Materiais'!A:A,'Lista de Materiais'!C:C) -> UN | H38: AJUSTE | M38: BARRA ROSCADA AC 1020 5/8POL UNC 1M
A39: ANTIGO | B39: 5019127 | C39: BOX RETO ELETRODUTO AL D1POL | E39: FALSE | F39: 137 | G39: =_xlfn.XLOOKUP(B:B,'Lista de Materiais'!A:A,'Lista de Materiais'!C:C) -> UN | H39: AJUSTE | M39: BARRA ROSCADA AC 1020 7/8POL UNC 1M
A40: ANTIGO | B40: 5025311 | C40: BOX RETO ELETRODUTO AL D2 | E40: FALSE | F40: 8 | G40: =_xlfn.XLOOKUP(B:B,'Lista de Materiais'!A:A,'Lista de Materiais'!C:C) -> #N/A | H40: AJUSTE | M40: BARRA ROSCADA AC 1POL UNC 1M
...

Sheet SAIDA DE MATERIAIS
A1: Data | B1: Cód.do Material | C1: Descrição do material | D1: CONDIÇÃO | E1: Baixa | F1: Qntd. | G1: Medida | H1: Destino | I1: Solicitante | J1: Responsável pela Saída | K1: Observações
A2: 02.03.2026 | B2: 5517146 | C2: TRANSMISSOR PRES COMP M12 IP67 100MCA | E2: TRUE | F2: 1 | G2: UN | H2: BOOSTER BRASILIA | I2: ANDREW | J2: ANDREW
A3: 02.03.2026 | B3: 2002904 | C3: LIXA FERRO GR100 225X275MM 50UNID | E3: TRUE | F3: 1 | G3: UN | H3: ELEVATORIA GRAMA | I3: DIEGO / MARCIO | J3: DIEGO
A4: 02.03.2026 | B4: 4007458 | C4: =_xlfn.XLOOKUP(B4,'Lista de Materiais'!A:A,'Lista de Materiais'!B:B) -> SELO MECANICO TS-P 1.3/4POL | E4: TRUE | F4: 1 | G4: UN | H4: ELEVATORIA GRAMA | I4: DIEGO / MARCIO | J4: DIEGO
A5: 04.03.2026 | B5: 5006218 | C5: LAMINA DE SERRA STARRET 1232 | E5: TRUE | F5: 2 | G5: UN | H5: BASE NOVA IGUAÇU | I5: CLOVIS | J5: MARCIOMC
A6: 04.03.2026 | B6: 5024639 | C6: FITA VEDA ROSCA BR 18MM ROL 50M | E6: TRUE | F6: 4 | G6: UN | H6: BASE NOVA IGUAÇU | I6: CLOVIS / VAGNER | J6: MARCIOMC
A7: 05.03.2026 | B7: 3000808 | C7: BUCHA FIXAÇÃO NYLON S10 | E7: TRUE | F7: 4 | G7: UN | H7: BOOSTER JK | I7: CLOVIS / VAGNER | J7: MARCIOMC | K7: PARA DO GUANDU
A8: 05.03.2026 | B8: 3000807 | C8: BUCHA FIXAÇÃO NYLON S12 | E8: TRUE | F8: 4 | G8: UN | H8: BOOSTER JK | I8: CLOVIS / VAGNER | J8: MARCIOMC | K8: PARA DO GUANDU
A9: 05.03.2026 | B9: 2002904 | C9: LIXA FERRO GR100 225X275MM 50UNID | E9: TRUE | F9: 2 | G9: UN | H9: BOOSTER JK | I9: CLOVIS / VAGNER | J9: MARCIOMC | K9: PARA DO GUANDU
A10: 05.03.2026 | B10: 3009924 | C10: PANO LIMPEZA RETALHO COST EQUIP OL/GX SACO C/ 25KG | E10: TRUE | F10: 1 | G10: KG | H10: BOOSTER JK | I10: CLOVIS / VAGNER | J10: MARCIOMC | K10: PARA DO GUANDU
A11: 05.03.2026 | B11: 5504610 | C11: TERMINAL ELET COMP 185MM2 | E11: TRUE | F11: 3 | G11: UN | H11: BOOSTER JK | I11: CLOVIS / VAGNER | J11: MARCIOMC | K11: PARA DO GUANDU
A12: 05.03.2026 | B12: 4007729 | C12: ROLAMENTO ESF RIG 6312 - 2Z/C3 | E12: TRUE | F12: 2 | G12: UN | H12: BOOSTER JK | I12: CLOVIS / VAGNER | J12: MARCIOMC | K12: PARA DO GUANDU
A13: 05.03.2026 | B13: 5024527 | C13: FITA ISOL PR 750V 19MM ROL 20M P44 | E13: TRUE | F13: 1 | G13: UN | H13: BOOSTER JK | I13: CLOVIS / VAGNER | J13: MARCIOMC | K13: PARA DO GUANDU
A14: 05.03.2026 | B14: 5534866 | C14: FITA AUTA TENSÃO FUSÃO19MMX10MTS | E14: TRUE | F14: 1 | G14: UN | H14: BOOSTER JK | I14: CLOVIS / VAGNER | J14: MARCIOMC | K14: PARA DO GUANDU
A15: 05.03.2026 | B15: 5504610 | C15: TERMINAL ELET COMP 185MM2 | E15: TRUE | F15: 6 | G15: UN | H15: BOOSTER JK | I15: CLOVIS / VAGNER | J15: MARCIOMC | K15: PARA DO GUANDU
A16: 05.03.2026 | B16: 5019991 | C16: CABO ELET FLEX 0,6/1KV1X185MM2 | E16: TRUE | F16: 18 | G16: M | H16: BOOSTER JK | I16: CLOVIS / VAGNER | J16: MARCIOMC | K16: PARA DO GUANDU
A17: 06.03.2026 | B17: 4007458 | C17: SELO MECÂNICO TS-P 1.3/4" | E17: TRUE | F17: 1 | G17: UN | H17: ELEVATORIA DA SERRA | I17: PAULO SERGIO /ERICK | J17: MARCIOMC
A18: 06.03.2026 | B18: 4007727 | C18: ROLAMENTO ESF RIG 6309-2Z/C3 SKF | E18: TRUE | F18: 1 | G18: UN | H18: ELEVATORIA DA SERRA | I18: PAULO SERGIO /ERICK | J18: MARCIOMC
A19: 06.03.2026 | B19: 4003682 | C19: ROLAMENTO ESF RIG 6209-2Z SKF | E19: TRUE | F19: 1 | G19: UN | H19: ELEVATORIA DA SERRA | I19: PAULO SERGIO /ERICK | J19: MARCIOMC
A20: 06.03.2026 | B20: 3009592 | C20: COLA MULTIUSO SPRAY 330G | E20: TRUE | F20: 2 | G20: UN | H20: BOOSTER JK | I20: CLOVIS | J20: MARCIOMC | K20: PARA DO GUANDU
A21: 06.03.2026 | B21: 4003682 | C21: ROLAMENTO ESF RIG 6209-2Z SKF | E21: TRUE | F21: 2 | G21: UN | H21: AJUSTE | J21: DAVI
A22: 02.03.2026 | B22: 5000738 | C22: BUCHA RED GALV RMF BSP D1X3/4 | D22: ATUALIZAÇÃO 02.03.26 | E22: TRUE | F22: 1 | G22: UN | H22: AJUSTE | J22: ATUALIZAÇÃO 02.03.26
A23: 02.03.2026 | B23: 5006963 | C23: LUVA RED GALV RF BSP D3/4X1/2 | D23: ATUALIZAÇÃO 02.03.26 | E23: TRUE | F23: 5 | G23: UN | H23: AJUSTE | J23: ATUALIZAÇÃO 02.03.26
A24: 02.03.2026 | B24: 5006901 | C24: LUVA RED GALV RF BSP D1.1/2X1 | D24: ATUALIZAÇÃO 02.03.26 | E24: TRUE | F24: 1 | G24: UN | H24: AJUSTE | J24: ATUALIZAÇÃO 02.03.26
A25: 02.03.2026 | B25: 5018313 | C25: NIPLE GALV RM BSP D1 | D25: ATUALIZAÇÃO 02.03.26 | E25: TRUE | F25: 2 | G25: UN | H25: AJUSTE | J25: ATUALIZAÇÃO 02.03.26
A26: 06.03.2026 | B26: 5504841 | C26: ELETRODUTO FLEXIVEL CORRUG PVC 2POL | E26: TRUE | F26: 30 | G26: M | H26: VILA RORAIMA II | I26: VAGNER | J26: MARCIOMC | K26: SERÁ MEDIDO NO LOCAL
A27: 06.03.2026 | B27: 5001146 | C27: CABO ELET FLEX 1 X 16MM2 PT | E27: TRUE | F27: 30 | G27: M | H27: VILA RORAIMA II | I27: VAGNER | J27: MARCIOMC
A28: 06.03.2026 | B28: 5504365 | C28: CURVA ELETRODUTO PVC 90X2" | E28: TRUE | F28: 2 | G28: UN | H28: VILA RORAIMA II | I28: VAGNER | J28: MARCIOMC
A29: 06.03.2026 | B29: 3008277 | C29: BUCHA ELETRODUTO AL 2POL | E29: TRUE | F29: 2 | G29: UN | H29: VILA RORAIMA II | I29: VAGNER | J29: MARCIOMC
A30: 06.03.2026 | B30: 3000328 | C30: ARRUELA ELETROD RED AL NPT 2POL | E30: TRUE | F30: 2 | G30: UN | H30: VILA RORAIMA II | I30: VAGNER | J30: MARCIOMC
A31: 06.03.2026 | B31: 5004508 | C31: DISJUNTOR MINI 3P 220 3XC80A | E31: TRUE | F31: 1 | G31: UN | H31: VILA RORAIMA II | I31: VAGNER | J31: MARCIOMC
A32: 06.03.2026 | B32: 3009327 | C32: ABRACADEIRA BAP AC GALV 1200MM 33 FUROS | E32: TRUE | F32: 1 | G32: UN | H32: VILA RORAIMA II | I32: VAGNER | J32: MARCIOMC
A33: 09.03.2026 | B33: 5534866 | C33: FITA AUTA TENSÃO FUSÃO19MMX10MTS | E33: TRUE | F33: 1 | G33: UN | H33: BOOSTER NILOPOLIS | I33: ERICK | J33: MARCIOMC
A34: 09.03.2026 | B34: 4007732 | C34: ROLAMENTO ESF RIG 6316 2Z C3 SKF | E34: TRUE | F34: 1 | G34: UN | H34: BOOSTER NILOPOLIS | I34: CLOVIS / VINICIUS | J34: MARCIOMC
A35: 09.03.2026 | B35: 4003557 | C35: ROLAMENTO ESF RIG 6319 C3 SKF | E35: TRUE | F35: 1 | G35: UN | H35: BOOSTER NILOPOLIS | I35: CLOVIS / VINICIUS | J35: MARCIOMC
A36: 09.03.2026 | B36: 5534866 | C36: FITA AUTA TENSÃO FUSÃO19MMX10MTS | E36: TRUE | F36: 2 | G36: UN | H36: AJUSTE
A37: 09.03.2026 | B37: 5024527 | C37: FITA ISOL PR 750V 19MM ROL 20M P44 | E37: TRUE | F37: 8 | G37: UN | H37: AJUSTE
A38: 09.03.2026 | B38: 5024531 | C38: FITA ISOLANTE AM 750V 18MM ROL 20M | E38: TRUE | F38: 2 | G38: UN | H38: AJUSTE
A39: 09.03.2026 | B39: 5001146 | C39: CABO ELET FLEX 1 X 16MM2 PT | E39: TRUE | F39: 30 | G39: M | H39: AJUSTE
A40: 10.03.2026 | B40: 5004525 | C40: DISJUNTOR MINI 3P 415VCA 3X125A | E40: TRUE | F40: 1 | G40: UN | H40: BXD1 - ELEVATORIA MANOEL GAMA II | I40: WENDREL / BRUNO | J40: MARCIOMC
...

Sheet Lista de Materiais
A2: Material | B2: TxtBreveMaterial | C2: UMB | G2: Teste
A3: 3000087 | B3: *ABRACADEIRA MANG AC 1020 150MM | C3: UN | M3: ='Lista de Materiais'!B5430 -> _TRANSMISSOR PRE COMP BLUET M12 IP67
A4: 3000092 | B4: *ABRACADEIRA MANG AC 1020 150MM | C4: UN
A5: 3012505 | B5: *ADESIVO EPOXI BICOMP LIQ 46G | C5: UN
A6: 3012506 | B6: *ADESIVO EPOXI BICOMP LIQ 46G | C6: UN
A7: 4000024 | B7: *ADITIVO LIQUIDO EMBALAGEM 200ML | C7: UN
A8: 4000022 | B8: *ADITIVO LIQUIDO EMBALAGEM 200ML | C8: UN
A9: 4000026 | B9: *ADITIVO LIQUIDO EMBALAGEM 200ML | C9: UN
A10: 4000029 | B10: *ADITIVO LIQUIDO EMBALAGEM 500ML | C10: UN
A11: 4000025 | B11: *ADITIVO LIQUIDO EMBALAGEM 500ML | C11: UN
A12: 4000027 | B12: *ADITIVO LIQUIDO EMBALAGEM 500ML | C12: UN
A13: 4004363 | B13: *AMORTECEDOR VEICULOS LEVES | C13: UN
A14: 4004987 | B14: *BANDEJA SUSPENSAO VEICULOS LEVES | C14: UN
A15: 4006025 | B15: *BIELA VEICULOS LEVES | C15: UN
... A56512: 1500235 | B56512: ZINCO ZINCOVER 5 PP 20ML HACH 100UN | C56512: UN
A56513: SEM | C56513: UN

Sheet ELEVATÓRIAS BXD2
A1: TIPO | B1: ELEVATORIA | C1: CADEADOS PADRÃO | D1: QTDD | E1: ROLAMENTO MOTOR | F1: ROLAMENTO BOMBA | G1: B. ACOPLAMENTO | H1: GAXETA | I1: SELO MECÃNICO | J1: DATA DA TROCA
B2: ALTO MILITÃO | C2: SIM | D2: 2
B3: ADOLFO BERGAMINI | C3: NÃO
B4: AMAURI GUIMARAES
A5: ABRIGADA | B5: ANGELA MARIA | E5: 6203 ZZ C3 | I5: 5/8" | J5: 22.01.26
A6: ABRIGADA | B6: ANTONIO VALDIGEM | C6: SIM | D6: 1 | I6: 1.1/8" | J6: 29.01.26
A7: ABRIGADA | B7: ASSEMBLEIA | C7: SIM | D7: 1
A8: ABRIGADA | B8: BELO HORIZONTE | C8: SIM | D8: 1
A9: ABRIGADA | B9: BURITI | E9: 6307/6206
A10: ABRIGADA | B10: CAIÇARA | C10: SIM | D10: 1 | E10: 6309/6209
B11: PRAÇA DA BÍBLIA | E11: 6309/6207
A12: ABRIGADA | B12: CAIXA VELHA | C12: SIM | D12: 1
B13: CANADENSE
A14: ABRIGADA | B14: CAONZE | C14: SIM | D14: 1
A15: ABRIGADA | B15: CARAMUJOS | C15: SIM | D15: 1
A16: ABRIGADA | B16: CARLOS SAMPAIO | C16: SIM | D16: 1
B17: CEFET
A18: ABRIGADA | B18: CHATUBA | C18: SIM | D18: 1
A19: ABRIGADA | B19: CITROPOLIS | C19: SIM | D19: 1 | E19: 6309 | F19: 6207 | J19: 29.04.2026
A20: ABRIGADA | B20: CLUBE 34 | C20: SIM | D20: 1
A21: ABRIGADA | B21: DA SERRA | C21: SIM | D21: 1 | E21: 6309Z2/C3 | F21: 6209Z2/C3 | I21: 1.3/4" | J21: 05.03.2026
A22: ABRIGADA | B22: DANON | C22: SIM | D22: 1
A23: ABRIGADA | B23: DAS ROSAS
B24: DINAMARCO REIS
A25: ABRIGADA | B25: DIVINO | C25: SIM | D25: 1
A26: ABRIGADA | B26: EDNA
A27: ABRIGADA | B27: EDUARDO CELIDÔNIO | C27: SIM | D27: 1
A28: ABRIGADA | B28: EEAT BOOSTER AUSTIN G1/G2/G3 | C28: SIM | D28: 4
A29: ABRIGADA | B29: EEAT BOOSTER CABUÇU ALTO | C29: SIM | D29: 1 | E29: 6312 / 6212 (G1 G2 G3 ) | F29: 6309/6309 | G29: 128 | H29: 1/2" | J29: 27.03.2026
A30: ABRIGADA | B30: EEAT BOOSTER CABUÇU BAIXO | C30: SIM | D30: 5 | E30: 6309 C3 | F30: 6309 C3
A31: ABRIGADA | B31: EEAT BOOSTER ENG.PEDREIRA G1/G2 | C31: SIM | D31: 5 | E31: 6311 | G31: 195 | H31: 1/2" | J31: 23.03.26
A32: ABRIGADA | B32: EEAT BOOSTER BRASÍLIA | C32: SIM | D32: 2 | E32: 6313 ZZ C3 | G32: 214
A33: ABRIGADA | B33: EEAT BOOSTER JK G1/G2/G3/G4 | C33: SIM | D33: 2 | E33: G3 /G4 6319 6316 | F33: G3/G4 6411 / G1/G2 6312 | G33: G3/G4 168 | H33: 1/2" 9/16" | J33: 45509
A34: ABRIGADA | B34: EEAT BOOSTER POSSE G1/G2/G3/G4 | C34: SIM | D34: 2 | F34: G4/G2 6311 / 6311 | H34: 1/2"
A35: ABRIGADA | B35: EEAT CABUCU ALTO G1/G2/G3 | C35: SIM | D35: 2 | H35: 1/2"
A36: ABRIGADA | B36: EEAT MESQUITA G1/G2 | C36: SIM | D36: 2 | I36: 1.3/4" | J36: 26.11.25
A37: ABRIGADA | B37: EEAT-BOOSTER NILOPOLIS G1/G2/G3 | C37: SIM | D37: 2 | E37: G1/G2/G3 6319 | F37: G1/G2/G3 6316 | G37: G1/194 | H37: 1/2" | J37: 45509
A38: ABRIGADA | B38: EEE LAGOINHA 1 | C38: SIM | D38: 2 | E38: 6309 /6209
A39: ABRIGADA | B39: EEE LAGOINNHA 2 | C39: SIM | D39: 2 | E39: 6309 /6209
B40: BVOLANTE TÓQUIO | C40: SIM | D40: 1 | E40: 6308/6207
...

Sheet Saidas até 28.02.2026
A1: Data | B1: Cód.do Material | C1: Descrição do material | D1: CONDIÇÃO | E1: Baixa | F1: Qntd. | G1: Medida | H1: Destino | I1: Solicitante | J1: Responsável pela Saída | K1: Observações
A2: 15.09.25 | B2: 5004372 | C2: DISJUNTOR MINI 3P 380V 63A 54MM | E2: TRUE | F2: 1 | G2: =_xlfn.XLOOKUP(B:B,'Lista de Materiais'!A:A,'Lista de Materiais'!C:C) -> UN | H2: BXD1 ELEVATÓRIA PINHEIRO MACHADO | I2: WENDREL/RODRIGO | J2: MÁRCIOMC
A3: 15.09.25 | B3: 5006526 | C3: LUVA RED PVC-R AF RF 1X3/4" | E3: TRUE | F3: 1 | G3: =_xlfn.XLOOKUP(B:B,'Lista de Materiais'!A:A,'Lista de Materiais'!C:C) -> UN | H3: BXD2 ELEVATÓRIA ANGELA MARIA | I3: ALEXSANDRO | J3: MÁRCIOMC
A4: 15.09.25 | B4: 5024639 | C4: FITA VEDA ROSCA BR 18MM ROL 50M | E4: TRUE | F4: 1 | G4: =_xlfn.XLOOKUP(B:B,'Lista de Materiais'!A:A,'Lista de Materiais'!C:C) -> UN | H4: BXD2 ELEVATÓRIA ANGELA MARIA | I4: ALEXSANDRO | J4: MÁRCIOMC
A5: 15.09.25 | B5: 5008157 | C5: NIPLE PVC-R AF RM DE 1" | E5: TRUE | F5: 1 | G5: =_xlfn.XLOOKUP(B:B,'Lista de Materiais'!A:A,'Lista de Materiais'!C:C) -> UN | H5: BXD2 ELEVATÓRIA ANGELA MARIA | I5: ALEXSANDRO | J5: MÁRCIOMC
A6: 16.09.25 | B6: 5018562 | C6: RELE MODULAR INTERFACE 6A 250V 24V AZUL | E6: TRUE | F6: 1 | G6: =_xlfn.XLOOKUP(B:B,'Lista de Materiais'!A:A,'Lista de Materiais'!C:C) -> UN | H6: BXD2 ELEVATÓRIA INDIA PORTUGUESA | I6: WENDREL/RODRIGO | J6: MÁRCIOMC
A7: 16.09.25 | B7: 5000667 | C7: BUCHA RED PVC SOLD 1.1/2"X 1" | E7: TRUE | F7: 1 | G7: =_xlfn.XLOOKUP(B:B,'Lista de Materiais'!A:A,'Lista de Materiais'!C:C) -> UN | H7: BXD2 ELEVATÓRIA ANGELA MARIA | I7: ANDRÉ / ALEXANDRE | J7: MÁRCIOMC
A8: 16.09.25 | B8: 5024639 | C8: FITA VEDA ROSCA BR 18MM ROL 50M | E8: TRUE | F8: 1 | G8: =_xlfn.XLOOKUP(B:B,'Lista de Materiais'!A:A,'Lista de Materiais'!C:C) -> UN | H8: BXD2 ELEVATÓRIA ANGELA MARIA | I8: ANDRÉ / ALEXANDRE | J8: MÁRCIOMC
A9: 16.09.25 | B9: 5004475 | C9: DISJUNTOR MINI 3P 400VCA 3X25A | E9: TRUE | F9: 1 | G9: =_xlfn.XLOOKUP(B:B,'Lista de Materiais'!A:A,'Lista de Materiais'!C:C) -> UN | H9: BXD1 ELEVATÓRIA SCHANGRILA | I9: JORGE / ANDRÉ | J9: MÁRCIOMC
A10: 17.09.25 | B10: 5018562 | C10: RELE INTERFACE 6A - 250V 24V AZUL | E10: TRUE | F10: 2 | G10: UN | H10: BXD2 ELEVATÓRIA LÚCIO TAVARES | I10: ANDREW | J10: MÁRCIOMC
A11: 17.09.25 | B11: 5001073 | C11: CABO ELETRICO 750V 1MM2 | E11: TRUE | F11: 1 | G11: M | H11: BXD2 ELEVATÓRIA LÚCIO TAVARES | I11: ANDREW | J11: MÁRCIOMC
A12: 17.09.25 | B12: 3000010 | C12: ABRAÇADEIRA SERRA COPO 3/4" | E12: TRUE | F12: 8 | G12: UN | H12: BXD2 OFICINA | I12: ALEXSANDRO / JHONATA | J12: MÁRCIOMC
A13: 17.09.25 | B13: 3006047 | C13: PARAFUSO AUTOATARRAXANTE PHILLIPS 3,5MMX6,5MM | E13: TRUE | F13: 15 | G13: UN | H13: BXD2 OFICINA | I13: ALEXSANDRO / JHONATA | J13: MÁRCIOMC
A14: 17.09.25 | B14: 3006163 | C14: PARAFUSO AÇO PB 4,2MMX13MM | E14: TRUE | F14: 15 | G14: UN | H14: BXD2 OFICINA | I14: ALEXSANDRO / JHONATA | J14: MÁRCIOMC
A15: 17.09.25 | B15: 5006821 | C15: LUVA PVC-R 1/2" | E15: TRUE | F15: 2 | G15: UN | H15: BXD2 OFICINA | I15: ALEXSANDRO / JHONATA | J15: MÁRCIOMC
A16: 17.09.25 | B16: 5025283 | C16: NIPLE PVC-R AF 1/2" | E16: TRUE | F16: 1 | G16: UN | H16: BXD2 OFICINA | I16: ALEXSANDRO / JHONATA | J16: MÁRCIOMC
A17: 19.09.25 | B17: 5025447 | C17: FITA ISOLANTE PR 750V 19MM P44 | E17: TRUE | F17: 1 | G17: UN | H17: BXD2 PREVENTIVA | I17: ALEXENDRE | J17: MÁRCIOMC
A18: 19.09.25 | B18: 5022362 | C18: CONTACTOR TRIPOLAR CAPACITOR CWMC32 | E18: TRUE | F18: 1 | G18: UN | H18: BXD2 ELEVATÓRIA MESQUITA G1 | I18: VAGNER / ALEXANDRE | J18: MÁRCIOMC
A19: 21.09.25 | B19: =_xlfn.XLOOKUP(C19,'Lista de Materiais'!B:B,'Lista de Materiais'!A:A) -> 5025447 | C19: FITA ISOLANTE AUTOFUSAO PT 10M 19MM | E19: TRUE | F19: 1 | G19: =_xlfn.XLOOKUP(B:B,'Lista de Materiais'!A:A,'Lista de Materiais'!C:C) -> UN | H19: BXD2 BOOSTER AUSTIN | I19: ERICK | J19: MÁRCIOMC
A20: 21.09.25 | B20: 3006225 | C20: PARAFUSO SEXT 5/8"X 2.1/2"" | E20: TRUE | F20: 5 | G20: UN | H20: BXD2 BOOSTER AUSTIN | I20: JORGE | J20: MÁRCIOMC
A21: 22.09.25 | B21: 5025447 | C21: FITA ISOLANTE PR 750V 19MM P44 | E21: TRUE | F21: 1 | G21: UN | H21: ATUALIZAÇÃO ESTOQUE | I21: ATUALIZAÇÃO ESTOQUE | J21: MÁRCIOMC
A22: 22.09.25 | B22: 5025447 | C22: FITA ISOLANTE AM 750V 19MM | E22: TRUE | F22: 1 | G22: UN | H22: ATUALIZAÇÃO ESTOQUE | I22: ATUALIZAÇÃO ESTOQUE | J22: MÁRCIOMC
A23: 22.09.25 | B23: =_xlfn.XLOOKUP(C23,'Lista de Materiais'!B:B,'Lista de Materiais'!A:A) -> #N/A | C23: CONTATOR TRIPOLAR AC 3 45A 400V | E23: TRUE | F23: 1 | G23: UN | H23: ELEVATÓRIA VILA RORAIMA | I23: ERICK | J23: MÁRCIOMC
A24: 23.09.25 | B24: 4007455 | C24: =_xlfn.XLOOKUP(B24,'Lista de Materiais'!A:A,'Lista de Materiais'!B:B) -> SELO MECANICO TS-P 1.1/4POL | E24: TRUE | F24: 1 | G24: UN | H24: ELEVATÓRIA VILA RORAIMA | I24: RONALDO / VALMIR | J24: MÁRCIOMC
A25: 23.09.25 | B25: =_xlfn.XLOOKUP(C25,'Lista de Materiais'!B:B,'Lista de Materiais'!A:A) -> #N/A | C25: TERMINAL ELETRIC OLHAL 1 FURO 4-6MM AMARELO | E25: TRUE | F25: 6 | G25: UN | H25: ELEVATÓRIA VILA RORAIMA | I25: RONALDO / VALMIR | J25: MÁRCIOMC
A26: 23.09.25 | B26: =_xlfn.XLOOKUP(C26,'Lista de Materiais'!B:B,'Lista de Materiais'!A:A) -> #N/A | C26: FUSÍVEL NH00 RETARDADO 63A | E26: TRUE | F26: 1 | G26: UN | H26: ELEVATÓRIA VILA RORAIMA | I26: RONALDO / VALMIR | J26: MÁRCIOMC
A27: 24.09.25 | B27: =_xlfn.XLOOKUP(C27,'Lista de Materiais'!B:B,'Lista de Materiais'!A:A) -> 3009830 | C27: PARAFUSO CHAVE PHILIPS AC 9MM 25MM 3,5MM | E27: TRUE | F27: 15 | G27: =_xlfn.XLOOKUP(B:B,'Lista de Materiais'!A:A,'Lista de Materiais'!C:C) -> UN | H27: OFICINA | I27: VAGNER / VINICIUS | J27: MÁRCIOMC
A28: 24.09.25 | B28: =_xlfn.XLOOKUP(C28,'Lista de Materiais'!B:B,'Lista de Materiais'!A:A) -> 5025447 | C28: FITA ISOLANTE AUTOFUSAO PT 10M 19MM | E28: TRUE | F28: 1 | G28: =_xlfn.XLOOKUP(B:B,'Lista de Materiais'!A:A,'Lista de Materiais'!C:C) -> UN | H28: PREVENTIVAS | I28: DOUGLAS | J28: ALEXSANDRO
A29: 24.09.25 | B29: =_xlfn.XLOOKUP(C29,'Lista de Materiais'!B:B,'Lista de Materiais'!A:A) -> #N/A | C29: FITA ISOL PR 750V 19MM ROL 20M P44 | E29: TRUE | F29: 1 | G29: =_xlfn.XLOOKUP(B:B,'Lista de Materiais'!A:A,'Lista de Materiais'!C:C) -> #N/A | H29: PREVENTIVAS | I29: DOUGLAS | J29: ALEXSANDRO
A30: 24.09.25 | B30: =_xlfn.XLOOKUP(C30,'Lista de Materiais'!B:B,'Lista de Materiais'!A:A) -> 5025447 | C30: FITA ISOLANTE AUTOFUSAO PT 10M 19MM | E30: TRUE | F30: 1 | G30: =_xlfn.XLOOKUP(B:B,'Lista de Materiais'!A:A,'Lista de Materiais'!C:C) -> UN | H30: ELEVATÓRIA DINAMARCO REIS | I30: ANDREW | J30: MÁRCIOMC
A31: 24.09.25 | B31: =_xlfn.XLOOKUP(C31,'Lista de Materiais'!B:B,'Lista de Materiais'!A:A) -> #N/A | C31: FITA ISOL PR 750V 19MM ROL 20M P44 | E31: TRUE | F31: 1 | G31: =_xlfn.XLOOKUP(B:B,'Lista de Materiais'!A:A,'Lista de Materiais'!C:C) -> #N/A | H31: ELEVATÓRIA DINAMARCO REIS | I31: ANDREW | J31: MÁRCIOMC
A32: 25.09.25 | B32: =_xlfn.XLOOKUP(C32,'Lista de Materiais'!B:B,'Lista de Materiais'!A:A) -> #N/A | C32: NIPLE PVC 3/4" | E32: TRUE | F32: 8 | G32: =_xlfn.XLOOKUP(B:B,'Lista de Materiais'!A:A,'Lista de Materiais'!C:C) -> #N/A | H32: ELEVATÓRIA CIRILO | I32: ANDREW / JHONATA | J32: MÁRCIOMC
A33: 25.09.25 | B33: =_xlfn.XLOOKUP(C33,'Lista de Materiais'!B:B,'Lista de Materiais'!A:A) -> #N/A | C33: TE PVC 3/4" | E33: TRUE | F33: 2 | G33: =_xlfn.XLOOKUP(B:B,'Lista de Materiais'!A:A,'Lista de Materiais'!C:C) -> #N/A | H33: ELEVATÓRIA CIRILO | I33: ANDREW / JHONATA | J33: MÁRCIOMC
A34: 25.09.25 | B34: =_xlfn.XLOOKUP(C34,'Lista de Materiais'!B:B,'Lista de Materiais'!A:A) -> #N/A | C34: LUVA PVC 3/4" | E34: TRUE | F34: 4 | G34: =_xlfn.XLOOKUP(B:B,'Lista de Materiais'!A:A,'Lista de Materiais'!C:C) -> #N/A | H34: ELEVATÓRIA CIRILO | I34: ANDREW / JHONATA | J34: MÁRCIOMC
A35: 25.09.25 | B35: =_xlfn.XLOOKUP(C35,'Lista de Materiais'!B:B,'Lista de Materiais'!A:A) -> #N/A | C35: JOELHP PVC 90X3/4" | E35: TRUE | F35: 2 | G35: =_xlfn.XLOOKUP(B:B,'Lista de Materiais'!A:A,'Lista de Materiais'!C:C) -> #N/A | H35: ELEVATÓRIA CIRILO | I35: ANDREW / JHONATA | J35: MÁRCIOMC
A36: 25.09.25 | B36: =_xlfn.XLOOKUP(C36,'Lista de Materiais'!B:B,'Lista de Materiais'!A:A) -> #N/A | C36: LUVA RED PVC-R AF 1"X3/4" | E36: TRUE | F36: 1 | G36: =_xlfn.XLOOKUP(B:B,'Lista de Materiais'!A:A,'Lista de Materiais'!C:C) -> #N/A | H36: ELEVATÓRIA CIRILO | I36: ANDREW / JHONATA | J36: MÁRCIOMC
A37: 25.09.25 | B37: =_xlfn.XLOOKUP(C37,'Lista de Materiais'!B:B,'Lista de Materiais'!A:A) -> #N/A | C37: ELETRO HASTE METAL 3/4" | E37: TRUE | F37: 2 | G37: =_xlfn.XLOOKUP(B:B,'Lista de Materiais'!A:A,'Lista de Materiais'!C:C) -> #N/A | H37: ELEVATÓRIA CIRILO | I37: ANDREW / JHONATA | J37: MÁRCIOMC
A38: 25.09.25 | B38: =_xlfn.XLOOKUP(C38,'Lista de Materiais'!B:B,'Lista de Materiais'!A:A) -> #N/A | C38: FITA VEDA ROSCA BR | E38: TRUE | F38: 1 | G38: =_xlfn.XLOOKUP(B:B,'Lista de Materiais'!A:A,'Lista de Materiais'!C:C) -> #N/A | H38: ELEVATÓRIA CIRILO | I38: ANDREW / JHONATA | J38: MÁRCIOMC
A39: 25.09.25 | B39: =_xlfn.XLOOKUP(C39,'Lista de Materiais'!B:B,'Lista de Materiais'!A:A) -> #N/A | C39: ELETRODO DE NIVEL | D39: USADO | E39: TRUE | F39: 1 | G39: =_xlfn.XLOOKUP(B:B,'Lista de Materiais'!A:A,'Lista de Materiais'!C:C) -> #N/A | H39: ELEVATÓRIA CIRILO | I39: ANDREW / JHONATA | J39: MÁRCIOMC
A40: 25.09.25 | B40: =_xlfn.XLOOKUP(C40,'Lista de Materiais'!B:B,'Lista de Materiais'!A:A) -> #N/A | C40: TIMER DIGITA | D40: USADO | E40: TRUE | F40: 1 | G40: =_xlfn.XLOOKUP(B:B,'Lista de Materiais'!A:A,'Lista de Materiais'!C:C) -> #N/A | H40: ELEVATÓRIA CIRILO | I40: ANDREW / JHONATA | J40: MÁRCIOMC
...

Sheet ESTOQUE BXD2
A1: ✏️ Manual | B1: ✏️ Manual | C1: ✏️ Manual | D1: ✅ Fórmula | E1: ✅ Fórmula | F1: ✅ Fórmula | G1: ✏️ Manual
A2: Cod.SAP | C2: unidade | D2: Entrada | E2: Saída | F2: Saldo Estoque | G2: ATUALIZAÇÃO
A3: =_xlfn.XLOOKUP(B3,'Entrada de Materiais'!C:C,'Entrada de Materiais'!B:B) -> 4010017 | B3: *ROLAMENTO ESF RIG 6226/C3 SKF | C3: UND | D3: =SUMIFS('Entrada de Materiais'!D:D, 'Entrada de Materiais'!C:C, B3) -> 4 | E3: =SUMIFS('SAIDA DE MATERIAIS'!F:F,'SAIDA DE MATERIAIS'!C:C,B3) -> 2 | F3: =+D3-E3 -> 2
A4: =_xlfn.XLOOKUP(B4,'Entrada de Materiais'!C:C,'Entrada de Materiais'!B:B) -> 5532022 | B4: _CHAVE SECCIONADORA POTENCIA - 160 A | C4: UND | D4: =SUMIFS('Entrada de Materiais'!D:D, 'Entrada de Materiais'!C:C, B4) -> 1 | E4: =SUMIFS('SAIDA DE MATERIAIS'!F:F,'SAIDA DE MATERIAIS'!C:C,B4) -> 0 | F4: =+D4-E4 -> 1
A5: =_xlfn.XLOOKUP(B5,'Entrada de Materiais'!C:C,'Entrada de Materiais'!B:B) -> 5532023 | B5: _CHAVE SECCIONADORA POTENCIA - 250 A | C5: UND | D5: =SUMIFS('Entrada de Materiais'!D:D, 'Entrada de Materiais'!C:C, B5) -> 2 | E5: =SUMIFS('SAIDA DE MATERIAIS'!F:F,'SAIDA DE MATERIAIS'!C:C,B5) -> 0 | F5: =+D5-E5 -> 2
A6: =_xlfn.XLOOKUP(B6,'Entrada de Materiais'!C:C,'Entrada de Materiais'!B:B) -> 5532024 | B6: _CHAVE SECCIONADORA POTENCIA - 400 A | C6: UND | D6: =SUMIFS('Entrada de Materiais'!D:D, 'Entrada de Materiais'!C:C, B6) -> 2 | E6: =SUMIFS('SAIDA DE MATERIAIS'!F:F,'SAIDA DE MATERIAIS'!C:C,B6) -> 0 | F6: =+D6-E6 -> 2
A7: =_xlfn.XLOOKUP(B7,'Entrada de Materiais'!C:C,'Entrada de Materiais'!B:B) -> 5532025 | B7: _CHAVE SECCIONADORA POTENCIA - 630 A | C7: UND | D7: =SUMIFS('Entrada de Materiais'!D:D, 'Entrada de Materiais'!C:C, B7) -> 2 | E7: =SUMIFS('SAIDA DE MATERIAIS'!F:F,'SAIDA DE MATERIAIS'!C:C,B7) -> 0 | F7: =+D7-E7 -> 2
A8: =_xlfn.XLOOKUP(B8,'Entrada de Materiais'!C:C,'Entrada de Materiais'!B:B) -> 5532031 | B8: _CHAVE SECCIONADORA PUNHO 3P 250A C/FUS | C8: UND | D8: =SUMIFS('Entrada de Materiais'!D:D, 'Entrada de Materiais'!C:C, B8) -> 1 | E8: =SUMIFS('SAIDA DE MATERIAIS'!F:F,'SAIDA DE MATERIAIS'!C:C,B8) -> 0 | F8: =+D8-E8 -> 1
A9: =_xlfn.XLOOKUP(B9,'Entrada de Materiais'!C:C,'Entrada de Materiais'!B:B) -> 5028401 | B9: _CONTATOR 3P 220V CA 1NA 80A | C9: UND | D9: =SUMIFS('Entrada de Materiais'!D:D, 'Entrada de Materiais'!C:C, B9) -> 2 | E9: =SUMIFS('SAIDA DE MATERIAIS'!F:F,'SAIDA DE MATERIAIS'!C:C,B9) -> 0 | F9: =+D9-E9 -> 2
A10: =_xlfn.XLOOKUP(B10,'Entrada de Materiais'!C:C,'Entrada de Materiais'!B:B) -> 5029619 | B10: _RELE SOBRECARGA TERMICO REG 95-120A | C10: UND | D10: =SUMIFS('Entrada de Materiais'!D:D, 'Entrada de Materiais'!C:C, B10) -> 1 | E10: =SUMIFS('SAIDA DE MATERIAIS'!F:F,'SAIDA DE MATERIAIS'!C:C,B10) -> 0 | F10: =+D10-E10 -> 1
A11: =_xlfn.XLOOKUP(B11,'Entrada de Materiais'!C:C,'Entrada de Materiais'!B:B) -> #N/A | B11: _TRANSMISSOR PRESSAO AI A1 TIPO G 0-6BAR | C11: UND | D11: =SUMIFS('Entrada de Materiais'!D:D, 'Entrada de Materiais'!C:C, B11) -> 0 | E11: =SUMIFS('SAIDA DE MATERIAIS'!F:F,'SAIDA DE MATERIAIS'!C:C,B11) -> 0 | F11: =+D11-E11 -> 0
A12: =_xlfn.XLOOKUP(B12,'Entrada de Materiais'!C:C,'Entrada de Materiais'!B:B) -> 3009327 | B12: ABRACADEIRA BAP AC GALV 1200MM 33 FUROS | C12: UND | D12: =SUMIFS('Entrada de Materiais'!D:D, 'Entrada de Materiais'!C:C, B12) -> 23 | E12: =SUMIFS('SAIDA DE MATERIAIS'!F:F,'SAIDA DE MATERIAIS'!C:C,B12) -> 1 | F12: =+D12-E12 -> 22
A13: =_xlfn.XLOOKUP(B13,'Entrada de Materiais'!C:C,'Entrada de Materiais'!B:B) -> 3000011 | B13: ABRACADEIRA COP AC 1020 CZ 1POL 25,4MM | C13: UND | D13: =SUMIFS('Entrada de Materiais'!D:D, 'Entrada de Materiais'!C:C, B13) -> 3 | E13: =SUMIFS('SAIDA DE MATERIAIS'!F:F,'SAIDA DE MATERIAIS'!C:C,B13) -> 0 | F13: =+D13-E13 -> 3
A14: =_xlfn.XLOOKUP(B14,'Entrada de Materiais'!C:C,'Entrada de Materiais'!B:B) -> 3000010 | B14: ABRACADEIRA COP AC 1020 NAT 3/4POL | C14: UND | D14: =SUMIFS('Entrada de Materiais'!D:D, 'Entrada de Materiais'!C:C, B14) -> 3 | E14: =SUMIFS('SAIDA DE MATERIAIS'!F:F,'SAIDA DE MATERIAIS'!C:C,B14) -> 0 | F14: =+D14-E14 -> 3
... A44: =_xlfn.XLOOKUP(B44,'Entrada de Materiais'!C:C,'Entrada de Materiais'!B:B) -> 5025255 | B44: BARRA ROSCADA AC 1POL UNC 1M | C44: UND | D44: =SUMIFS('Entrada de Materiais'!D:D, 'Entrada de Materiais'!C:C, B44) -> 8 | E44: =SUMIFS('SAIDA DE MATERIAIS'!F:F,'SAIDA DE MATERIAIS'!C:C,B44) -> 0 | F44: =+D44-E44 -> 8
A45: =_xlfn.XLOOKUP(B45,'Entrada de Materiais'!C:C,'Entrada de Materiais'!B:B) -> 5024701 | B45: BARRA ROSCADA DE AÇO 1/2" X 1000 | C45: UND | D45: 8 | E45: =SUMIFS('SAIDA DE MATERIAIS'!F:F,'SAIDA DE MATERIAIS'!C:C,B45) -> 0 | F45: =+D45-E45 -> 8
A46: =_xlfn.XLOOKUP(B46,'Entrada de Materiais'!C:C,'Entrada de Materiais'!B:B) -> 5024706 | B46: BARRA ROSCADA DE AÇO 3/4" X 1000 | C46: UND | D46: =SUMIFS('Entrada de Materiais'!D:D, 'Entrada de Materiais'!C:C, B46) -> 13 | E46: =SUMIFS('SAIDA DE MATERIAIS'!F:F,'SAIDA DE MATERIAIS'!C:C,B46) -> 0 | F46: =+D46-E46 -> 13
A47: =_xlfn.XLOOKUP(B47,'Entrada de Materiais'!C:C,'Entrada de Materiais'!B:B) -> 5024711 | B47: BARRA ROSCADA DE AÇO 5/8" X 1000 | C47: UND | D47: =SUMIFS('Entrada de Materiais'!D:D, 'Entrada de Materiais'!C:C, B47) -> 12 | E47: =SUMIFS('SAIDA DE MATERIAIS'!F:F,'SAIDA DE MATERIAIS'!C:C,B47) -> 0 | F47: =+D47-E47 -> 12
A48: =_xlfn.XLOOKUP(B48,'Entrada de Materiais'!C:C,'Entrada de Materiais'!B:B) -> 5024713 | B48: BARRA ROSCADA DE AÇO 7/8" X 1000 | C48: UND | D48: =SUMIFS('Entrada de Materiais'!D:D, 'Entrada de Materiais'!C:C, B48) -> 1 | E48: =SUMIFS('SAIDA DE MATERIAIS'!F:F,'SAIDA DE MATERIAIS'!C:C,B48) -> 0 | F48: =+D48-E48 -> 1
A49: =_xlfn.XLOOKUP(B49,'Entrada de Materiais'!C:C,'Entrada de Materiais'!B:B) -> 5000324 | B49: BASE RELE RET PT 250V 10A 15,6MM | C49: UND | D49: =SUMIFS('Entrada de Materiais'!D:D, 'Entrada de Materiais'!C:C, B49) -> 53 | E49: =SUMIFS('SAIDA DE MATERIAIS'!F:F,'SAIDA DE MATERIAIS'!C:C,B49) -> 0 | F49: =+D49-E49 -> 53
A50: =_xlfn.XLOOKUP(B50,'Entrada de Materiais'!C:C,'Entrada de Materiais'!B:B) -> 5000315 | B50: BASE UNIPOLAR 250A /690v | C50: UND | D50: =SUMIFS('Entrada de Materiais'!D:D, 'Entrada de Materiais'!C:C, B50) -> 1 | E50: =SUMIFS('SAIDA DE MATERIAIS'!F:F,'SAIDA DE MATERIAIS'!C:C,B50) -> 0 | F50: =+D50-E50 -> 1
A51: =_xlfn.XLOOKUP(B51,'Entrada de Materiais'!C:C,'Entrada de Materiais'!B:B) -> 4007463 | B51: BATERIA ALCAL RECARREGAVEL 9V 250MAH | C51: UNID | D51: =SUMIFS('Entrada de Materiais'!D:D, 'Entrada de Materiais'!C:C, B51) -> 20 | E51: =SUMIFS('SAIDA DE MATERIAIS'!F:F,'SAIDA DE MATERIAIS'!C:C,B51) -> 0 | F51: =+D51-E51 -> 20
A52: =_xlfn.XLOOKUP(B52,'Entrada de Materiais'!C:C,'Entrada de Materiais'!B:B) -> 5023164 | B52: BLOCO CONTATO AUX 2NA+2NF | C52: UND | D52: =SUMIFS('Entrada de Materiais'!D:D, 'Entrada de Materiais'!C:C, B52) -> 2 | E52: =SUMIFS('SAIDA DE MATERIAIS'!F:F,'SAIDA DE MATERIAIS'!C:C,B52) -> 0 | F52: =+D52-E52 -> 2
A53: =_xlfn.XLOOKUP(B53,'Entrada de Materiais'!C:C,'Entrada de Materiais'!B:B) -> 5517135 | B53: BOMBA CENTRIFUCA AG 125L/S 85MCA | C53: UND | D53: =SUMIFS('Entrada de Materiais'!D:D, 'Entrada de Materiais'!C:C, B53) -> 0 | E53: =SUMIFS('SAIDA DE MATERIAIS'!F:F,'SAIDA DE MATERIAIS'!C:C,B53) -> 0 | F53: =+D53-E53 -> 0
A54: 5501606 | B54: BOMBA SUBMERSIVEL 8,6M3/H 8,5MCA 0,5CV | C54: UND | D54: =SUMIFS('Entrada de Materiais'!D:D, 'Entrada de Materiais'!C:C, B54) -> 8 | E54: =SUMIFS('SAIDA DE MATERIAIS'!F:F,'SAIDA DE MATERIAIS'!C:C,B54) -> 0 | F54: =+D54-E54 -> 8
A55: =_xlfn.XLOOKUP(B55,'Entrada de Materiais'!C:C,'Entrada de Materiais'!B:B) -> 5503631 | B55: BOTÃO DE COMANDO 22MM COR VERDE | C55: UND | D55: =SUMIFS('Entrada de Materiais'!D:D, 'Entrada de Materiais'!C:C, B55) -> 0 | E55: =SUMIFS('SAIDA DE MATERIAIS'!F:F,'SAIDA DE MATERIAIS'!C:C,B55) -> 0 | F55: =+D55-E55 -> 0
A56: =_xlfn.XLOOKUP(B56,'Entrada de Materiais'!C:C,'Entrada de Materiais'!B:B) -> 5503633 | B56: BOTÃO DE COMANDO 22MM COR VERMELHO | C56: UND | D56: =SUMIFS('Entrada de Materiais'!D:D, 'Entrada de Materiais'!C:C, B56) -> 0 | E56: =SUMIFS('SAIDA DE MATERIAIS'!F:F,'SAIDA DE MATERIAIS'!C:C,B56) -> 0 | F56: =+D56-E56 -> 0
A57: =_xlfn.XLOOKUP(B57,'Entrada de Materiais'!C:C,'Entrada de Materiais'!B:B) -> 5019127 | B57: BOX RETO ELETRODUTO AL D1POL | C57: UND | D57: =SUMIFS('Entrada de Materiais'!D:D, 'Entrada de Materiais'!C:C, B57) -> 19 | E57: =SUMIFS('SAIDA DE MATERIAIS'!F:F,'SAIDA DE MATERIAIS'!C:C,B57) -> 2 | F57: =+D57-E57 -> 17
A58: =_xlfn.XLOOKUP(B58,'Entrada de Materiais'!C:C,'Entrada de Materiais'!B:B) -> 5025311 | B58: BOX RETO ELETRODUTO AL D2 | C58: UND | D58: =SUMIFS('Entrada de Materiais'!D:D, 'Entrada de Materiais'!C:C, B58) -> 0 | E58: =SUMIFS('SAIDA DE MATERIAIS'!F:F,'SAIDA DE MATERIAIS'!C:C,B58) -> 0 | F58: =+D58-E58 -> 0
A59: =_xlfn.XLOOKUP(B59,'Entrada de Materiais'!C:C,'Entrada de Materiais'!B:B) -> 5507206 | B59: BROCA DE AÇO RAPIDO 3,5MM | C59: UND | D59: =SUMIFS('Entrada de Materiais'!D:D, 'Entrada de Materiais'!C:C, B59) -> 0 | E59: =SUMIFS('SAIDA DE MATERIAIS'!F:F,'SAIDA DE MATERIAIS'!C:C,B59) -> 0 | F59: =+D59-E59 -> 0
A60: =_xlfn.XLOOKUP(B60,'Entrada de Materiais'!C:C,'Entrada de Materiais'!B:B) -> 5507217 | B60: BROCA DE AÇO RAPIDO 4MM | C60: UND | D60: =SUMIFS('Entrada de Materiais'!D:D, 'Entrada de Materiais'!C:C, B60) -> 0 | E60: =SUMIFS('SAIDA DE MATERIAIS'!F:F,'SAIDA DE MATERIAIS'!C:C,B60) -> 0 | F60: =+D60-E60 -> 0
A61: =_xlfn.XLOOKUP(B61,'Entrada de Materiais'!C:C,'Entrada de Materiais'!B:B) -> 5507189 | B61: BROCA HELIC CIL HSS DIR 1/4POL 4POL | C61: UND | D61: =SUMIFS('Entrada de Materiais'!D:D, 'Entrada de Materiais'!C:C, B61) -> 0 | E61: =SUMIFS('SAIDA DE MATERIAIS'!F:F,'SAIDA DE MATERIAIS'!C:C,B61) -> 0 | F61: =+D61-E61 -> 0
A62: =_xlfn.XLOOKUP(B62,'Entrada de Materiais'!C:C,'Entrada de Materiais'!B:B) -> 5507191 | B62: BROCA HELIC CIL HSS DIR 10MM | C62: UND | D62: =SUMIFS('Entrada de Materiais'!D:D, 'Entrada de Materiais'!C:C, B62) -> 0 | E62: =SUMIFS('SAIDA DE MATERIAIS'!F:F,'SAIDA DE MATERIAIS'!C:C,B62) -> 0 | F62: =+D62-E62 -> 0
A63: =_xlfn.XLOOKUP(B63,'Entrada de Materiais'!C:C,'Entrada de Materiais'!B:B) -> 5507194 | B63: BROCA HELIC CIL HSS DIR 11MM 142MM | C63: UND | D63: =SUMIFS('Entrada de Materiais'!D:D, 'Entrada de Materiais'!C:C, B63) -> 0 | E63: =SUMIFS('SAIDA DE MATERIAIS'!F:F,'SAIDA DE MATERIAIS'!C:C,B63) -> 0 | F63: =+D63-E63 -> 0
A64: =_xlfn.XLOOKUP(B64,'Entrada de Materiais'!C:C,'Entrada de Materiais'!B:B) -> 5507199 | B64: BROCA HELIC CIL HSS DIR 13MM 151MM | C64: UND | D64: =SUMIFS('Entrada de Materiais'!D:D, 'Entrada de Materiais'!C:C, B64) -> 4 | E64: =SUMIFS('SAIDA DE MATERIAIS'!F:F,'SAIDA DE MATERIAIS'!C:C,B64) -> 0 | F64: =+D64-E64 -> 4
A65: =_xlfn.XLOOKUP(B65,'Entrada de Materiais'!C:C,'Entrada de Materiais'!B:B) -> 5507209 | B65: BROCA HELIC CIL HSS DIR 3/16POL 91MM | C65: UND | D65: =SUMIFS('Entrada de Materiais'!D:D, 'Entrada de Materiais'!C:C, B65) -> 0 | E65: =SUMIFS('SAIDA DE MATERIAIS'!F:F,'SAIDA DE MATERIAIS'!C:C,B65) -> 0 | F65: =+D65-E65 -> 0
A66: =_xlfn.XLOOKUP(B66,'Entrada de Materiais'!C:C,'Entrada de Materiais'!B:B) -> 5507213 | B66: BROCA HELIC CIL HSS DIR 3MM 61MM | C66: UND | D66: =SUMIFS('Entrada de Materiais'!D:D, 'Entrada de Materiais'!C:C, B66) -> 7 | E66: =SUMIFS('SAIDA DE MATERIAIS'!F:F,'SAIDA DE MATERIAIS'!C:C,B66) -> 0 | F66: =+D66-E66 -> 7
... A97: =_xlfn.XLOOKUP(B97,'Entrada de Materiais'!C:C,'Entrada de Materiais'!B:B) -> 5021333 | B97: CABO ELET FLEX 0,6/1KV 70MM2 CL5 PT | C97: M | D97: =SUMIFS('Entrada de Materiais'!D:D, 'Entrada de Materiais'!C:C, B97) -> 0 | E97: =SUMIFS('SAIDA DE MATERIAIS'!F:F,'SAIDA DE MATERIAIS'!C:C,B97) -> 0 | F97: =+D97-E97 -> 0
