Workbook

Sheet 02.07
A1: Rótulos de Linha | B1: Comprador Cotação | C1: Requisicao | D1: Item RC | E1: Pedido | F1: Descrição Material | G1: Dt Criação RC | H1: Status Geral | I1: Qtde RC | J1: Chegou? | K1: Foi Retirado? | L1: Cobrado via Email? | M1: Obs: | N1: Chave
N2: =C2&D2
N3: =C3&D3
N4: =C4&D4
N5: =C5&D5
N6: =C6&D6
N7: =C7&D7
N8: =C8&D8
N9: =C9&D9
N10: =C10&D10
N11: =C11&D11
N12: =C12&D12
N13: =C13&D13
... N171: =C171&D171

Sheet 08.06
A1: Rótulos de Linha | B1: Comprador Cotação | C1: Requisicao | D1: Item RC | E1: Pedido | F1: Descrição Material | G1: Dt Criação RC | H1: Status Geral | I1: Qtde RC | J1: Chegou? | K1: Foi Retirado? | L1: Cobrado via Email? | M1: Obs: | N1: Chave
A2: André Queiroz | B2: André Queiroz | C2: 16430051 | D2: 20 | E2: 4500751385 | F2: ADESIVO RESINA EPOXI 16G | G2: 46073 | H2: Escrituração Realizada | I2: 10 | N2: =C2&D2 -> 1643005120
A3: Beatriz Serafim | B3: Beatriz Serafim | C3: 16421260 | D3: 20 | E3: 4500716344 | F3: ADESIVO RESINA EPOXI 16G | G3: 46024 | H3: Escrituração Realizada | I3: 10 | J3: SIm | K3: SIm | N3: =C3&D3 -> 1642126020
A4: Edney Jean | B4: (vazio) | C4: 16411558 | D4: 10 | E4: 4500645222 | F4: ALICATE AMPERIMETRO DIGITAL 20/200/1000A | G4: 45961 | H4: Escrituração Realizada | I4: 7 | J4: SIm | K4: SIm | N4: =C4&D4 -> 1641155810
A5: Luciara Oliveira | B5: Luciara Oliveira | C5: 16362199 | D5: 2130 | E5: 4500437805 | F5: ANEL BORR ABF FLANGE FOFO DN100MM | G5: 45659 | H5: Escrituração Realizada | I5: 2 | J5: SIm | K5: SIm | N5: =C5&D5 -> 163621992130
A6: Luciara Oliveira | B6: Luciara Oliveira | C6: 16362199 | D6: 500 | E6: 4500437805 | F6: ANEL BORR ABF FLANGE FOFO DN100MM | G6: 45659 | H6: Escrituração Realizada | I6: 2 | J6: SIm | K6: SIm | N6: =C6&D6 -> 16362199500
A7: Luciara Oliveira | B7: Luciara Oliveira | C7: 16404745 | D7: 100 | E7: 4500619102 | F7: BARRA ROSCADA AC 1020 1/2POL UNC 1M | G7: 45922 | H7: Escrituração Realizada | I7: 10 | N7: =C7&D7 -> 16404745100
A8: Victor L. Lopes | B8: Victor L. Lopes | C8: 16378221 | D8: 10 | E8: 4500509387 | F8: BASTAO RESGATE FIBRA VID 34,5KV 2,28M | G8: 45754 | H8: PC - em Aprovação | I8: 4 | N8: =C8&D8 -> 1637822110
A9: Amanda Oliva | B9: (vazio) | C9: 16411558 | D9: 20 | E9: 4500645232 | F9: BATERIA ALCAL RECARREGAVEL 9V 250MAH | G9: 45961 | H9: Escrituração Realizada | I9: 20 | J9: SIm | K9: SIm | N9: =C9&D9 -> 1641155820
A10: (vazio) | B10: Fernando Gonçalo | C10: 16432776 | D10: 40 | E10: (vazio) | F10: BOMBA MANUAL GRAX 12G 7KG | G10: 46090 | H10: Cotação - em Negociação | I10: 10 | N10: =C10&D10 -> 1643277640
A11: (vazio) | B11: (vazio) | C11: 16394075 | D11: 10 | E11: (vazio) | F11: BOMBA MANUAL GRAX 12G 7KG | G11: 45855 | H11: Requisição - Item Concluído | I11: 10 | J11: Não | K11: Não | M11: CANCELADO | N11: =C11&D11 -> 1639407510
A12: (vazio) | B12: (vazio) | C12: 16447769 | D12: 10 | E12: (vazio) | F12: BUCHA REDUCAO GALV 2.1/2X2 | G12: 46168 | H12: Cotação a agregar | I12: 10 | N12: =C12&D12 -> 1644776910
A13: (vazio) | B13: (vazio) | C13: 16437339 | D13: 20 | E13: (vazio) | F13: CABO COB PP 1KV 4X16MM2 PT | G13: 46113 | H13: Cotação a agregar | I13: 100 | N13: =C13&D13 -> 1643733920
A14: (vazio) | B14: (vazio) | C14: 16437339 | D14: 30 | E14: (vazio) | F14: CABO COB PP 1KV 4X4MM2 PT | G14: 46113 | H14: Cotação a agregar | I14: 100 | N14: =C14&D14 -> 1643733930
A15: (vazio) | B15: (vazio) | C15: 16437339 | D15: 40 | E15: (vazio) | F15: CABO COB PP 750V4X10MM2 PT | G15: 46113 | H15: Cotação a agregar | I15: 200 | N15: =C15&D15 -> 1643733940
A16: Edney Jean | B16: (vazio) | C16: 16404745 | D16: 160 | E16: 4500612934 | F16: CABO ELET FLEX 750V 1MM2 CZ | G16: 45922 | H16: Escrituração Realizada | I16: 600 | J16: SIm | K16: SIm | N16: =C16&D16 -> 16404745160
A17: Edney Jean | B17: (vazio) | C17: 16404745 | D17: 150 | E17: 4500612934 | F17: CABO ELET FLEX 750V 1MM2 PT | G17: 45922 | H17: Escrituração Realizada | I17: 600 | J17: SIm | K17: SIm | N17: =C17&D17 -> 16404745150
A18: (vazio) | B18: Robson Ferreira | C18: 16437339 | D18: 10 | E18: (vazio) | F18: CABO ELET PP 450 / 750 V 4 X 6MM2 | G18: 46113 | H18: Cotação - em Negociação | I18: 100 | M18: Feito a validação 1.6 | N18: =C18&D18 -> 1643733910
A19: Edson Sanchez | B19: Edson Sanchez | C19: 16426739 | D19: 300 | E19: 4500783774 | F19: CABO ELET PP 450 / 750 V 4 X 6MM2 | G19: 46056 | H19: Aguardando emissão NF | I19: 100 | J19: SIM | N19: =C19&D19 -> 16426739300
A20: Edson Sanchez | B20: Edson Sanchez | C20: 16426739 | D20: 280 | E20: 4500783774 | F20: CABO ELET PP 450/750V4 X 25MM2 PT | G20: 46056 | H20: Aguardando emissão NF | I20: 100 | J20: SIM | N20: =C20&D20 -> 16426739280
A21: Victor L. Lopes | B21: Victor L. Lopes | C21: 16440116 | D21: 640 | E21: 4500842888 | F21: CALCA MANUT OPER BRIM CED RIP ST AZM GG | G21: 46129 | H21: PC - em Aprovação | I21: 18 | N21: =C21&D21 -> 16440116640
A22: Victor L. Lopes | B22: Victor L. Lopes | C22: 16440116 | D22: 650 | E22: 4500842888 | F22: CALCA MANUT OPER BRIM CED RIP ST AZM XG | G22: 46129 | H22: PC - em Aprovação | I22: 15 | N22: =C22&D22 -> 16440116650
A23: Victor L. Lopes | B23: Victor L. Lopes | C23: 16440116 | D23: 660 | E23: 4500842888 | F23: CALCA MANUT OPER BRIM CED RIP STOP AZM G | G23: 46129 | H23: PC - em Aprovação | I23: 18 | N23: =C23&D23 -> 16440116660
A24: Victor L. Lopes | B24: Victor L. Lopes | C24: 16440116 | D24: 670 | E24: 4500842888 | F24: CALCA MANUT OPER BRIM CED RIP STOP AZM M | G24: 46129 | H24: PC - em Aprovação | I24: 11 | N24: =C24&D24 -> 16440116670
A25: Victor L. Lopes | B25: Victor L. Lopes | C25: 16440116 | D25: 680 | E25: 4500842888 | F25: CALCA MANUT OPER BRIM CED RIP STOP AZM P | G25: 46129 | H25: PC - em Aprovação | I25: 9 | N25: =C25&D25 -> 16440116680
A26: Victor L. Lopes | B26: Victor L. Lopes | C26: 16440116 | D26: 690 | E26: 4500842888 | F26: CALCA MANUT OPER BRIM CEDR RIP AZM XXXG | G26: 46129 | H26: PC - em Aprovação | I26: 11 | N26: =C26&D26 -> 16440116690
A27: (vazio) | B27: Victor L. Lopes | C27: 16440116 | D27: 700 | E27: (vazio) | F27: CAMISA UNIF TERM/OP UNIS PES AZ ML GG | G27: 46129 | H27: Cotação - em Negociação | I27: 18 | N27: =C27&D27 -> 16440116700
A28: (vazio) | B28: Victor L. Lopes | C28: 16440116 | D28: 710 | E28: (vazio) | F28: CAMISA UNIF TERM/OP UNIS PES AZ ML TAM G | G28: 46129 | H28: Cotação - em Negociação | I28: 18 | N28: =C28&D28 -> 16440116710
A29: (vazio) | B29: Victor L. Lopes | C29: 16440116 | D29: 720 | E29: (vazio) | F29: CAMISA UNIF TERM/OP UNIS PES AZ ML TAM M | G29: 46129 | H29: Cotação - em Negociação | I29: 11 | N29: =C29&D29 -> 16440116720
A30: (vazio) | B30: Victor L. Lopes | C30: 16440116 | D30: 730 | E30: (vazio) | F30: CAMISA UNIF TERM/OP UNIS PES AZ ML TAM P | G30: 46129 | H30: Cotação - em Negociação | I30: 9 | N30: =C30&D30 -> 16440116730
A31: (vazio) | B31: Victor L. Lopes | C31: 16440116 | D31: 740 | E31: (vazio) | F31: CAMISA UNIF TERM/OP UNIS PES AZ ML XG | G31: 46129 | H31: Cotação - em Negociação | I31: 15 | N31: =C31&D31 -> 16440116740
A32: (vazio) | B32: (vazio) | C32: 16440116 | D32: 750 | E32: (vazio) | F32: CAMISA UNIF TERM/OP UNIS PES AZ ML XXXG | G32: 46129 | H32: Cotação a agregar | I32: 11 | N32: =C32&D32 -> 16440116750
A33: Jocilene Ramos | B33: Jocilene Ramos | C33: 16432794 | D33: 30 | E33: 4500779173 | F33: CARREGADOR PILHA/BAT 2BAT 12V 110/220V | G33: 46090 | H33: Escrituração Realizada | I33: 2 | J33: Sim | K33: Sim | L33: Sim | N33: =C33&D33 -> 1643279430
A34: Luciara Oliveira | B34: Luciara Oliveira | C34: 16426739 | D34: 310 | E34: 4500748195 | F34: CHAVE COMBINADA 15º-10º 34MM | G34: 46056 | H34: Escrituração Realizada | I34: 3 | J34: Sim | K34: não | N34: =C34&D34 -> 16426739310
A35: Sandra Cardoso | B35: Sandra Cardoso | C35: 16401510 | D35: 10 | E35: 4500595429 | F35: CHAVE COMBINADA 15º-10º 36MM | G35: 45902 | H35: Aguardando emissão NF | I35: 3 | J35: SIm | K35: Não | N35: =C35&D35 -> 1640151010
A36: Edney Jean | B36: (vazio) | C36: 16442320 | D36: 20 | E36: 4500814842 | F36: CHAVE COMBINADA JG 15PC 6-32MM | G36: 46141 | H36: Aguardando emissão NF | I36: 10 | J36: #N/A | K36: #N/A | L36: #N/A | M36: #N/A | N36: =C36&D36 -> 1644232020
A37: Edney Jean | B37: (vazio) | C37: 16432794 | D37: 10 | E37: 4500775130 | F37: CINTA CARGA OLHAL 7:1 3T 4M AM | G37: 46090 | H37: Aguardando emissão NF | I37: 10 | N37: =C37&D37 -> 1643279410
A38: Beatriz Serafim | B38: Beatriz Serafim | C38: 16442320 | D38: 10 | E38: 4500827969 | F38: COLA MULTIUSO SPRAY 330G | G38: 46141 | H38: Aguardando emissão NF | I38: 16 | J38: #N/A | K38: #N/A | L38: #N/A | M38: #N/A | N38: =C38&D38 -> 1644232010
A39: Edney Jean | B39: (vazio) | C39: 16425056 | D39: 90 | E39: 4500721455 | F39: CONECTOR DERIV PERF 16-150MM2 | G39: 46045 | H39: Aguardando emissão NF | I39: 40 | J39: Aguardando | N39: =C39&D39 -> 1642505690
A40: (vazio) | B40: (vazio) | C40: 16425056 | D40: 80 | E40: (vazio) | F40: CONECTOR DERIV PERF 50-240MM2 | G40: 46045 | H40: Requisição - Item Concluído | I40: 40 | N40: =C40&D40 -> 1642505680
...

Sheet 27.04
A1: Rótulos de Linha | B1: Comprador Cotação | C1: Requisicao | D1: Item RC | E1: Pedido | F1: Descrição Material | G1: Dt Criação RC | H1: Status Geral | I1: Qtde RC | J1: Chegou? | K1: Foi Retirado? | L1: Cobrado via Email? | M1: Obs: | N1: Chave
A2: Edney Jean | B2: (vazio) | C2: {=_xlfn.XLOOKUP('27.04'!F51 & G2,Export!P:P & Export!H:H,Export!B:B)} -> #N/A | D2: {=_xlfn.XLOOKUP(F2 & G2,Export!P:P & Export!H:H,Export!C:C)} -> 10 | E2: 4500760506 | F2: DISJUNTOR MINI 3P 400VCA 32A | G2: 46073 | H2: Aguardando emissão NF | I2: 10 | N2: =C2&D2 -> #N/A
A3: (vazio) | B3: Edson Sanchez | C3: {=_xlfn.XLOOKUP('27.04'!F71 & G3,Export!P:P & Export!H:H,Export!B:B)} -> #N/A | D3: {=_xlfn.XLOOKUP(F3 & G3,Export!P:P & Export!H:H,Export!C:C)} -> 30 | E3: (vazio) | F3: DISJUNTOR MINI 3P 400VCA 40A | G3: 46073 | H3: Cotação - em Negociação | I3: 10 | N3: =C3&D3 -> #N/A
A4: (vazio) | B4: (vazio) | C4: {=_xlfn.XLOOKUP('27.04'!F81 & G4,Export!P:P & Export!H:H,Export!B:B)} -> #N/A | D4: {=_xlfn.XLOOKUP(F4 & G4,Export!P:P & Export!H:H,Export!C:C)} -> 20 | E4: (vazio) | F4: DISJUNTOR MINI 3P 400VCA 50A | G4: 46073 | H4: Cotação a agregar | I4: 10 | N4: =C4&D4 -> #N/A
A5: Edney Jean | B5: (vazio) | C5: {=_xlfn.XLOOKUP('27.04'!F54 & G5,Export!P:P & Export!H:H,Export!B:B)} -> #N/A | D5: {=_xlfn.XLOOKUP(F5 & G5,Export!P:P & Export!H:H,Export!C:C)} -> 40 | E5: 4500760680 | F5: DISJUNTOR MINI 3P 400VCA 70A | G5: 46073 | H5: Aguardando emissão NF | I5: 15 | N5: =C5&D5 -> #N/A
A6: Edney Jean | B6: (vazio) | C6: {=_xlfn.XLOOKUP('27.04'!F53 & G6,Export!P:P & Export!H:H,Export!B:B)} -> #N/A | D6: {=_xlfn.XLOOKUP(F6 & G6,Export!P:P & Export!H:H,Export!C:C)} -> 140 | E6: 4500760680 | F6: DISJUNTOR TM 3P 400VCA 20A | G6: 46073 | H6: Aguardando emissão NF | I6: 10 | N6: =C6&D6 -> #N/A
A7: Marcilene Carvalho | B7: Marcilene Carvalho | C7: {=_xlfn.XLOOKUP('27.04'!F14 & G7,Export!P:P & Export!H:H,Export!B:B)} -> #N/A | D7: {=_xlfn.XLOOKUP(F7 & G7,Export!P:P & Export!H:H,Export!C:C)} -> 60 | E7: 4500620545 | F7: ELEMENTO ELASTICO E-128 VULKAN | G7: 45922 | H7: Aguardando emissão NF | I7: 4 | J7: SIm | K7: SIm | N7: =C7&D7 -> #N/A
A8: Marcilene Carvalho | B8: Marcilene Carvalho | C8: {=_xlfn.XLOOKUP('27.04'!F16 & G8,Export!P:P & Export!H:H,Export!B:B)} -> #N/A | D8: {=_xlfn.XLOOKUP(F8 & G8,Export!P:P & Export!H:H,Export!C:C)} -> 80 | E8: 4500620545 | F8: ELEMENTO ELASTICO E-148 VULKAN | G8: 45922 | H8: Aguardando emissão NF | I8: 2 | J8: SIm | K8: SIm | N8: =C8&D8 -> #N/A
A9: Marcilene Carvalho | B9: Marcilene Carvalho | C9: {=_xlfn.XLOOKUP('27.04'!F15 & G9,Export!P:P & Export!H:H,Export!B:B)} -> #N/A | D9: {=_xlfn.XLOOKUP(F9 & G9,Export!P:P & Export!H:H,Export!C:C)} -> 70 | E9: 4500620545 | F9: ELEMENTO ELASTICO GE112 VULKAN | G9: 45922 | H9: Aguardando emissão NF | I9: 2 | J9: SIm | K9: SIm | N9: =C9&D9 -> #N/A
A10: Sandra Cardoso | B10: Sandra Cardoso | C10: {=_xlfn.XLOOKUP('27.04'!F9 & G10,Export!P:P & Export!H:H,Export!B:B)} -> 16404745 | D10: {=_xlfn.XLOOKUP(F10 & G10,Export!P:P & Export!H:H,Export!C:C)} -> 90 | E10: 4500682923 | F10: ELETRODO NIVEL HASTE 3/4POL BSP DIGIMEC | G10: 45922 | H10: Aguardando emissão NF | I10: 20 | M10: Valor excessivo | N10: =C10&D10 -> 1640474590
A11: Edney Jean | B11: (vazio) | C11: {=_xlfn.XLOOKUP('27.04'!F57 & G11,Export!P:P & Export!H:H,Export!B:B)} -> #N/A | D11: {=_xlfn.XLOOKUP(F11 & G11,Export!P:P & Export!H:H,Export!C:C)} -> 30 | E11: 4500594849 | F11: ELETRODO PENDULO PO POLIPROPILENO H | G11: 45904 | H11: Escrituração Realizada | I11: 30 | J11: SIm | K11: SIm | N11: =C11&D11 -> #N/A
A12: Sandra Cardoso | B12: Sandra Cardoso | C12: {=_xlfn.XLOOKUP('27.04'!F10 & G12,Export!P:P & Export!H:H,Export!B:B)} -> #N/A | D12: {=_xlfn.XLOOKUP(F12 & G12,Export!P:P & Export!H:H,Export!C:C)} -> 10 | E12: 4500564848 | F12: ESCADA EXTENSIVEL 6 M | G12: 45855 | H12: Escrituração Realizada | I12: 2 | J12: SIm | K12: SIm | N12: =C12&D12 -> #N/A
A13: (vazio) | B13: (vazio) | C13: {=_xlfn.XLOOKUP('27.04'!F89 & G13,Export!P:P & Export!H:H,Export!B:B)} -> #N/A | D13: {=_xlfn.XLOOKUP(F13 & G13,Export!P:P & Export!H:H,Export!C:C)} -> 70 | E13: (vazio) | F13: ESCADA EXTENSIVEL 6 M | G13: 46122 | H13: Requisição - Item Bloqueado | I13: 2 | N13: =C13&D13 -> #N/A
A14: (vazio) | B14: (vazio) | C14: {=_xlfn.XLOOKUP('27.04'!F119 & G14,Export!P:P & Export!H:H,Export!B:B)} -> #N/A | D14: {=_xlfn.XLOOKUP(F14 & G14,Export!P:P & Export!H:H,Export!C:C)} -> 50 | E14: (vazio) | F14: FERRAMENTA ALINHAM POLIA 2,1MW | G14: 46073 | H14: Requisição - Item Eliminado | I14: 1 | N14: =C14&D14 -> #N/A
A15: Edney Jean | B15: (vazio) | C15: {=_xlfn.XLOOKUP('27.04'!F59 & G15,Export!P:P & Export!H:H,Export!B:B)} -> #N/A | D15: {=_xlfn.XLOOKUP(F15 & G15,Export!P:P & Export!H:H,Export!C:C)} -> 10 | E15: 4500721581 | F15: FITA ISOL PR 750V 19MM ROL 20M | G15: 46045 | H15: Escrituração Realizada | I15: 150 | J15: SIm | K15: SIm | N15: =C15&D15 -> #N/A
A16: Edney Jean | B16: (vazio) | C16: {=_xlfn.XLOOKUP('27.04'!F61 & G16,Export!P:P & Export!H:H,Export!B:B)} -> #N/A | D16: {=_xlfn.XLOOKUP(F16 & G16,Export!P:P & Export!H:H,Export!C:C)} -> 20 | E16: 4500721581 | F16: FITA ISOLANTE AUTOFUSAO PT 10M 19MM | G16: 46045 | H16: Escrituração Realizada | I16: 100 | J16: SIm | K16: SIm | N16: =C16&D16 -> #N/A
A17: Amanda Oliva | B17: Amanda Oliva | C17: {=_xlfn.XLOOKUP('27.04'!F69 & G17,Export!P:P & Export!H:H,Export!B:B)} -> #N/A | D17: {=_xlfn.XLOOKUP(F17 & G17,Export!P:P & Export!H:H,Export!C:C)} -> 20 | E17: 4500629184 | F17: FITA ROTULADOR 12MM 8M 1UN | G17: 45930 | H17: Escrituração Realizada | I17: 5 | J17: SIm | K17: SIm | N17: =C17&D17 -> #N/A
A18: (vazio) | B18: Fernando Gonçalo | C18: {=_xlfn.XLOOKUP('27.04'!F72 & G18,Export!P:P & Export!H:H,Export!B:B)} -> #N/A | D18: {=_xlfn.XLOOKUP(F18 & G18,Export!P:P & Export!H:H,Export!C:C)} -> 30 | E18: (vazio) | F18: FURADEIRA ELET IMP 3250RPM | G18: 46073 | H18: Cotação - em Negociação | I18: 1 | N18: =C18&D18 -> #N/A
A19: (vazio) | B19: Edson Sanchez | C19: {=_xlfn.XLOOKUP('27.04'!F70 & G19,Export!P:P & Export!H:H,Export!B:B)} -> 16429923 | D19: {=_xlfn.XLOOKUP(F19 & G19,Export!P:P & Export!H:H,Export!C:C)} -> 100 | E19: (vazio) | F19: FUSIVEL NH LAMINA 500V 100A | G19: 46073 | H19: Cotação - em Negociação | I19: 10 | N19: =C19&D19 -> 16429923100
A20: Edney Jean | B20: (vazio) | C20: {=_xlfn.XLOOKUP('27.04'!F55 & G20,Export!P:P & Export!H:H,Export!B:B)} -> #N/A | D20: {=_xlfn.XLOOKUP(F20 & G20,Export!P:P & Export!H:H,Export!C:C)} -> 90 | E20: 4500760680 | F20: FUSIVEL NH LAMINA 500V 80A | G20: 46073 | H20: Aguardando emissão NF | I20: 10 | N20: =C20&D20 -> #N/A
A21: Edney Jean | B21: (vazio) | C21: {=_xlfn.XLOOKUP('27.04'!F52 & G21,Export!P:P & Export!H:H,Export!B:B)} -> #N/A | D21: {=_xlfn.XLOOKUP(F21 & G21,Export!P:P & Export!H:H,Export!C:C)} -> 110 | E21: 4500760504 | F21: FUSIVEL NH00 LAMINA 500V 160A | G21: 46073 | H21: Aguardando emissão NF | I21: 10 | N21: =C21&D21 -> #N/A
A22: (vazio) | B22: (vazio) | C22: {=_xlfn.XLOOKUP('27.04'!F99 & G22,Export!P:P & Export!H:H,Export!B:B)} -> #N/A | D22: {=_xlfn.XLOOKUP(F22 & G22,Export!P:P & Export!H:H,Export!C:C)} -> 140 | E22: (vazio) | F22: FUSIVEL NH01 ULTRA-RAPIDO 690V 200A AR | G22: 46122 | H22: Requisição - Item Bloqueado | I22: 21 | N22: =C22&D22 -> #N/A
A23: (vazio) | B23: (vazio) | C23: {=_xlfn.XLOOKUP('27.04'!F100 & G23,Export!P:P & Export!H:H,Export!B:B)} -> #N/A | D23: {=_xlfn.XLOOKUP(F23 & G23,Export!P:P & Export!H:H,Export!C:C)} -> 150 | E23: (vazio) | F23: FUSIVEL NH01 ULTRA-RAPIDO 690V 63A AR | G23: 46122 | H23: Requisição - Item Bloqueado | I23: 21 | N23: =C23&D23 -> #N/A
A24: (vazio) | B24: (vazio) | C24: {=_xlfn.XLOOKUP('27.04'!F101 & G24,Export!P:P & Export!H:H,Export!B:B)} -> #N/A | D24: {=_xlfn.XLOOKUP(F24 & G24,Export!P:P & Export!H:H,Export!C:C)} -> 160 | E24: (vazio) | F24: FUSIVEL NH02 ULTRA-RAPIDO 690V 250A AR | G24: 46122 | H24: Requisição - Item Bloqueado | I24: 21 | N24: =C24&D24 -> #N/A
A25: (vazio) | B25: (vazio) | C25: {=_xlfn.XLOOKUP('27.04'!F102 & G25,Export!P:P & Export!H:H,Export!B:B)} -> #N/A | D25: {=_xlfn.XLOOKUP(F25 & G25,Export!P:P & Export!H:H,Export!C:C)} -> 20 | E25: (vazio) | F25: FUSIVEL ULTRA-RAPIDO 100A 690V 00 | G25: 46122 | H25: Requisição - Item Bloqueado | I25: 27 | N25: =C25&D25 -> #N/A
A26: (vazio) | B26: (vazio) | C26: {=_xlfn.XLOOKUP('27.04'!F103 & G26,Export!P:P & Export!H:H,Export!B:B)} -> #N/A | D26: {=_xlfn.XLOOKUP(F26 & G26,Export!P:P & Export!H:H,Export!C:C)} -> 30 | E26: (vazio) | F26: FUSIVEL ULTRA-RAPIDO 125A 690V 00 | G26: 46122 | H26: Requisição - Item Bloqueado | I26: 27 | N26: =C26&D26 -> #N/A
A27: (vazio) | B27: (vazio) | C27: {=_xlfn.XLOOKUP('27.04'!F104 & G27,Export!P:P & Export!H:H,Export!B:B)} -> #N/A | D27: {=_xlfn.XLOOKUP(F27 & G27,Export!P:P & Export!H:H,Export!C:C)} -> 40 | E27: (vazio) | F27: FUSIVEL ULTRA-RAPIDO 160A 100KVA | G27: 46122 | H27: Requisição - Item Bloqueado | I27: 21 | N27: =C27&D27 -> #N/A
A28: (vazio) | B28: (vazio) | C28: {=_xlfn.XLOOKUP('27.04'!F105 & G28,Export!P:P & Export!H:H,Export!B:B)} -> #N/A | D28: {=_xlfn.XLOOKUP(F28 & G28,Export!P:P & Export!H:H,Export!C:C)} -> 50 | E28: (vazio) | F28: FUSIVEL ULTRA-RAPIDO 350A 690V | G28: 46122 | H28: Requisição - Item Bloqueado | I28: 21 | N28: =C28&D28 -> #N/A
A29: (vazio) | B29: (vazio) | C29: {=_xlfn.XLOOKUP('27.04'!F106 & G29,Export!P:P & Export!H:H,Export!B:B)} -> #N/A | D29: {=_xlfn.XLOOKUP(F29 & G29,Export!P:P & Export!H:H,Export!C:C)} -> 60 | E29: (vazio) | F29: FUSIVEL ULTRA-RAPIDO 35A 690V 000 | G29: 46122 | H29: Requisição - Item Bloqueado | I29: 27 | N29: =C29&D29 -> #N/A
A30: (vazio) | B30: (vazio) | C30: {=_xlfn.XLOOKUP('27.04'!F107 & G30,Export!P:P & Export!H:H,Export!B:B)} -> #N/A | D30: {=_xlfn.XLOOKUP(F30 & G30,Export!P:P & Export!H:H,Export!C:C)} -> 70 | E30: (vazio) | F30: FUSIVEL ULTRA-RAPIDO 50A 690V 000 | G30: 46122 | H30: Requisição - Item Bloqueado | I30: 27 | N30: =C30&D30 -> #N/A
A31: (vazio) | B31: (vazio) | C31: {=_xlfn.XLOOKUP('27.04'!F108 & G31,Export!P:P & Export!H:H,Export!B:B)} -> #N/A | D31: {=_xlfn.XLOOKUP(F31 & G31,Export!P:P & Export!H:H,Export!C:C)} -> 80 | E31: (vazio) | F31: FUSIVEL ULTRA-RAPIDO 80A 690V 000 | G31: 46122 | H31: Requisição - Item Bloqueado | I31: 27 | N31: =C31&D31 -> #N/A
A32: (vazio) | B32: (vazio) | C32: {=_xlfn.XLOOKUP('27.04'!F109 & G32,Export!P:P & Export!H:H,Export!B:B)} -> #N/A | D32: {=_xlfn.XLOOKUP(F32 & G32,Export!P:P & Export!H:H,Export!C:C)} -> 90 | E32: (vazio) | F32: FUSIVEL ULTRA-RAPIDO NH-1 160A 690V | G32: 46122 | H32: Requisição - Item Bloqueado | I32: 21 | N32: =C32&D32 -> #N/A
A33: (vazio) | B33: (vazio) | C33: {=_xlfn.XLOOKUP('27.04'!F95 & G33,Export!P:P & Export!H:H,Export!B:B)} -> #N/A | D33: {=_xlfn.XLOOKUP(F33 & G33,Export!P:P & Export!H:H,Export!C:C)} -> 100 | E33: (vazio) | F33: FUSIVEL ULTRA-RAPIDO NH2 315A 690V | G33: 46122 | H33: Requisição - Item Bloqueado | I33: 21 | N33: =C33&D33 -> #N/A
A34: (vazio) | B34: (vazio) | C34: {=_xlfn.XLOOKUP('27.04'!F96 & G34,Export!P:P & Export!H:H,Export!B:B)} -> #N/A | D34: {=_xlfn.XLOOKUP(F34 & G34,Export!P:P & Export!H:H,Export!C:C)} -> 110 | E34: (vazio) | F34: FUSIVEL ULTRA-RAPIDO NH-2 630A 690V | G34: 46122 | H34: Requisição - Item Bloqueado | I34: 21 | N34: =C34&D34 -> #N/A
A35: (vazio) | B35: (vazio) | C35: {=_xlfn.XLOOKUP('27.04'!F97 & G35,Export!P:P & Export!H:H,Export!B:B)} -> #N/A | D35: {=_xlfn.XLOOKUP(F35 & G35,Export!P:P & Export!H:H,Export!C:C)} -> 120 | E35: (vazio) | F35: FUSIVEL ULTRA-RAPIDO SITOR 40A 690V | G35: 46122 | H35: Requisição - Item Bloqueado | I35: 21 | N35: =C35&D35 -> #N/A
A36: (vazio) | B36: (vazio) | C36: {=_xlfn.XLOOKUP('27.04'!F98 & G36,Export!P:P & Export!H:H,Export!B:B)} -> #N/A | D36: {=_xlfn.XLOOKUP(F36 & G36,Export!P:P & Export!H:H,Export!C:C)} -> 130 | E36: (vazio) | F36: FUSIVEL ULTRA-RAPIDO SITOR 63A 690V | G36: 46122 | H36: Requisição - Item Bloqueado | I36: 21 | N36: =C36&D36 -> #N/A
A37: (vazio) | B37: (vazio) | C37: {=_xlfn.XLOOKUP('27.04'!F86 & G37,Export!P:P & Export!H:H,Export!B:B)} -> #N/A | D37: {=_xlfn.XLOOKUP(F37 & G37,Export!P:P & Export!H:H,Export!C:C)} -> 40 | E37: (vazio) | F37: GARRAFA TERMICA 5L | G37: 46122 | H37: Requisição - Item Bloqueado | I37: 10 | N37: =C37&D37 -> #N/A
A38: (vazio) | B38: (vazio) | C38: {=_xlfn.XLOOKUP('27.04'!F120 & G38,Export!P:P & Export!H:H,Export!B:B)} -> #N/A | D38: {=_xlfn.XLOOKUP(F38 & G38,Export!P:P & Export!H:H,Export!C:C)} -> 10 | E38: (vazio) | F38: GARRAFA TERMICA 5L | G38: 46111 | H38: Requisição - Item Eliminado | I38: 1 | N38: =C38&D38 -> #N/A
A39: (vazio) | B39: (vazio) | C39: {=_xlfn.XLOOKUP('27.04'!F93 & G39,Export!P:P & Export!H:H,Export!B:B)} -> #N/A | D39: {=_xlfn.XLOOKUP(F39 & G39,Export!P:P & Export!H:H,Export!C:C)} -> 30 | E39: (vazio) | F39: GAXETA CORD QUAD 1/2POL | G39: 46122 | H39: Requisição - Item Bloqueado | I39: 5 | N39: =C39&D39 -> #N/A
A40: (vazio) | B40: (vazio) | C40: {=_xlfn.XLOOKUP('27.04'!F111 & G40,Export!P:P & Export!H:H,Export!B:B)} -> #N/A | D40: {=_xlfn.XLOOKUP(F40 & G40,Export!P:P & Export!H:H,Export!C:C)} -> 50 | E40: (vazio) | F40: GAXETA CORD QUAD 1/2POL | G40: 45902 | H40: Requisição - Item Concluído | I40: 1 | N40: =C40&D40 -> #N/A
...

Sheet 01.06
A1: Rótulos de Linha | B1: Comprador Cotação | C1: Requisicao | D1: Item RC | E1: Pedido | F1: Descrição Material | G1: Dt Criação RC | H1: Status Geral | I1: Qtde RC | J1: Chegou? | K1: Foi Retirado? | L1: Cobrado via Email? | M1: Obs: | N1: Chave
A2: Luciara Oliveira | B2: Luciara Oliveira | C2: 16362199 | D2: 2130 | E2: 4500437805 | F2: ANEL BORR ABF FLANGE FOFO DN100MM | G2: 45659 | H2: Escrituração Realizada | I2: 2 | J2: SIm | K2: SIm | N2: =C2&D2 -> 163621992130
A3: Luciara Oliveira | B3: Luciara Oliveira | C3: 16362199 | D3: 500 | E3: 4500437805 | F3: ANEL BORR ABF FLANGE FOFO DN100MM | G3: 45659 | H3: Escrituração Realizada | I3: 2 | J3: SIm | K3: SIm | N3: =C3&D3 -> 16362199500
A4: Victor L. Lopes | B4: Victor L. Lopes | C4: 16378221 | D4: 10 | E4: 4500509387 | F4: BASTAO RESGATE FIBRA VID 34,5KV 2,28M | G4: 45754 | H4: PC - em Aprovação | I4: 4 | N4: =C4&D4 -> 1637822110
A5: Sandra Cardoso | B5: Sandra Cardoso | C5: 16394071 | D5: 10 | E5: 4500564848 | F5: ESCADA EXTENSIVEL 6 M | G5: 45855 | H5: Escrituração Realizada | I5: 2 | J5: SIm | K5: SIm | N5: =C5&D5 -> 1639407110
A6: (vazio) | B6: (vazio) | C6: 16394075 | D6: 10 | E6: (vazio) | F6: BOMBA MANUAL GRAX 12G 7KG | G6: 45855 | H6: Requisição - Item Concluído | I6: 10 | J6: Não | K6: Não | M6: CANCELADO | N6: =C6&D6 -> 1639407510
A7: Sandra Cardoso | B7: Sandra Cardoso | C7: 16401510 | D7: 10 | E7: 4500595429 | F7: CHAVE COMBINADA 15º-10º 36MM | G7: 45902 | H7: Aguardando emissão NF | I7: 3 | J7: SIm | K7: Não | N7: =C7&D7 -> 1640151010
A8: (vazio) | B8: (vazio) | C8: 16401510 | D8: 20 | E8: (vazio) | F8: DESENGRIPANTE LIQ AM SPR 300ML | G8: 45902 | H8: Requisição - Item Concluído | I8: 30 | J8: Não | K8: Não | M8: CANCELADO | N8: =C8&D8 -> 1640151020
A9: (vazio) | B9: (vazio) | C9: 16401510 | D9: 50 | E9: (vazio) | F9: GAXETA CORD QUAD 1/2POL | G9: 45902 | H9: Requisição - Item Concluído | I9: 1 | J9: Não | K9: Não | M9: CANCELADO | N9: =C9&D9 -> 1640151050
A10: (vazio) | B10: (vazio) | C10: 16401510 | D10: 60 | E10: (vazio) | F10: GAXETA CORDAO QUADR 5/8POL | G10: 45902 | H10: Requisição - Item Concluído | I10: 1 | J10: Não | K10: Não | M10: CANCELADO | N10: =C10&D10 -> 1640151060
A11: Marcilene Carvalho | B11: Marcilene Carvalho | C11: 16401510 | D11: 40 | E11: 4500598336 | F11: ROLAMENTO ESF RIG 6209 ZZ C3 SKF | G11: 45902 | H11: Aguardando emissão NF | I11: 6 | N11: =C11&D11 -> 1640151040
A12: Marcilene Carvalho | B12: Marcilene Carvalho | C12: 16401510 | D12: 30 | E12: 4500598336 | F12: ROLAMENTO ESF RIG 6309-2Z/C3 SKF | G12: 45902 | H12: Aguardando emissão NF | I12: 6 | N12: =C12&D12 -> 1640151030
A13: Edney Jean | B13: (vazio) | C13: 16401860 | D13: 30 | E13: 4500594849 | F13: ELETRODO PENDULO PO POLIPROPILENO H | G13: 45904 | H13: Escrituração Realizada | I13: 30 | J13: SIm | K13: SIm | N13: =C13&D13 -> 1640186030
A14: Marcilene Carvalho | B14: Marcilene Carvalho | C14: 16401860 | D14: 10 | E14: 4500600032 | F14: SELO MECANICO TS-P 1.1/4POL | G14: 45904 | H14: Escrituração Realizada | I14: 10 | J14: SIm | K14: SIm | N14: =C14&D14 -> 1640186010
A15: Marcilene Carvalho | B15: Marcilene Carvalho | C15: 16401860 | D15: 20 | E15: 4500600032 | F15: SELO MECANICO TS-P 1.3/4POL | G15: 45904 | H15: Escrituração Realizada | I15: 10 | J15: SIm | K15: SIm | N15: =C15&D15 -> 1640186020
A16: Edney Jean | B16: (vazio) | C16: 16404745 | D16: 150 | E16: 4500612934 | F16: CABO ELET FLEX 750V 1MM2 PT | G16: 45922 | H16: Escrituração Realizada | I16: 600 | J16: SIm | K16: SIm | N16: =C16&D16 -> 16404745150
A17: Edney Jean | B17: (vazio) | C17: 16404745 | D17: 160 | E17: 4500612934 | F17: CABO ELET FLEX 750V 1MM2 CZ | G17: 45922 | H17: Escrituração Realizada | I17: 600 | J17: SIm | K17: SIm | N17: =C17&D17 -> 16404745160
A18: Luciara Oliveira | B18: Luciara Oliveira | C18: 16404745 | D18: 100 | E18: 4500619102 | F18: BARRA ROSCADA AC 1020 1/2POL UNC 1M | G18: 45922 | H18: Escrituração Realizada | I18: 10 | N18: =C18&D18 -> 16404745100
A19: Marcilene Carvalho | B19: Marcilene Carvalho | C19: 16404745 | D19: 20 | E19: 4500620544 | F19: ROLAMENTO ESF RIG 6203ZZ B EEMS NSK | G19: 45922 | H19: Escrituração Final Realizada | I19: 3 | N19: =C19&D19 -> 1640474520
A20: Marcilene Carvalho | B20: Marcilene Carvalho | C20: 16404745 | D20: 110 | E20: 4500621638 | F20: PORCA AC 1020 1/2POL | G20: 45922 | H20: Escrituração Realizada | I20: 50 | N20: =C20&D20 -> 16404745110
A21: Marcilene Carvalho | B21: Marcilene Carvalho | C21: 16404745 | D21: 120 | E21: 4500621638 | F21: PORCA AC 1020 3/4POL | G21: 45922 | H21: Escrituração Realizada | I21: 100 | N21: =C21&D21 -> 16404745120
A22: Marcilene Carvalho | B22: Marcilene Carvalho | C22: 16404745 | D22: 130 | E22: 4500621638 | F22: PORCA AC 1020 5/16POL | G22: 45922 | H22: Escrituração Realizada | I22: 100 | N22: =C22&D22 -> 16404745130
A23: Marcilene Carvalho | B23: Marcilene Carvalho | C23: 16404745 | D23: 140 | E23: 4500621638 | F23: PORCA SEXT AC 1020 1POL | G23: 45922 | H23: Escrituração Realizada | I23: 50 | N23: =C23&D23 -> 16404745140
A24: Marcilene Carvalho | B24: Marcilene Carvalho | C24: 16404745 | D24: 30 | E24: 4500618537 | F24: LUVA ACOPLAMENTO 240MM | G24: 45922 | H24: Escrituração Realizada | I24: 2 | J24: SIm | K24: SIm | N24: =C24&D24 -> 1640474530
A25: Marcilene Carvalho | B25: Marcilene Carvalho | C25: 16404745 | D25: 40 | E25: 4500618537 | F25: LUVA ACOPLAMENTO 194MM | G25: 45922 | H25: Escrituração Realizada | I25: 4 | J25: SIm | K25: SIm | N25: =C25&D25 -> 1640474540
A26: Marcilene Carvalho | B26: Marcilene Carvalho | C26: 16404745 | D26: 50 | E26: 4500618537 | F26: LUVA ACOPLAMENTO 168MM | G26: 45922 | H26: Escrituração Realizada | I26: 4 | J26: SIm | K26: SIm | N26: =C26&D26 -> 1640474550
A27: Marcilene Carvalho | B27: Marcilene Carvalho | C27: 16404745 | D27: 60 | E27: 4500620545 | F27: ELEMENTO ELASTICO E-128 VULKAN | G27: 45922 | H27: Aguardando emissão NF | I27: 4 | J27: SIm | K27: SIm | N27: =C27&D27 -> 1640474560
A28: Marcilene Carvalho | B28: Marcilene Carvalho | C28: 16404745 | D28: 70 | E28: 4500620545 | F28: ELEMENTO ELASTICO GE112 VULKAN | G28: 45922 | H28: Aguardando emissão NF | I28: 2 | J28: SIm | K28: SIm | N28: =C28&D28 -> 1640474570
A29: Marcilene Carvalho | B29: Marcilene Carvalho | C29: 16404745 | D29: 80 | E29: 4500620545 | F29: ELEMENTO ELASTICO E-148 VULKAN | G29: 45922 | H29: Aguardando emissão NF | I29: 2 | J29: SIm | K29: SIm | N29: =C29&D29 -> 1640474580
A30: Sandra Cardoso | B30: Sandra Cardoso | C30: 16404745 | D30: 90 | E30: 4500682923 | F30: ELETRODO NIVEL HASTE 3/4POL BSP DIGIMEC | G30: 45922 | H30: Aguardando emissão NF | I30: 20 | M30: Valor excessivo | N30: =C30&D30 -> 1640474590
A31: Marcilene Carvalho | B31: Marcilene Carvalho | C31: 16404745 | D31: 10 | E31: 4500620544 | F31: ROLAMENTO ESF RIG 6213ZC3 NSK | G31: 45922 | H31: Escrituração Final Realizada | I31: 6 | N31: =C31&D31 -> 1640474510
A32: Amanda Oliva | B32: Amanda Oliva | C32: 16405989 | D32: 20 | E32: 4500629184 | F32: FITA ROTULADOR 12MM 8M 1UN | G32: 45930 | H32: Escrituração Realizada | I32: 5 | J32: SIm | K32: SIm | N32: =C32&D32 -> 1640598920
A33: Gislene Rodrigues | B33: Gislene Rodrigues | C33: 16405989 | D33: 10 | E33: 4500633639 | F33: ROTULADOR ELETRON AUTOM 230DPI 7,5MM/S | G33: 45930 | H33: Escrituração Realizada | I33: 1 | J33: SIm | K33: SIm | N33: =C33&D33 -> 1640598910
A34: Edney Jean | B34: (vazio) | C34: 16407867 | D34: 50 | E34: 4500640315 | F34: VALVULA RET DUPLA FOFO WAF D200 150 | G34: 45940 | H34: Escrituração Realizada | I34: 4 | N34: =C34&D34 -> 1640786750
A35: (vazio) | B35: (vazio) | C35: 16407867 | D35: 10 | E35: (vazio) | F35: VALVULA RET DUPLA FOFO WAF D50 16BAR | G35: 45940 | H35: Requisição - Item Eliminado | I35: 10 | N35: =C35&D35 -> 1640786710
A36: (vazio) | B36: (vazio) | C36: 16407867 | D36: 20 | E36: (vazio) | F36: VALVULA RET HOR UNICA BZ BSP D2 PN16 | G36: 45940 | H36: Requisição - Item Eliminado | I36: 10 | N36: =C36&D36 -> 1640786720
A37: (vazio) | B37: (vazio) | C37: 16407867 | D37: 30 | E37: (vazio) | F37: VALVULA RET DUPLA FOFO WAF D65 16BAR | G37: 45940 | H37: Requisição - Item Concluído | I37: 2 | N37: =C37&D37 -> 1640786730
A38: (vazio) | B38: (vazio) | C38: 16407867 | D38: 40 | E38: (vazio) | F38: VALVULA RET DUPLA FOFO WAF D100 16BAR | G38: 45940 | H38: Requisição - Item Eliminado | I38: 6 | N38: =C38&D38 -> 1640786740
A39: Amanda Oliva | B39: (vazio) | C39: 16411558 | D39: 20 | E39: 4500645232 | F39: BATERIA ALCAL RECARREGAVEL 9V 250MAH | G39: 45961 | H39: Escrituração Realizada | I39: 20 | J39: SIm | K39: SIm | N39: =C39&D39 -> 1641155820
A40: Edney Jean | B40: (vazio) | C40: 16411558 | D40: 10 | E40: 4500645222 | F40: ALICATE AMPERIMETRO DIGITAL 20/200/1000A | G40: 45961 | H40: Escrituração Realizada | I40: 7 | J40: SIm | K40: SIm | N40: =C40&D40 -> 1641155810
...

Sheet Pedidos projetos
A1: Comprador Cotação | B1: Requisicao | C1: Item RC | D1: Pedido | E1: Descrição Material | F1: Dt Criação RC | G1: Status Geral | H1: Qtde RC | I1: Chegou? | J1: Foi Retirado? | K1: Cobrado via Email? | L1: Obs: | M1: Chave
A2: Sandra Cardoso | B2: 16408698 | C2: 10 | D2: 4500678166 | E2: BATERIA ALCALINA 2700MAH 4,5V | F2: 45945 | G2: Aguardando emissão NF | H2: 30

Sheet Dash
A1: Rótulos de Linha | B1: Comprador Cotação | C1: Requisicao | D1: Item RC | E1: Pedido | F1: Descrição Material | G1: Dt Criação RC | H1: Status Geral | I1: Qtde RC | J1: Chegou? | K1: Foi Retirado? | L1: Cobrado via Email? | M1: Obs:
A2: Amanda Oliva | B2: Amanda Oliva | C2: 16405989 | D2: 20 | E2: 4500629184 | F2: FITA ROTULADOR 12MM 8M 1UN | G2: 45930 | H2: Escrituração Realizada | I2: 5 | J2: SIm | K2: SIm
A3: Amanda Oliva | B3: (vazio) | C3: 16411558 | D3: 20 | E3: 4500645232 | F3: BATERIA ALCAL RECARREGAVEL 9V 250MAH | G3: 45961 | H3: Escrituração Realizada | I3: 20 | J3: SIm | K3: SIm
A4: Amanda Oliva | B4: (vazio) | C4: 16438863 | D4: 40 | E4: 4500814863 | F4: GARRAFA TERMICA 5L | G4: 46122 | H4: Escrituração Realizada | I4: 10
A5: André Queiroz | B5: André Queiroz | C5: 16428381 | D5: 10 | E5: 4500750655 | F5: MARCADOR IND 2MM AMARELA TB 60ML | G5: 46063 | H5: Escrituração Realizada | I5: 3 | J5: SIm | K5: SIm
A6: André Queiroz | B6: André Queiroz | C6: 16430051 | D6: 10 | E6: 4500751393 | F6: MASSA PLAST PAST CZ LT 400GR | G6: 46073 | H6: Escrituração Realizada | I6: 10
A7: André Queiroz | B7: André Queiroz | C7: 16430051 | D7: 20 | E7: 4500751385 | F7: ADESIVO RESINA EPOXI 16G | G7: 46073 | H7: Escrituração Realizada | I7: 10
A8: André Queiroz | B8: André Queiroz | C8: 16444659 | D8: 10 | E8: 4500856471 | F8: TORQUIMETRO ESTALO 3/8POL 10-60NM | G8: 46150 | H8: Aguardando emissão NF | I8: 2
A9: André Queiroz | B9: André Queiroz | C9: 16444659 | D9: 20 | E9: 4500856471 | F9: TORQUIMETRO ESTALO 1/2POL 10-60NM | G9: 46150 | H9: Aguardando emissão NF | I9: 2 | J9: SIm | K9: SIm
A10: Beatriz Serafim | B10: Beatriz Serafim | C10: 16421260 | D10: 10 | E10: 4500716344 | F10: MASSA PLAST PAST CZ LT 400GR | G10: 46024 | H10: Escrituração Realizada | I10: 10
A11: Beatriz Serafim | B11: Beatriz Serafim | C11: 16421260 | D11: 20 | E11: 4500716344 | F11: ADESIVO RESINA EPOXI 16G | G11: 46024 | H11: Escrituração Realizada | I11: 10
A12: Beatriz Serafim | B12: Beatriz Serafim | C12: 16432794 | D12: 60 | E12: 4500782412 | F12: LENCOL BORR PT 2MM | G12: 46090 | H12: Escrituração Realizada | I12: 2 | J12: SIm | K12: SIm
A13: Beatriz Serafim | B13: Beatriz Serafim | C13: 16432794 | D13: 70 | E13: 4500782408 | F13: LENCOL BORR PT 3MM | G13: 46090 | H13: Aguardando emissão NF | I13: 5
A14: Beatriz Serafim | B14: Beatriz Serafim | C14: 16432794 | D14: 80 | E14: 4500782412 | F14: LENCOL BORR PT 4MM | G14: 46090 | H14: Escrituração Realizada | I14: 5
A15: Beatriz Serafim | B15: Beatriz Serafim | C15: 16442320 | D15: 10 | E15: 4500827969 | F15: COLA MULTIUSO SPRAY 330G | G15: 46141 | H15: Escrituração Realizada | I15: 16
A16: Edney Jean | B16: (vazio) | C16: 16401860 | D16: 30 | E16: 4500594849 | F16: ELETRODO PENDULO PO POLIPROPILENO H | G16: 45904 | H16: Escrituração Realizada | I16: 30
A17: Edney Jean | B17: (vazio) | C17: 16404745 | D17: 150 | E17: 4500612934 | F17: CABO ELET FLEX 750V 1MM2 PT | G17: 45922 | H17: Escrituração Realizada | I17: 600
A18: Edney Jean | B18: (vazio) | C18: 16404745 | D18: 160 | E18: 4500612934 | F18: CABO ELET FLEX 750V 1MM2 CZ | G18: 45922 | H18: Escrituração Realizada | I18: 600
A19: Edney Jean | B19: (vazio) | C19: 16407867 | D19: 50 | E19: 4500640315 | F19: VALVULA RET DUPLA FOFO WAF D200 150 | G19: 45940 | H19: Escrituração Realizada | I19: 4
A20: Edney Jean | B20: (vazio) | C20: 16411558 | D20: 10 | E20: 4500645222 | F20: ALICATE AMPERIMETRO DIGITAL 20/200/1000A | G20: 45961 | H20: Escrituração Realizada | I20: 7
A21: Edney Jean | B21: (vazio) | C21: 16425056 | D21: 10 | E21: 4500721581 | F21: FITA ISOL PR 750V 19MM ROL 20M | G21: 46045 | H21: Escrituração Realizada | I21: 150
A22: Edney Jean | B22: (vazio) | C22: 16425056 | D22: 100 | E22: 4500737223 | F22: JG CHAVE FENDA SIMP CRUZ ISOL 1000V 7UN | G22: 46045 | H22: Escrituração Realizada | I22: 15
A23: Edney Jean | B23: (vazio) | C23: 16425056 | D23: 20 | E23: 4500721581 | F23: FITA ISOLANTE AUTOFUSAO PT 10M 19MM | G23: 46045 | H23: Escrituração Realizada | I23: 100
A24: Edney Jean | B24: (vazio) | C24: 16425056 | D24: 90 | E24: 4500721455 | F24: CONECTOR DERIV PERF 16-150MM2 | G24: 46045 | H24: Aguardando emissão NF | I24: 40
A25: Edney Jean | B25: (vazio) | C25: 16426739 | D25: 210 | E25: 4500738264 | F25: LUVA PROT TERMICA AGENTES MEC 10/GG | G25: 46056 | H25: Escrituração Realizada | I25: 20 | J25: SIm
A26: Edney Jean | B26: (vazio) | C26: 16426739 | D26: 220 | E26: 4500738264 | F26: LUVA PROT TERMICA AGENTES MEC 9/G | G26: 46056 | H26: Escrituração Realizada | I26: 20
A27: Edney Jean | B27: (vazio) | C27: 16426739 | D27: 290 | E27: 4500737679 | F27: DISCO CORTE S/REV 115MM 22,22MM 1MM META | G27: 46056 | H27: Aguardando emissão NF | I27: 50
A28: Edney Jean | B28: (vazio) | C28: 16428381 | D28: 20 | E28: 4500740122 | F28: RELE TEMPORIZADO TENSAO ALIMENTACAO 100 | G28: 46063 | H28: Aguardando emissão NF | I28: 3
A29: Edney Jean | B29: (vazio) | C29: 16428381 | D29: 50 | E29: 4500737715 | F29: RELE NIVEL INF SUP 220/380V 50/60HZ IP20 | G29: 46063 | H29: Escrituração Realizada | I29: 15
A30: Edney Jean | B30: (vazio) | C30: 16429923 | D30: 10 | E30: 4500760393 | F30: PARAFUSADEIRA FURADEIRA 110/220V | G30: 46073 | H30: Aguardando emissão NF | I30: 1
A31: Edney Jean | B31: (vazio) | C31: 16429989 | D31: 10 | E31: 4500760506 | F31: DISJUNTOR MINI 3P 400VCA 32A | G31: 46073 | H31: Escrituração Realizada | I31: 10
A32: Edney Jean | B32: (vazio) | C32: 16429989 | D32: 110 | E32: 4500760504 | F32: FUSIVEL NH00 LAMINA 500V 160A | G32: 46073 | H32: Aguardando emissão NF | I32: 10
A33: Edney Jean | B33: (vazio) | C33: 16429989 | D33: 130 | E33: 4500760489 | F33: DISJUNTOR MINI 3P 220/380VCA 80A | G33: 46073 | H33: Escrituração Realizada | I33: 10
A34: Edney Jean | B34: (vazio) | C34: 16429989 | D34: 140 | E34: 4500760680 | F34: DISJUNTOR TM 3P 400VCA 20A | G34: 46073 | H34: Escrituração Realizada | I34: 10
A35: Edney Jean | B35: (vazio) | C35: 16429989 | D35: 150 | E35: 4500760494 | F35: DISJUNTOR MINI 3P 400VCA 25A | G35: 46073 | H35: Escrituração Realizada | I35: 10
A36: Edney Jean | B36: (vazio) | C36: 16429989 | D36: 40 | E36: 4500760680 | F36: DISJUNTOR MINI 3P 400VCA 70A | G36: 46073 | H36: Escrituração Realizada | I36: 15
A37: Edney Jean | B37: (vazio) | C37: 16429989 | D37: 90 | E37: 4500760680 | F37: FUSIVEL NH LAMINA 500V 80A | G37: 46073 | H37: Escrituração Realizada | I37: 10
... A44: Edney Jean | B44: (vazio) | C44: 16438836 | D44: 120 | E44: 4500814598 | F44: FUSIVEL ULTRA-RAPIDO SITOR 40A 690V | G44: 46122 | H44: Aguardando emissão NF | I44: 21
A45: Edney Jean | B45: (vazio) | C45: 16438836 | D45: 130 | E45: 4500814598 | F45: FUSIVEL ULTRA-RAPIDO SITOR 63A 690V | G45: 46122 | H45: Aguardando emissão NF | I45: 21 | J45: SIm
A46: Edney Jean | B46: (vazio) | C46: 16438836 | D46: 20 | E46: 4500814666 | F46: FUSIVEL ULTRA-RAPIDO 100A 690V 00 | G46: 46122 | H46: Aguardando emissão NF | I46: 27 | J46: SIm
...

Sheet Export
A1: Nº Acomp. | B1: Requisicao | C1: Item RC | D1: Cód. ClassContabil | E1: Class. Contab. RC | F1: Tipo RC | G1: RC Criada Por | H1: Dt Criação RC | I1: Dt Remessa RC | J1: Status Requisição | K1: Dt Aprovação RC | L1: Regional | M1: Centro | N1: Unidade | O1: Material | P1: Descrição Material | Q1: Qtde RC | R1: DepositoRC | S1: Setor | T1: ParametroDefinitivo | U1: DataBaseProcessodefinitivo | V1: Material Corporativo | W1: Contrato ou Spot | X1: Urgente | Y1: Material/Serviço | Z1: Categoria/Família | AA1: Cen. Custo / PEP | AB1: InfraEstrutura | AC1: Ordem | AD1: ContaDoRazaoRC | AE1: Cotacao | AF1: Item Cotacao | AG1: Comprador Cotação | AH1: Qtde Cotacao | AI1: Dt Criação Cotação | AJ1: Contrato | AK1: Item Contrato | AL1: Comprador Contrato | AM1: Qtde Contrato | AN1: Dt Criação Contrato | AO1: Status Lib. Contrato | AP1: Dt Aprov. Contrato | AQ1: Cód Fornecedor | AR1: Fornecedor | AS1: Pedido Criado Por | AT1: Nome Criador Pedido | AU1: TipoPedido | AV1: Pedido | AW1: Item Pedido | AX1: CompraLocal | AY1: Comprador Pedido | AZ1: Dt Criação Pedido | BA1: Status Lib. Pedido | BB1: Dt Aprovação Pedido | BC1: Dt Remessa Pedido | BD1: Dt Estatistica Pedido | BE1: DataConfirmada | BF1: Qtd Pedido | BG1: Qtd Fornecida | BH1: Qtd a fornecer | BI1: Dt MIGO | BJ1: Qtd Escriturada | BK1: Qtd a Escriturar | BL1: Dt MIRO | BM1: Emissão NF | BN1: Dt Pagamento | BO1: Status Geral | BP1: TotalLinhas
B2: 16407867 | C2: 20 | D2: Q | E2: Produção ind.projeto | F2: ZMAT | G2: ACRUZ10 | H2: 45940 | I2: 45960 | J2: Aprovado | K2: 45947 | L2: R4 | M2: RJB4 | N2: SPE SANEAMENTO RIO 4 S.A | O2: 5018596 | P2: VALVULA RET HOR UNICA BZ BSP D2 PN16 | Q2: 10 | R2: DP98 | S2: Suprimentos | V2: Sim | W2: Spot | X2: Não Urgente | Y2: Material | Z2: TUBOS E CONEXÕES DE AÇO | AA2: U/46A.23153.A.RD.M.001 | AB2: Rede de Distribuição | AD2: 1141000003 | BO2: Requisição - Item Eliminado | BP2: 1
B3: 16407867 | C3: 30 | D3: Q | E3: Produção ind.projeto | F3: ZMAT | G3: ACRUZ10 | H3: 45940 | I3: 45960 | J3: Aprovado | K3: 45947 | L3: R4 | M3: RJB4 | N3: SPE SANEAMENTO RIO 4 S.A | O3: 5030545 | P3: VALVULA RET DUPLA FOFO WAF D65 16BAR | Q3: 2 | R3: DP98 | S3: Suprimentos | V3: Sim | W3: Spot | X3: Não Urgente | Y3: Material | Z3: FERRO FUNDIDO | AA3: U/46A.23153.A.RD.M.001 | AB3: Rede de Distribuição | AD3: 1141000003 | BO3: Requisição - Item Concluído | BP3: 1
B4: 16407867 | C4: 10 | D4: Q | E4: Produção ind.projeto | F4: ZMAT | G4: ACRUZ10 | H4: 45940 | I4: 45960 | J4: Aprovado | K4: 45947 | L4: R4 | M4: RJB4 | N4: SPE SANEAMENTO RIO 4 S.A | O4: 5025393 | P4: VALVULA RET DUPLA FOFO WAF D50 16BAR | Q4: 10 | R4: DP98 | S4: Suprimentos | V4: Sim | W4: Spot | X4: Não Urgente | Y4: Material | Z4: FERRO FUNDIDO | AA4: U/46A.23153.A.RD.M.001 | AB4: Rede de Distribuição | AD4: 1141000003 | BO4: Requisição - Item Eliminado | BP4: 1
B5: 16407867 | C5: 50 | D5: Q | E5: Produção ind.projeto | F5: ZMAT | G5: ACRUZ10 | H5: 45940 | I5: 45992 | J5: Aprovado | K5: 45947 | L5: R4 | M5: RJB4 | N5: SPE SANEAMENTO RIO 4 S.A | O5: 5013457 | P5: VALVULA RET DUPLA FOFO WAF D200 150 | Q5: 4 | R5: DP98 | S5: Suprimentos | T5: 85 | U5: 45645 | V5: Sim | W5: Contrato | X5: Não Urgente | Y5: Material | Z5: FERRO FUNDIDO | AA5: U/46A.23153.A.RD.M.001 | AB5: Rede de Distribuição | AD5: 1141000003 | AJ5: 4600084015 | AK5: 600 | AL5: Hermes Morais | AM5: 0 | AN5: 45645 | AO5: Liberado | AQ5: 102514 | AR5: AVK - VALVULAS DO BRASIL LTDA | AS5: JCRUZ3 | AT5: Junio Alvares da Cruz | AU5: PGLO | AV5: 4500640315 | AW5: 10 | AX5: Não | AY5: Edney Jean | AZ5: 45954 | BA5: Liberado | BB5: 45957.358 | BF5: 4 | BG5: 4 | BH5: 0 | BI5: 46007 | BJ5: 4 | BK5: 0 | BL5: 46007 | BO5: Escrituração Realizada | BP5: 1
B6: 16407867 | C6: 40 | D6: Q | E6: Produção ind.projeto | F6: ZMAT | G6: ACRUZ10 | H6: 45940 | I6: 45960 | J6: Aprovado | K6: 45947 | L6: R4 | M6: RJB4 | N6: SPE SANEAMENTO RIO 4 S.A | O6: 5025345 | P6: VALVULA RET DUPLA FOFO WAF D100 16BAR | Q6: 6 | R6: DP98 | S6: Suprimentos | V6: Sim | W6: Spot | X6: Não Urgente | Y6: Material | Z6: FERRO FUNDIDO | AA6: U/46A.23153.A.RD.M.001 | AB6: Rede de Distribuição | AD6: 1141000003 | BO6: Requisição - Item Eliminado | BP6: 1
B7: 16444659 | C7: 10 | D7: Q | E7: Produção ind.projeto | F7: ZMAT | G7: ACRUZ10 | H7: 46150 | I7: 46150 | J7: Aprovado | K7: 46164 | L7: R4 | M7: RJB4 | N7: SPE SANEAMENTO RIO 4 S.A | O7: 5515632 | P7: TORQUIMETRO ESTALO 3/8POL 10-60NM | Q7: 2 | R7: DP98 | S7: Unidade | T7: 156 | U7: 46170 | V7: Não | W7: Spot | X7: Não Urgente | Y7: Material | Z7: CONSTRUÇÃO CIVIL | AA7: U/46A.23153.A.RD.M.001 | AB7: Rede de Distribuição | AD7: 1141000001 | AE7: 6000152290 | AF7: 110 | AG7: André Queiroz | AH7: 2 | AI7: 46170 | AK7: 0 | AQ7: 143551 | AR7: ABRASUL ABRASIVO EPI SOLDAS LTDA | AS7: ARIBACIG | AT7: Conexão ARIBACIG x S4P | AU7: PMNB | AV7: 4500856471 | AW7: 10 | AX7: Não | AY7: André Queiroz | AZ7: 46187 | BA7: Liberado | BB7: 46188.342 | BE7: 46204 | BF7: 2 | BH7: 2 | BK7: 2 | BO7: Aguardando emissão NF | BP7: 1
B8: 16444659 | C8: 20 | D8: Q | E8: Produção ind.projeto | F8: ZMAT | G8: ACRUZ10 | H8: 46150 | I8: 46150 | J8: Aprovado | K8: 46164 | L8: R4 | M8: RJB4 | N8: SPE SANEAMENTO RIO 4 S.A | O8: 5515633 | P8: TORQUIMETRO ESTALO 1/2POL 10-60NM | Q8: 2 | R8: DP98 | S8: Unidade | T8: 156 | U8: 46170 | V8: Não | W8: Spot | X8: Não Urgente | Y8: Material | Z8: CONSTRUÇÃO CIVIL | AA8: U/46A.23153.A.RD.M.001 | AB8: Rede de Distribuição | AD8: 1141000001 | AE8: 6000152290 | AF8: 120 | AG8: André Queiroz | AH8: 2 | AI8: 46170 | AK8: 0 | AQ8: 143551 | AR8: ABRASUL ABRASIVO EPI SOLDAS LTDA | AS8: ARIBACIG | AT8: Conexão ARIBACIG x S4P | AU8: PMNB | AV8: 4500856471 | AW8: 20 | AX8: Não | AY8: André Queiroz | AZ8: 46187 | BA8: Liberado | BB8: 46188.342 | BE8: 46204 | BF8: 2 | BH8: 2 | BK8: 2 | BO8: Aguardando emissão NF | BP8: 1
B9: 16425056 | C9: 60 | D9: Q | E9: Produção ind.projeto | F9: ZMAT | G9: ACRUZ10 | H9: 46045 | I9: 46076 | J9: Aprovado | K9: 46045 | L9: R4 | M9: RJB4 | N9: SPE SANEAMENTO RIO 4 S.A | O9: 5010127 | P9: TOMADA ELETRICA 220V 32A 3P+T | Q9: 5 | R9: DP98 | S9: Suprimentos | T9: 263 | U9: 45820 | V9: Sim | W9: Contrato | X9: Não Urgente | Y9: Material | Z9: MATERIAIS ELÉTRICOS | AA9: U/46A.23153.A.RD.M.001 | AB9: Rede de Distribuição | AD9: 1141000003 | AJ9: 4600092936 | AK9: 120 | AL9: Natasha Amancio | AM9: 0 | AN9: 45820 | AO9: Liberado | AQ9: 133854 | AR9: FECVA S.A. SOLUCOES INDUSTRIAIS | AS9: T3NAMANCIO | AT9: NATASHA DE OLIVEIRA AMANCIO DE OLIVEIRA AMANCIO | AU9: PGLO | AV9: 4500726918 | AW9: 10 | AX9: Não | AY9: Natasha Amancio | AZ9: 46056 | BA9: Liberado | BB9: 46065.709 | BE9: 46101 | BF9: 5 | BG9: 5 | BH9: 0 | BI9: 46108 | BJ9: 5 | BK9: 0 | BL9: 46108 | BO9: Escrituração Realizada | BP9: 1
B10: 16432776 | C10: 10 | D10: Q | E10: Produção ind.projeto | F10: ZMAT | G10: PMORAIS | H10: 46090 | I10: 46128 | J10: Aprovado | K10: 46104 | L10: R4 | M10: RJB4 | N10: SPE SANEAMENTO RIO 4 S.A | O10: 3008639 | P10: SILICONE ACETICO ALTA TEMP VM 280G | Q10: 4 | R10: DP98 | S10: Unidade | T10: 349 | U10: 46121 | V10: Sim | W10: Spot | X10: Não Urgente | Y10: Material | Z10: FERRAMENTAS | AA10: U/46A.23153.A.RD.M.001 | AB10: Rede de Distribuição | AD10: 1141000001 | AE10: 6000148656 | AF10: 50 | AG10: Diego Rocha | AH10: 4 | AI10: 46121 | BO10: Cotação - em Negociação | BP10: 1
B11: 16426739 | C11: 260 | D11: Q | E11: Produção ind.projeto | F11: ZMAT | G11: ACRUZ10 | H11: 46056 | I11: 46076 | J11: Aprovado | K11: 46065 | L11: R4 | M11: RJB4 | N11: SPE SANEAMENTO RIO 4 S.A | O11: 4007453 | P11: SELO MECANICO TS-P 3/4POL | Q11: 5 | R11: DP98 | S11: Suprimentos | T11: 194 | U11: 46066 | V11: Sim | W11: Spot | X11: Não Urgente | Y11: Material | Z11: MATERIAIS MECÂNICOS | AA11: U/46A.23153.A.RD.M.001 | AB11: Rede de Distribuição | AD11: 1141000003 | AE11: 6000144266 | AF11: 40 | AG11: Joaz Souza | AH11: 5 | AI11: 46066 | AK11: 0 | AQ11: 116824 | AR11: PLANAC MAQUINAS E FERRAMENTAS LTDA | AS11: ARIBACIG | AT11: Conexão ARIBACIG x S4P | AU11: PMNB | AV11: 4500804285 | AW11: 40 | AX11: Sim | AY11: Joaz Souza | AZ11: 46139 | BA11: Liberado | BB11: 46140.407 | BD11: 46156 | BE11: 46162 | BF11: 5 | BG11: 5 | BH11: 0 | BI11: 46154 | BJ11: 5 | BK11: 0 | BL11: 46154 | BO11: Escrituração Realizada | BP11: 1
B12: 16401860 | C12: 20 | D12: Q | E12: Produção ind.projeto | F12: ZMAT | G12: ACRUZ10 | H12: 45904 | I12: 45915 | J12: Aprovado | K12: 45904 | L12: R4 | M12: RJB4 | N12: SPE SANEAMENTO RIO 4 S.A | O12: 4007458 | P12: SELO MECANICO TS-P 1.3/4POL | Q12: 10 | R12: DP98 | S12: Suprimentos | T12: 351 | U12: 45904 | V12: Sim | W12: Spot | X12: Não Urgente | Y12: Material | Z12: MATERIAIS MECÂNICOS | AA12: U/46A.23153.A.RD.M.001 | AB12: Rede de Distribuição | AD12: 1141000003 | AE12: 6000131298 | AF12: 20 | AG12: Marcilene Carvalho | AH12: 10 | AI12: 45904 | AK12: 0 | AQ12: 116824 | AR12: PLANAC MAQUINAS E FERRAMENTAS LTDA | AS12: ARIBACIG | AT12: Conexão ARIBACIG x S4P | AU12: PMNB | AV12: 4500600032 | AW12: 20 | AX12: Sim | AY12: Marcilene Carvalho | AZ12: 45910 | BA12: Liberado | BB12: 45911.348 | BD12: 45929 | BE12: 45945 | BF12: 10 | BG12: 10 | BH12: 0 | BI12: 45923 | BJ12: 10 | BK12: 0 | BL12: 45923 | BO12: Escrituração Realizada | BP12: 1
B13: 16426739 | C13: 240 | D13: Q | E13: Produção ind.projeto | F13: ZMAT | G13: ACRUZ10 | H13: 46056 | I13: 46076 | J13: Aprovado | K13: 46065 | L13: R4 | M13: RJB4 | N13: SPE SANEAMENTO RIO 4 S.A | O13: 4007458 | P13: SELO MECANICO TS-P 1.3/4POL | Q13: 10 | R13: DP98 | S13: Suprimentos | T13: 194 | U13: 46066 | V13: Sim | W13: Spot | X13: Não Urgente | Y13: Material | Z13: MATERIAIS MECÂNICOS | AA13: U/46A.23153.A.RD.M.001 | AB13: Rede de Distribuição | AD13: 1141000003 | AE13: 6000144266 | AF13: 20 | AG13: Joaz Souza | AH13: 10 | AI13: 46066 | AK13: 0 | AQ13: 116824 | AR13: PLANAC MAQUINAS E FERRAMENTAS LTDA | AS13: ARIBACIG | AT13: Conexão ARIBACIG x S4P | AU13: PMNB | AV13: 4500804285 | AW13: 20 | AX13: Sim | AY13: Joaz Souza | AZ13: 46139 | BA13: Liberado | BB13: 46140.407 | BD13: 46156 | BE13: 46162 | BF13: 10 | BG13: 10 | BH13: 0 | BI13: 46154 | BJ13: 10 | BK13: 0 | BL13: 46154 | BO13: Escrituração Realizada | BP13: 1
B14: 16429989 | C14: 170 | D14: Q | E14: Produção ind.projeto | F14: ZMAT | G14: ACRUZ10 | H14: 46073 | I14: 46083 | J14: Aprovado | K14: 46091 | L14: R4 | M14: RJB4 | N14: SPE SANEAMENTO RIO 4 S.A | O14: 4007458 | P14: SELO MECANICO TS-P 1.3/4POL | Q14: 20 | R14: DP98 | S14: Suprimentos | T14: 194 | U14: 46102 | V14: Sim | W14: Spot | X14: Não Urgente | Y14: Material | Z14: MATERIAIS MECÂNICOS | AA14: U/46A.23153.A.RD.M.001 | AB14: Rede de Distribuição | AD14: 1141000003 | AE14: 6000147117 | AF14: 20 | AG14: Joaz Souza | AH14: 20 | AI14: 46102 | AK14: 0 | AQ14: 120996 | AR14: ABECOM ROLAMENTOS E PRODUTOS DE BOR | AS14: ARIBACIG | AT14: Conexão ARIBACIG x S4P | AU14: PMNB | AV14: 4500805703 | AW14: 20 | AX14: Não | AY14: Joaz Souza | AZ14: 46141 | BA14: Liberado | BB14: 46142.633 | BD14: 46178 | BE14: 46178 | BF14: 20 | BG14: 20 | BH14: 0 | BI14: 46153 | BJ14: 20 | BK14: 0 | BL14: 46154 | BO14: Escrituração Realizada | BP14: 1
B15: 16401860 | C15: 10 | D15: Q | E15: Produção ind.projeto | F15: ZMAT | G15: ACRUZ10 | H15: 45904 | I15: 45915 | J15: Aprovado | K15: 45904 | L15: R4 | M15: RJB4 | N15: SPE SANEAMENTO RIO 4 S.A | O15: 4007455 | P15: SELO MECANICO TS-P 1.1/4POL | Q15: 10 | R15: DP98 | S15: Suprimentos | T15: 351 | U15: 45904 | V15: Sim | W15: Spot | X15: Não Urgente | Y15: Material | Z15: MATERIAIS MECÂNICOS | AA15: U/46A.23153.A.RD.M.001 | AB15: Rede de Distribuição | AD15: 1141000003 | AE15: 6000131298 | AF15: 10 | AG15: Marcilene Carvalho | AH15: 10 | AI15: 45904 | AK15: 0 | AQ15: 116824 | AR15: PLANAC MAQUINAS E FERRAMENTAS LTDA | AS15: ARIBACIG | AT15: Conexão ARIBACIG x S4P | AU15: PMNB | AV15: 4500600032 | AW15: 10 | AX15: Sim | AY15: Marcilene Carvalho | AZ15: 45910 | BA15: Liberado | BB15: 45911.348 | BD15: 45929 | BE15: 45945 | BF15: 10 | BG15: 10 | BH15: 0 | BI15: 45923 | BJ15: 10 | BK15: 0 | BL15: 45923 | BO15: Escrituração Realizada | BP15: 1
B16: 16426739 | C16: 230 | D16: Q | E16: Produção ind.projeto | F16: ZMAT | G16: ACRUZ10 | H16: 46056 | I16: 46076 | J16: Aprovado | K16: 46065 | L16: R4 | M16: RJB4 | N16: SPE SANEAMENTO RIO 4 S.A | O16: 4007455 | P16: SELO MECANICO TS-P 1.1/4POL | Q16: 10 | R16: DP98 | S16: Suprimentos | T16: 194 | U16: 46066 | V16: Sim | W16: Spot | X16: Não Urgente | Y16: Material | Z16: MATERIAIS MECÂNICOS | AA16: U/46A.23153.A.RD.M.001 | AB16: Rede de Distribuição | AD16: 1141000003 | AE16: 6000144266 | AF16: 10 | AG16: Joaz Souza | AH16: 10 | AI16: 46066 | AK16: 0 | AQ16: 116824 | AR16: PLANAC MAQUINAS E FERRAMENTAS LTDA | AS16: ARIBACIG | AT16: Conexão ARIBACIG x S4P | AU16: PMNB | AV16: 4500804285 | AW16: 10 | AX16: Sim | AY16: Joaz Souza | AZ16: 46139 | BA16: Liberado | BB16: 46140.407 | BD16: 46156 | BE16: 46162 | BF16: 10 | BG16: 10 | BH16: 0 | BI16: 46154 | BJ16: 10 | BK16: 0 | BL16: 46154 | BO16: Escrituração Realizada | BP16: 1
B17: 16429989 | C17: 160 | D17: Q | E17: Produção ind.projeto | F17: ZMAT | G17: ACRUZ10 | H17: 46073 | I17: 46083 | J17: Aprovado | K17: 46091 | L17: R4 | M17: RJB4 | N17: SPE SANEAMENTO RIO 4 S.A | O17: 4007455 | P17: SELO MECANICO TS-P 1.1/4POL | Q17: 20 | R17: DP98 | S17: Suprimentos | T17: 194 | U17: 46102 | V17: Sim | W17: Spot | X17: Não Urgente | Y17: Material | Z17: MATERIAIS MECÂNICOS | AA17: U/46A.23153.A.RD.M.001 | AB17: Rede de Distribuição | AD17: 1141000003 | AE17: 6000147117 | AF17: 10 | AG17: Joaz Souza | AH17: 20 | AI17: 46102 | AK17: 0 | AQ17: 120996 | AR17: ABECOM ROLAMENTOS E PRODUTOS DE BOR | AS17: ARIBACIG | AT17: Conexão ARIBACIG x S4P | AU17: PMNB | AV17: 4500805703 | AW17: 10 | AX17: Não | AY17: Joaz Souza | AZ17: 46141 | BA17: Liberado | BB17: 46142.633 | BD17: 46178 | BE17: 46178 | BF17: 20 | BG17: 20 | BH17: 0 | BI17: 46153 | BJ17: 20 | BK17: 0 | BL17: 46154 | BO17: Escrituração Realizada | BP17: 1
B18: 16426739 | C18: 250 | D18: Q | E18: Produção ind.projeto | F18: ZMAT | G18: ACRUZ10 | H18: 46056 | I18: 46076 | J18: Aprovado | K18: 46065 | L18: R4 | M18: RJB4 | N18: SPE SANEAMENTO RIO 4 S.A | O18: 4005833 | P18: SELO MECANICO 21 D1.3/8 | Q18: 7 | R18: DP98 | S18: Suprimentos | T18: 194 | U18: 46066 | V18: Sim | W18: Spot | X18: Não Urgente | Y18: Material | Z18: MATERIAIS MECÂNICOS | AA18: U/46A.23153.A.RD.M.001 | AB18: Rede de Distribuição | AD18: 1141000003 | AE18: 6000144266 | AF18: 30 | AG18: Joaz Souza | AH18: 7 | AI18: 46066 | AK18: 0 | AQ18: 116824 | AR18: PLANAC MAQUINAS E FERRAMENTAS LTDA | AS18: ARIBACIG | AT18: Conexão ARIBACIG x S4P | AU18: PMNB | AV18: 4500804285 | AW18: 30 | AX18: Sim | AY18: Joaz Souza | AZ18: 46139 | BA18: Liberado | BB18: 46140.407 | BD18: 46156 | BE18: 46162 | BF18: 7 | BG18: 7 | BH18: 0 | BI18: 46154 | BJ18: 7 | BK18: 0 | BL18: 46154 | BO18: Escrituração Realizada | BP18: 1
B19: 16429989 | C19: 180 | D19: Q | E19: Produção ind.projeto | F19: ZMAT | G19: ACRUZ10 | H19: 46073 | I19: 46073 | J19: Aprovado | K19: 46091 | L19: R4 | M19: RJB4 | N19: SPE SANEAMENTO RIO 4 S.A | O19: 4005833 | P19: SELO MECANICO 21 D1.3/8 | Q19: 7 | R19: DP98 | S19: Suprimentos | T19: 194 | U19: 46102 | V19: Sim | W19: Spot | X19: Não Urgente | Y19: Material | Z19: MATERIAIS MECÂNICOS | AA19: U/46A.23153.A.RD.M.001 | AB19: Rede de Distribuição | AD19: 1141000003 | AE19: 6000147117 | AF19: 30 | AG19: Joaz Souza | AH19: 7 | AI19: 46102 | AK19: 0 | AQ19: 120996 | AR19: ABECOM ROLAMENTOS E PRODUTOS DE BOR | AS19: ARIBACIG | AT19: Conexão ARIBACIG x S4P | AU19: PMNB | AV19: 4500805703 | AW19: 30 | AX19: Não | AY19: Joaz Souza | AZ19: 46141 | BA19: Liberado | BB19: 46142.633 | BD19: 46178 | BE19: 46178 | BF19: 7 | BG19: 7 | BH19: 0 | BI19: 46153 | BJ19: 7 | BK19: 0 | BL19: 46154 | BO19: Escrituração Realizada | BP19: 1
B20: 16442320 | C20: 30 | D20: Q | E20: Produção ind.projeto | F20: ZMAT | G20: ACRUZ10 | H20: 46141 | I20: 46150 | J20: Aprovado | K20: 46150 | L20: R4 | M20: RJB4 | N20: SPE SANEAMENTO RIO 4 S.A | O20: 5507548 | P20: SACA GAXETA FLEX INTERC 11,1MM 280MM | Q20: 10 | R20: DP98 | S20: Suprimentos | T20: 349 | U20: 46161 | V20: Sim | W20: Spot | X20: Não Urgente | Y20: Material | Z20: FERRAMENTAS | AA20: U/46A.23153.A.RD.M.001 | AB20: Rede de Distribuição | AD20: 1141000003 | AE20: 6000151574 | AF20: 130 | AG20: Diego Rocha | AH20: 10 | AI20: 46161 | BO20: Cotação - em Negociação | BP20: 1
B21: 16405989 | C21: 10 | D21: Q | E21: Produção ind.projeto | F21: ZMAT | G21: ACRUZ10 | H21: 45930 | I21: 45940 | J21: Aprovado | K21: 45932 | L21: R4 | M21: RJB4 | N21: SPE SANEAMENTO RIO 4 S.A | O21: 5512377 | P21: ROTULADOR ELETRON AUTOM 230DPI 7,5MM/S | Q21: 1 | R21: DP98 | S21: Unidade | T21: 77 | U21: 45936 | V21: Não | W21: Spot | X21: Não Urgente | Y21: Material | Z21: MATERIAIS DE TI | AA21: U/46A.23153.A.RD.M.001 | AB21: Rede de Distribuição | AD21: 1141000001 | AE21: 6000133819 | AF21: 30 | AG21: Gislene Rodrigues | AH21: 1 | AI21: 45936 | AK21: 0 | AQ21: 142020 | AR21: ED PEL COMERCIO E SERVICO LTDA | AS21: ARIBACIG | AT21: Conexão ARIBACIG x S4P | AU21: PMNB | AV21: 4500633639 | AW21: 10 | AX21: Sim | AY21: Gislene Rodrigues | AZ21: 45946 | BA21: Liberado | BB21: 45967.561 | BD21: 45978 | BE21: 45978 | BF21: 1 | BG21: 1 | BH21: 0 | BI21: 45993 | BJ21: 1 | BK21: 0 | BL21: 45993 | BO21: Escrituração Realizada | BP21: 1
B22: 16432794 | C22: 40 | D22: Q | E22: Produção ind.projeto | F22: ZMAT | G22: PMORAIS | H22: 46090 | I22: 46128 | J22: Aprovado | K22: 46104 | L22: R4 | M22: RJB4 | N22: SPE SANEAMENTO RIO 4 S.A | O22: 4006590 | P22: ROLAMENTO RIG ESF RAD 6411 C3 | Q22: 6 | R22: DP98 | S22: Suprimentos | T22: 194 | U22: 46150 | V22: Sim | W22: Spot | X22: Não Urgente | Y22: Material | Z22: MATERIAIS MECÂNICOS | AA22: U/46A.23153.A.RD.M.001 | AB22: Rede de Distribuição | AD22: 1141000003 | AE22: 6000150731 | AF22: 20 | AG22: Joaz Souza | AH22: 6 | AI22: 46150 | AK22: 0 | AQ22: 116824 | AR22: PLANAC MAQUINAS E FERRAMENTAS LTDA | AS22: ARIBACIG | AT22: Conexão ARIBACIG x S4P | AU22: PMNB | AV22: 4500836232 | AW22: 10 | AX22: Sim | AY22: Joaz Souza | AZ22: 46167 | BA22: Liberado | BB22: 46167.709 | BD22: 46183 | BE22: 46203 | BF22: 6 | BH22: 6 | BK22: 6 | BO22: Aguardando emissão NF | BP22: 1
B23: 16426739 | C23: 110 | D23: Q | E23: Produção ind.projeto | F23: ZMAT | G23: ACRUZ10 | H23: 46056 | I23: 46076 | J23: Aprovado | K23: 46065 | L23: R4 | M23: RJB4 | N23: SPE SANEAMENTO RIO 4 S.A | O23: 4006576 | P23: ROLAMENTO ESF RIG 6314 Z C3 | Q23: 4 | R23: DP98 | S23: Suprimentos | T23: 194 | U23: 46066 | V23: Sim | W23: Spot | X23: Não Urgente | Y23: Material | Z23: MATERIAIS MECÂNICOS | AA23: U/46A.23153.A.RD.M.001 | AB23: Rede de Distribuição | AD23: 1141000001 | AE23: 6000144265 | AF23: 100 | AG23: Joaz Souza | AH23: 4 | AI23: 46066 | AK23: 0 | AQ23: 145468 | AR23: PORTORROL DISTRIBUIDORA LTDA | AS23: ARIBACIG | AT23: Conexão ARIBACIG x S4P | AU23: PMNB | AV23: 4500778966 | AW23: 100 | AX23: Não | AY23: Joaz Souza | AZ23: 46111 | BA23: Liberado | BB23: 46127.456 | BD23: 46134 | BE23: 46139 | BF23: 4 | BG23: 4 | BH23: 0 | BI23: 46150 | BJ23: 4 | BK23: 0 | BL23: 46168 | BO23: Escrituração Realizada | BP23: 1
B24: 16432794 | C24: 50 | D24: Q | E24: Produção ind.projeto | F24: ZMAT | G24: PMORAIS | H24: 46090 | I24: 46128 | J24: Aprovado | K24: 46104 | L24: R4 | M24: RJB4 | N24: SPE SANEAMENTO RIO 4 S.A | O24: 4003701 | P24: ROLAMENTO ESF RIG 6312-ZZ SKF | Q24: 6 | R24: DP98 | S24: Suprimentos | T24: 194 | U24: 46150 | V24: Sim | W24: Spot | X24: Não Urgente | Y24: Material | Z24: MATERIAIS MECÂNICOS | AA24: U/46A.23153.A.RD.M.001 | AB24: Rede de Distribuição | AD24: 1141000001 | AE24: 6000150731 | AF24: 30 | AG24: Joaz Souza | AH24: 6 | AI24: 46150 | AK24: 0 | AQ24: 116824 | AR24: PLANAC MAQUINAS E FERRAMENTAS LTDA | AS24: ARIBACIG | AT24: Conexão ARIBACIG x S4P | AU24: PMNB | AV24: 4500836232 | AW24: 20 | AX24: Sim | AY24: Joaz Souza | AZ24: 46167 | BA24: Liberado | BB24: 46167.709 | BD24: 46183 | BE24: 46203 | BF24: 6 | BH24: 6 | BK24: 6 | BO24: Aguardando emissão NF | BP24: 1
B25: 16426739 | C25: 100 | D25: Q | E25: Produção ind.projeto | F25: ZMAT | G25: ACRUZ10 | H25: 46056 | I25: 46076 | J25: Aprovado | K25: 46065 | L25: R4 | M25: RJB4 | N25: SPE SANEAMENTO RIO 4 S.A | O25: 4003640 | P25: ROLAMENTO ESF RIG 6311ZZC3 FAG | Q25: 4 | R25: DP98 | S25: Suprimentos | T25: 194 | U25: 46066 | V25: Sim | W25: Spot | X25: Não Urgente | Y25: Material | Z25: MATERIAIS MECÂNICOS | AA25: U/46A.23153.A.RD.M.001 | AB25: Rede de Distribuição | AD25: 1141000001 | AE25: 6000144265 | AF25: 90 | AG25: Joaz Souza | AH25: 4 | AI25: 46066 | AK25: 0 | AQ25: 145468 | AR25: PORTORROL DISTRIBUIDORA LTDA | AS25: ARIBACIG | AT25: Conexão ARIBACIG x S4P | AU25: PMNB | AV25: 4500778966 | AW25: 90 | AX25: Não | AY25: Joaz Souza | AZ25: 46111 | BA25: Liberado | BB25: 46127.456 | BD25: 46134 | BE25: 46139 | BF25: 4 | BG25: 4 | BH25: 0 | BI25: 46150 | BJ25: 4 | BK25: 0 | BL25: 46168 | BO25: Escrituração Realizada | BP25: 1
