Workbook
Name Área_de_Impressão: Agenda!$B$2:$I$23
Name CampoQuem: tblDados[QUEM]
Name MostrarNome: Agenda!$H$3
Name PesquisarQuem: OFFSET('Pesquisa de nome'!$A$3,,,COUNT('Pesquisa de nome'!$B:$B),1)
Name SemanaDe: Agenda!$G$3

Sheet PAPEIS & RESPONSABILIDADES
A1: PAPEIS E RESPONSABILIDADES - ANALISTA DE OPERAÇÕES EMEC
A2: PROCESSOS
A3: PLANEJAMENTO | B3: PROGRAMAÇÃO | C3: CUSTO E MEDIÇÃO | D3: GESTÃO DE RECURSOS | E3: ANÁLISE DE PERFORMANCE
D4: SOLICITAÇÃO DE COMPRAS | E4: KPI's EMEC
D5: RESERVAS CL | E5: GESTÃO DOS DADOS
D6: RESSUPRIMENTO
D7: CRONOGRAMA MUNCK
A11: PADRONIZAÇÃO DE ANÁLISE DE FALHA E RECORRÊNCIA OS | B11: GESTÃO DE DOCUMENTOS | C11: INOVAÇÃO E MELHORIAS | D11: APRESENTAÇÃO DE RESULTADOS | E11: CAPACITAÇÃO
C12: POWER BI | D12: MATERIAL | E12: CAMPO EMEC
C13: DASHBOARD | D13: RELATÓRIO | E13: PLANEJAMENTO
C14: OTIMIZAR A GESTÃO DA ROTINA DE EMEC | D14: EPC

Sheet Agenda
B2: PROGRAMAÇÃO DIÁRIA | G2: Para a semana de | H2: Mostrar agenda de:
F3: =WEEKDAY(SemanaDe,1) -> 3 | G3: 41093 | H3: Manuel
C4: =$F$3=COLUMN(A$1) -> FALSE | D4: =$F$3=COLUMN(B$1) -> FALSE | E4: =$F$3=COLUMN(C$1) -> TRUE | F4: =$F$3=COLUMN(D$1) -> FALSE | G4: =$F$3=COLUMN(E$1) -> FALSE | H4: =$F$3=COLUMN(F$1) -> FALSE | I4: =$F$3=COLUMN(G$1) -> FALSE
C5: =COLUMN(A$1)-MATCH(TRUE,$C$4:$I$4,0)+SemanaDe+1 -> 41092 | D5: =COLUMN(B$1)-MATCH(TRUE,$C$4:$I$4,0)+SemanaDe+1 -> 41093 | E5: =COLUMN(C$1)-MATCH(TRUE,$C$4:$I$4,0)+SemanaDe+1 -> 41094 | F5: =COLUMN(D$1)-MATCH(TRUE,$C$4:$I$4,0)+SemanaDe+1 -> 41095 | G5: =COLUMN(E$1)-MATCH(TRUE,$C$4:$I$4,0)+SemanaDe+1 -> 41096 | H5: =COLUMN(F$1)-MATCH(TRUE,$C$4:$I$4,0)+SemanaDe+1 -> 41097 | I5: =COLUMN(G$1)-MATCH(TRUE,$C$4:$I$4,0)+SemanaDe+1 -> 41098
B6: HORA | C6: SEGUNDA-FEIRA | D6: TERÇA-FEIRA | E6: QUARTA-FEIRA | F6: QUINTA-FEIRA | G6: SEXTA-FEIRA | H6: SÁBADO | I6: DOMINGO
B7: 0.25 | C7: {=IFERROR(INDEX(tblDados[],MATCH(C$5+$B7&MostrarNome,tblDados[DATA E HORA]&tblDados[QUEM],0),3),"")} | D7: {=IFERROR(INDEX(tblDados[],MATCH(D$5+$B7&MostrarNome,tblDados[DATA E HORA]&tblDados[QUEM],0),3),"")} | E7: {=IFERROR(INDEX(tblDados[],MATCH(E$5+$B7&MostrarNome,tblDados[DATA E HORA]&tblDados[QUEM],0),3),"")} | F7: {=IFERROR(INDEX(tblDados[],MATCH(F$5+$B7&MostrarNome,tblDados[DATA E HORA]&tblDados[QUEM],0),3),"")} | G7: {=IFERROR(INDEX(tblDados[],MATCH(G$5+$B7&MostrarNome,tblDados[DATA E HORA]&tblDados[QUEM],0),3),"")} | H7: {=IFERROR(INDEX(tblDados[],MATCH(H$5+$B7&MostrarNome,tblDados[DATA E HORA]&tblDados[QUEM],0),3),"")} | I7: {=IFERROR(INDEX(tblDados[],MATCH(I$5+$B7&MostrarNome,tblDados[DATA E HORA]&tblDados[QUEM],0),3),"")}
B8: 0.29166667 | C8: {=IFERROR(INDEX(tblDados[],MATCH(C$5+$B8&MostrarNome,tblDados[DATA E HORA]&tblDados[QUEM],0),3),"")} | D8: {=IFERROR(INDEX(tblDados[],MATCH(D$5+$B8&MostrarNome,tblDados[DATA E HORA]&tblDados[QUEM],0),3),"")} | E8: {=IFERROR(INDEX(tblDados[],MATCH(E$5+$B8&MostrarNome,tblDados[DATA E HORA]&tblDados[QUEM],0),3),"")} | F8: {=IFERROR(INDEX(tblDados[],MATCH(F$5+$B8&MostrarNome,tblDados[DATA E HORA]&tblDados[QUEM],0),3),"")} | G8: {=IFERROR(INDEX(tblDados[],MATCH(G$5+$B8&MostrarNome,tblDados[DATA E HORA]&tblDados[QUEM],0),3),"")} | H8: {=IFERROR(INDEX(tblDados[],MATCH(H$5+$B8&MostrarNome,tblDados[DATA E HORA]&tblDados[QUEM],0),3),"")} | I8: {=IFERROR(INDEX(tblDados[],MATCH(I$5+$B8&MostrarNome,tblDados[DATA E HORA]&tblDados[QUEM],0),3),"")}
B9: 0.33333333 | C9: {=IFERROR(INDEX(tblDados[],MATCH(C$5+$B9&MostrarNome,tblDados[DATA E HORA]&tblDados[QUEM],0),3),"")} | D9: {=IFERROR(INDEX(tblDados[],MATCH(D$5+$B9&MostrarNome,tblDados[DATA E HORA]&tblDados[QUEM],0),3),"")} | E9: {=IFERROR(INDEX(tblDados[],MATCH(E$5+$B9&MostrarNome,tblDados[DATA E HORA]&tblDados[QUEM],0),3),"")} | F9: {=IFERROR(INDEX(tblDados[],MATCH(F$5+$B9&MostrarNome,tblDados[DATA E HORA]&tblDados[QUEM],0),3),"")} | G9: {=IFERROR(INDEX(tblDados[],MATCH(G$5+$B9&MostrarNome,tblDados[DATA E HORA]&tblDados[QUEM],0),3),"")} | H9: {=IFERROR(INDEX(tblDados[],MATCH(H$5+$B9&MostrarNome,tblDados[DATA E HORA]&tblDados[QUEM],0),3),"")} | I9: {=IFERROR(INDEX(tblDados[],MATCH(I$5+$B9&MostrarNome,tblDados[DATA E HORA]&tblDados[QUEM],0),3),"")}
B10: 0.375 | C10: {=IFERROR(INDEX(tblDados[],MATCH(C$5+$B10&MostrarNome,tblDados[DATA E HORA]&tblDados[QUEM],0),3),"")} | D10: {=IFERROR(INDEX(tblDados[],MATCH(D$5+$B10&MostrarNome,tblDados[DATA E HORA]&tblDados[QUEM],0),3),"")} | E10: {=IFERROR(INDEX(tblDados[],MATCH(E$5+$B10&MostrarNome,tblDados[DATA E HORA]&tblDados[QUEM],0),3),"")} | F10: {=IFERROR(INDEX(tblDados[],MATCH(F$5+$B10&MostrarNome,tblDados[DATA E HORA]&tblDados[QUEM],0),3),"")} | G10: {=IFERROR(INDEX(tblDados[],MATCH(G$5+$B10&MostrarNome,tblDados[DATA E HORA]&tblDados[QUEM],0),3),"")} | H10: {=IFERROR(INDEX(tblDados[],MATCH(H$5+$B10&MostrarNome,tblDados[DATA E HORA]&tblDados[QUEM],0),3),"")} | I10: {=IFERROR(INDEX(tblDados[],MATCH(I$5+$B10&MostrarNome,tblDados[DATA E HORA]&tblDados[QUEM],0),3),"")}
B11: 0.41666667 | C11: {=IFERROR(INDEX(tblDados[],MATCH(C$5+$B11&MostrarNome,tblDados[DATA E HORA]&tblDados[QUEM],0),3),"")} | D11: {=IFERROR(INDEX(tblDados[],MATCH(D$5+$B11&MostrarNome,tblDados[DATA E HORA]&tblDados[QUEM],0),3),"")} | E11: {=IFERROR(INDEX(tblDados[],MATCH(E$5+$B11&MostrarNome,tblDados[DATA E HORA]&tblDados[QUEM],0),3),"")} | F11: {=IFERROR(INDEX(tblDados[],MATCH(F$5+$B11&MostrarNome,tblDados[DATA E HORA]&tblDados[QUEM],0),3),"")} | G11: {=IFERROR(INDEX(tblDados[],MATCH(G$5+$B11&MostrarNome,tblDados[DATA E HORA]&tblDados[QUEM],0),3),"")} | H11: {=IFERROR(INDEX(tblDados[],MATCH(H$5+$B11&MostrarNome,tblDados[DATA E HORA]&tblDados[QUEM],0),3),"")} | I11: {=IFERROR(INDEX(tblDados[],MATCH(I$5+$B11&MostrarNome,tblDados[DATA E HORA]&tblDados[QUEM],0),3),"")}
B12: 0.45833333 | C12: {=IFERROR(INDEX(tblDados[],MATCH(C$5+$B12&MostrarNome,tblDados[DATA E HORA]&tblDados[QUEM],0),3),"")} | D12: {=IFERROR(INDEX(tblDados[],MATCH(D$5+$B12&MostrarNome,tblDados[DATA E HORA]&tblDados[QUEM],0),3),"")} | E12: {=IFERROR(INDEX(tblDados[],MATCH(E$5+$B12&MostrarNome,tblDados[DATA E HORA]&tblDados[QUEM],0),3),"")} | F12: {=IFERROR(INDEX(tblDados[],MATCH(F$5+$B12&MostrarNome,tblDados[DATA E HORA]&tblDados[QUEM],0),3),"")} | G12: {=IFERROR(INDEX(tblDados[],MATCH(G$5+$B12&MostrarNome,tblDados[DATA E HORA]&tblDados[QUEM],0),3),"")} | H12: {=IFERROR(INDEX(tblDados[],MATCH(H$5+$B12&MostrarNome,tblDados[DATA E HORA]&tblDados[QUEM],0),3),"")} | I12: {=IFERROR(INDEX(tblDados[],MATCH(I$5+$B12&MostrarNome,tblDados[DATA E HORA]&tblDados[QUEM],0),3),"")}
B13: 0.5 | C13: {=IFERROR(INDEX(tblDados[],MATCH(C$5+$B13&MostrarNome,tblDados[DATA E HORA]&tblDados[QUEM],0),3),"")} | D13: {=IFERROR(INDEX(tblDados[],MATCH(D$5+$B13&MostrarNome,tblDados[DATA E HORA]&tblDados[QUEM],0),3),"")} | E13: {=IFERROR(INDEX(tblDados[],MATCH(E$5+$B13&MostrarNome,tblDados[DATA E HORA]&tblDados[QUEM],0),3),"")} | F13: {=IFERROR(INDEX(tblDados[],MATCH(F$5+$B13&MostrarNome,tblDados[DATA E HORA]&tblDados[QUEM],0),3),"")} | G13: {=IFERROR(INDEX(tblDados[],MATCH(G$5+$B13&MostrarNome,tblDados[DATA E HORA]&tblDados[QUEM],0),3),"")} | H13: {=IFERROR(INDEX(tblDados[],MATCH(H$5+$B13&MostrarNome,tblDados[DATA E HORA]&tblDados[QUEM],0),3),"")} | I13: {=IFERROR(INDEX(tblDados[],MATCH(I$5+$B13&MostrarNome,tblDados[DATA E HORA]&tblDados[QUEM],0),3),"")}
B14: 0.54166667 | C14: {=IFERROR(INDEX(tblDados[],MATCH(C$5+$B14&MostrarNome,tblDados[DATA E HORA]&tblDados[QUEM],0),3),"")} | D14: {=IFERROR(INDEX(tblDados[],MATCH(D$5+$B14&MostrarNome,tblDados[DATA E HORA]&tblDados[QUEM],0),3),"")} | E14: {=IFERROR(INDEX(tblDados[],MATCH(E$5+$B14&MostrarNome,tblDados[DATA E HORA]&tblDados[QUEM],0),3),"")} | F14: {=IFERROR(INDEX(tblDados[],MATCH(F$5+$B14&MostrarNome,tblDados[DATA E HORA]&tblDados[QUEM],0),3),"")} | G14: {=IFERROR(INDEX(tblDados[],MATCH(G$5+$B14&MostrarNome,tblDados[DATA E HORA]&tblDados[QUEM],0),3),"")} | H14: {=IFERROR(INDEX(tblDados[],MATCH(H$5+$B14&MostrarNome,tblDados[DATA E HORA]&tblDados[QUEM],0),3),"")} | I14: {=IFERROR(INDEX(tblDados[],MATCH(I$5+$B14&MostrarNome,tblDados[DATA E HORA]&tblDados[QUEM],0),3),"")}
B15: 0.58333333 | C15: {=IFERROR(INDEX(tblDados[],MATCH(C$5+$B15&MostrarNome,tblDados[DATA E HORA]&tblDados[QUEM],0),3),"")} | D15: {=IFERROR(INDEX(tblDados[],MATCH(D$5+$B15&MostrarNome,tblDados[DATA E HORA]&tblDados[QUEM],0),3),"")} | E15: {=IFERROR(INDEX(tblDados[],MATCH(E$5+$B15&MostrarNome,tblDados[DATA E HORA]&tblDados[QUEM],0),3),"")} | F15: {=IFERROR(INDEX(tblDados[],MATCH(F$5+$B15&MostrarNome,tblDados[DATA E HORA]&tblDados[QUEM],0),3),"")} | G15: {=IFERROR(INDEX(tblDados[],MATCH(G$5+$B15&MostrarNome,tblDados[DATA E HORA]&tblDados[QUEM],0),3),"")} | H15: {=IFERROR(INDEX(tblDados[],MATCH(H$5+$B15&MostrarNome,tblDados[DATA E HORA]&tblDados[QUEM],0),3),"")} | I15: {=IFERROR(INDEX(tblDados[],MATCH(I$5+$B15&MostrarNome,tblDados[DATA E HORA]&tblDados[QUEM],0),3),"")}
B16: 0.625 | C16: {=IFERROR(INDEX(tblDados[],MATCH(C$5+$B16&MostrarNome,tblDados[DATA E HORA]&tblDados[QUEM],0),3),"")} | D16: {=IFERROR(INDEX(tblDados[],MATCH(D$5+$B16&MostrarNome,tblDados[DATA E HORA]&tblDados[QUEM],0),3),"")} | E16: {=IFERROR(INDEX(tblDados[],MATCH(E$5+$B16&MostrarNome,tblDados[DATA E HORA]&tblDados[QUEM],0),3),"")} | F16: {=IFERROR(INDEX(tblDados[],MATCH(F$5+$B16&MostrarNome,tblDados[DATA E HORA]&tblDados[QUEM],0),3),"")} | G16: {=IFERROR(INDEX(tblDados[],MATCH(G$5+$B16&MostrarNome,tblDados[DATA E HORA]&tblDados[QUEM],0),3),"")} | H16: {=IFERROR(INDEX(tblDados[],MATCH(H$5+$B16&MostrarNome,tblDados[DATA E HORA]&tblDados[QUEM],0),3),"")} | I16: {=IFERROR(INDEX(tblDados[],MATCH(I$5+$B16&MostrarNome,tblDados[DATA E HORA]&tblDados[QUEM],0),3),"")}
B17: 0.66666667 | C17: {=IFERROR(INDEX(tblDados[],MATCH(C$5+$B17&MostrarNome,tblDados[DATA E HORA]&tblDados[QUEM],0),3),"")} | D17: {=IFERROR(INDEX(tblDados[],MATCH(D$5+$B17&MostrarNome,tblDados[DATA E HORA]&tblDados[QUEM],0),3),"")} | E17: {=IFERROR(INDEX(tblDados[],MATCH(E$5+$B17&MostrarNome,tblDados[DATA E HORA]&tblDados[QUEM],0),3),"")} | F17: {=IFERROR(INDEX(tblDados[],MATCH(F$5+$B17&MostrarNome,tblDados[DATA E HORA]&tblDados[QUEM],0),3),"")} | G17: {=IFERROR(INDEX(tblDados[],MATCH(G$5+$B17&MostrarNome,tblDados[DATA E HORA]&tblDados[QUEM],0),3),"")} | H17: {=IFERROR(INDEX(tblDados[],MATCH(H$5+$B17&MostrarNome,tblDados[DATA E HORA]&tblDados[QUEM],0),3),"")} | I17: {=IFERROR(INDEX(tblDados[],MATCH(I$5+$B17&MostrarNome,tblDados[DATA E HORA]&tblDados[QUEM],0),3),"")}
B18: 0.70833333 | C18: {=IFERROR(INDEX(tblDados[],MATCH(C$5+$B18&MostrarNome,tblDados[DATA E HORA]&tblDados[QUEM],0),3),"")} | D18: {=IFERROR(INDEX(tblDados[],MATCH(D$5+$B18&MostrarNome,tblDados[DATA E HORA]&tblDados[QUEM],0),3),"")} | E18: {=IFERROR(INDEX(tblDados[],MATCH(E$5+$B18&MostrarNome,tblDados[DATA E HORA]&tblDados[QUEM],0),3),"")} | F18: {=IFERROR(INDEX(tblDados[],MATCH(F$5+$B18&MostrarNome,tblDados[DATA E HORA]&tblDados[QUEM],0),3),"")} | G18: {=IFERROR(INDEX(tblDados[],MATCH(G$5+$B18&MostrarNome,tblDados[DATA E HORA]&tblDados[QUEM],0),3),"")} | H18: {=IFERROR(INDEX(tblDados[],MATCH(H$5+$B18&MostrarNome,tblDados[DATA E HORA]&tblDados[QUEM],0),3),"")} | I18: {=IFERROR(INDEX(tblDados[],MATCH(I$5+$B18&MostrarNome,tblDados[DATA E HORA]&tblDados[QUEM],0),3),"")}
... B23: 0.91666667 | C23: {=IFERROR(INDEX(tblDados[],MATCH(C$5+$B23&MostrarNome,tblDados[DATA E HORA]&tblDados[QUEM],0),3),"")} | D23: {=IFERROR(INDEX(tblDados[],MATCH(D$5+$B23&MostrarNome,tblDados[DATA E HORA]&tblDados[QUEM],0),3),"")} | E23: {=IFERROR(INDEX(tblDados[],MATCH(E$5+$B23&MostrarNome,tblDados[DATA E HORA]&tblDados[QUEM],0),3),"")} | F23: {=IFERROR(INDEX(tblDados[],MATCH(F$5+$B23&MostrarNome,tblDados[DATA E HORA]&tblDados[QUEM],0),3),"")} | G23: {=IFERROR(INDEX(tblDados[],MATCH(G$5+$B23&MostrarNome,tblDados[DATA E HORA]&tblDados[QUEM],0),3),"")} | H23: {=IFERROR(INDEX(tblDados[],MATCH(H$5+$B23&MostrarNome,tblDados[DATA E HORA]&tblDados[QUEM],0),3),"")} | I23: {=IFERROR(INDEX(tblDados[],MATCH(I$5+$B23&MostrarNome,tblDados[DATA E HORA]&tblDados[QUEM],0),3),"")}

Sheet Entrada de dados
B1: ENTRADA DE DADOS
B3: DATA E HORA | C3: QUEM | D3: TAREFA

Sheet DISPO ATIVOS 
A1: DISPONIBILIDADE DE ATIVOS CRÍTICOS
A2: EEE | M2: EAT
B3: G1 | C3: G2 | D3: G3 | E3: G4 | F3: G5 | G3: G6 | H3: G7 | I3: G8 | J3: G9 | K3: TOTAL: | N3: G1 | O3: G2 | P3: G3 | Q3: G4 | R3: G5 | S3: G6 | T3: G7 | U3: G8 | V3: G9 | W3: TOTAL:
A4: PARAFUSO | M4: GUAICURUS
A5: ANDRÉ AZEVEDO | M5: PERI
A6: CAIÇARAS | M6: FARO
M7: JACARANDÁS

Sheet CAPACIDADE
A1: JUNHO
A3: NOME | B3: LOGIN SAP | C3: ESCALA | D3: CARGA HORÁRIA (H) | E3: QTD DIAS TRAB | F3: QTD DIAS AUSENTE | G3: QTD HORAS AUSENTE | H3: CAPACIDADE (MÊS) | I3: REAL TRABALHADO | J3: BASE SAP
A4: LUIZ CLAUDIO FERREIRA DE SOUZA | B4: LSOUZA04 | C4: 5x2 | D4: 9 | E4: 21 | F4: 5 | G4: =D4*F4 -> 45 | H4: =D4*E4 -> 189 | I4: =D4*E4-G4 -> 144 | J4: 72.24
A5: THIAGO DE SOUZA BRAZ | B5: TDSBRAZ | C5: 5x2 | D5: 9 | E5: 21 | F5: 4 | G5: =D5*F5 -> 36 | H5: =D5*E5 -> 189 | I5: =D5*E5-G5 -> 153 | J5: 77.7
A6: RICHARD SILVA DE OLIVEIRA | B6: RSDOLIVEIRA1 | C6: 5x2 | D6: 9 | E6: 21 | F6: 2 | G6: =D6*F6 -> 18 | H6: =D6*E6 -> 189 | I6: =D6*E6-G6 -> 171 | J6: 170.74
A7: DHIEGO SILVESTRE CERESO | B7: DCERESO | C7: 5x2 | D7: 9 | E7: 21 | F7: 3 | G7: =D7*F7 -> 27 | H7: =D7*E7 -> 189 | I7: =D7*E7-G7 -> 162 | J7: 150.67
A8: CARLOS EMMANOEL IGNOCENCIO DO AMARAL | B8: CEIDAMARAL | C8: 5x2 | D8: 9 | E8: 21 | F8: 4 | G8: =D8*F8 -> 36 | H8: =D8*E8 -> 189 | I8: =D8*E8-G8 -> 153 | J8: 150.37
A9: LINALDO DOS SANTOS | B9: LSANTOS7 | C9: 5x2 | D9: 9 | E9: 21 | F9: 5 | G9: =D9*F9 -> 45 | H9: =D9*E9 -> 189 | I9: =D9*E9-G9 -> 144 | J9: 93.75
A10: GILSON MOREIRA SANCHES | B10: GSANCHES | C10: 5x2 | D10: 9 | E10: 21 | F10: 2 | G10: =D10*F10 -> 18 | H10: =D10*E10 -> 189 | I10: =D10*E10-G10 -> 171 | J10: 97.22
A11: FRANCISCO ALVES CAMELO JUNIOR | B11: FAJUNIOR | C11: 2x2 | D11: 11 | E11: 15 | G11: =D11*F11 -> 0 | H11: =D11*E11 -> 165 | I11: =D11*E11-G11 -> 165 | J11: 145.59
A12: GUSTAVO MATHEUS MOREIRA DA SILVA | B12: GSILVA54 | C12: 2x2 | D12: 11 | E12: 15 | G12: =D12*F12 -> 0 | H12: =D12*E12 -> 165 | I12: =D12*E12-G12 -> 165 | J12: 130.09
A13: LUCAS VILANOVA SILVA | B13: LVSILVA | C13: 2x2 | D13: 11 | E13: 15 | G13: =D13*F13 -> 0 | H13: =D13*E13 -> 165 | I13: =D13*E13-G13 -> 165 | J13: 105.92
A14: DIOGO LOGULLO TAVARES MORAIS | B14: DMORAIS01 | C14: 2x2 | D14: 11 | E14: 15 | F14: 11 | G14: =D14*F14 -> 121 | H14: =D14*E14 -> 165 | I14: =D14*E14-G14 -> 44 | J14: 42.98
A15: JOSIVALDO ALEXANDRE DE OLIVEIRA | B15: JOLIVEIRA17 | C15: 2x2 | D15: 11 | E15: 15 | F15: 2 | G15: =D15*F15 -> 22 | H15: =D15*E15 -> 165 | I15: =D15*E15-G15 -> 143 | J15: 140.37
A16: ODILON XAVIER BARRETO DA SILVA GOMES | B16: OGOMES01 | C16: 2x2 | D16: 11 | E16: 15 | F16: 2 | G16: =D16*F16 -> 22 | H16: =D16*E16 -> 165 | I16: =D16*E16-G16 -> 143 | J16: 109.43
A17: EDER RODRIGUES DA SILVA | B17: ESILVA19 | C17: 2x2 | D17: 11 | E17: 15 | F17: 1 | G17: =D17*F17 -> 11 | H17: =D17*E17 -> 165 | I17: =D17*E17-G17 -> 154 | J17: 125.37
A18: JEFFERSON COUTO DE SOUZA | B18: JSOUZA61 | C18: 2x2 | D18: 11 | E18: 15 | G18: =D18*F18 -> 0 | H18: =D18*E18 -> 165 | I18: =D18*E18-G18 -> 165 | J18: 161.48
A19: RIVAL DA MATTA NUNES | B19: RNUNES04 | C19: 2x2 | D19: 11 | E19: 15 | F19: 3 | G19: =D19*F19 -> 33 | H19: =D19*E19 -> 165 | I19: =D19*E19-G19 -> 132 | J19: 129.98
A20: EDSON CARLOS DA SILVA | B20: ESILVA21 | C20: 2x2 | D20: 11 | E20: 15 | G20: =D20*F20 -> 0 | H20: =D20*E20 -> 165 | I20: =D20*E20-G20 -> 165 | J20: 98.61
A21: LEONSTHIN DE CARVALHO MELO | B21: LMELO03 | C21: 2x2 | D21: 11 | E21: 15 | G21: =D21*F21 -> 0 | H21: =D21*E21 -> 165 | I21: =D21*E21-G21 -> 165 | J21: 98.61
A22: WASHINGTON IGOR PONTES NUNES | B22: WNUNES03 | C22: 2x2 | D22: 11 | E22: 15 | F22: 1 | G22: =D22*F22 -> 11 | H22: =D22*E22 -> 165 | I22: =D22*E22-G22 -> 154 | J22: 151.76
A23: TOTAL: | D23: =SUM(D4:D22) -> 195 | E23: =SUM(E4:E22) -> 327 | F23: =SUM(F4:F22) -> 45 | G23: =SUM(G4:G22) -> 445 | H23: =SUM(H4:H22) -> 3303 | I23: =SUM(I4:I22) -> 2858 | J23: =SUM(J4:J22) -> 2252.88
A25: JULHO
A27: NOME | B27: LOGIN SAP | C27: ESCALA | D27: CARGA HORÁRIA (H) | E27: QTD DIAS TRAB | F27: QTD DIAS AUSENTE | G27: QTD HORAS AUSENTE | H27: CAPACIDADE (MÊS) | I27: REAL TRABALHADO | J27: BASE SAP
A28: AMANCIO THIAGO PEDRO DIAS | B28: ADIAS08 | C28: 2x2 | D28: 11 | E28: 15 | G28: =D28*F28 -> 0 | H28: =D28*E28 -> 165 | I28: =D28*E28-G28 -> 165 | J28: 136.06
A29: DHIEGO SILVESTRE CERESO | B29: DCERESO | C29: 2x2 | D29: 11 | E29: 15 | G29: =D29*F29 -> 0 | H29: =D29*E29 -> 165 | I29: =D29*E29-G29 -> 165 | J29: 182.72
A30: EDER RODRIGUES DA SILVA | B30: ESILVA19 | C30: 2x2 | D30: 11 | E30: 15 | G30: =D30*F30 -> 0 | H30: =D30*E30 -> 165 | I30: =D30*E30-G30 -> 165 | J30: 132.87
A31: EDSON CARLOS DA SILVA | B31: ESILVA21 | C31: 2x2 | D31: 11 | E31: 15 | F31: 1 | G31: =D31*F31 -> 11 | H31: =D31*E31 -> 165 | I31: =D31*E31-G31 -> 154 | J31: 111.28
A32: FRANCISCO ALVES CAMILO JUNIOR | B32: FAJUNIOR | C32: 2x2 | D32: 11 | E32: 15 | G32: =D32*F32 -> 0 | H32: =D32*E32 -> 165 | I32: =D32*E32-G32 -> 165 | J32: 169.07
A33: GUSTAVO MATHEUS MOREIRA DA SILVA | B33: GSILVA54 | C33: 2x2 | D33: 11 | E33: 15 | F33: 2 | G33: =D33*F33 -> 22 | H33: =D33*E33 -> 165 | I33: =D33*E33-G33 -> 143 | J33: 135.4
A34: LUCAS SILVA BRAGA D IMPÉRIO AROUCHA | B34: LSBDIAROUCHA | C34: 5x2 | D34: 9 | E34: 23 | G34: =D34*F34 -> 0 | H34: =D34*E34 -> 207 | I34: =D34*E34-G34 -> 207
A35: LUCAS VILANOVA SILVA | B35: LVSILVA | C35: 2x2 | D35: 11 | E35: 15 | G35: =D35*F35 -> 0 | H35: =D35*E35 -> 165 | I35: =D35*E35-G35 -> 165 | J35: 103.83
A36: LUIZ CLAUDIO FERREIRA DE SOUZA | B36: LSOUZA04 | C36: 5x2 | D36: 9 | E36: 23 | F36: 2 | G36: =D36*F36 -> 18 | H36: =D36*E36 -> 207 | I36: =D36*E36-G36 -> 189 | J36: 166.86
A37: ODILON XAVIER BARRETO DA SILVA GOMES | B37: OGOMES01 | C37: 2x2 | D37: 11 | E37: 15 | G37: =D37*F37 -> 0 | H37: =D37*E37 -> 165 | I37: =D37*E37-G37 -> 165 | J37: 130.62
A38: PAULO ROBERTO SENA RODRIGUES SILVA | B38: PSILVA20 | C38: 2x2 | D38: 11 | E38: 15 | F38: 2 | G38: =D38*F38 -> 22 | H38: =D38*E38 -> 165 | I38: =D38*E38-G38 -> 143 | J38: 105.5
A39: RICHARD SILVA DE OLIVEIRA | B39: RSDOLIVEIRA1 | C39: 2x2 | D39: 11 | E39: 15 | G39: =D39*F39 -> 0 | H39: =D39*E39 -> 165 | I39: =D39*E39-G39 -> 165 | J39: 156.54
A40: LINALDO DOS SANTOS | B40: LSANTOS7 | C40: 5x2 | D40: 9 | E40: 23 | G40: =D40*F40 -> 0 | H40: =D40*E40 -> 207 | I40: =D40*E40-G40 -> 207 | J40: 113
A41: RIVAL DA MATTA NUNES | B41: RNUNES04 | C41: 2x2 | D41: 11 | E41: 15 | G41: =D41*F41 -> 0 | H41: =D41*E41 -> 165 | I41: =D41*E41-G41 -> 165 | J41: 132.44
A42: WASHINGTON IGOR PONTES NUNES | B42: WNUNES03 | C42: 5x2 | D42: 9 | E42: 23 | F42: 2 | G42: =D42*F42 -> 18 | H42: =D42*E42 -> 207 | I42: =D42*E42-G42 -> 189 | J42: 148
A43: TOTAL: | D43: =SUM(D28:D42) -> 157 | E43: =SUM(E28:E42) -> 257 | F43: =SUM(F28:F42) -> 9 | G43: =SUM(G28:G42) -> 91 | H43: =SUM(H28:H42) -> 2643 | I43: =SUM(I28:I42) -> 2552 | J43: =SUM(J28:J42) -> 1924.19
...

Sheet CRONOGRAMA MUNCK
A1: 19/09/2025 | B1: 20/09/2025 | C1: 21/09/2025 | D1: 22/09/2025 | E1: 23/09/2025 | F1: 24/09/2025 | G1: 25/09/2025 | H1: 26/09/2025
A2: SEXTA-FEIRA | B2: SÁBADO | C2: DOMINGO | D2: SEGUNDA-FEIRA | E2: TERÇA-FEIRA | F2: QUARTA-FEIRA | G2: QUINTA-FEIRA | H2: SEXTA-FEIRA
A3: FLÁVIO | B3: FLÁVIO | C3: MAURICIO | D3: MAURICIO | E3: FLÁVIO | F3: FLÁVIO | G3: MAURICIO | H3: MAURICIO
A4: COLETAR CAIZA REDUTORA NA PRODUMEC | B4: COLETAR VOLUTA NA WORKMEC | D4: EAT SIQUEIRA CAMPOS - RETIRAR BOMBAS E MOTORES QUE ESTÃO SOLTOS NA UNIDADE | E4: EAT ALMIRANTE ALEXANDRINO - RETIRAR BOMBAS E MOTORES QUE ESTÃO SOLTOS NA UNIDADE
A7: 01/10/2025 | B7: 02/10/2025 | C7: 03/10/2025 | D7: 04/10/2025 | E7: 05/10/2025 | F7: 06/10/2026 | G7: 07/10/2027 | H7: 05/10/2028
A8: QUARTA | B8: QUINTA | C8: SEXTA | D8: SÁBADO | E8: DOMINGO
A9: FLÁVIO | B9: FLÁVIO | C9: MAURICIO | D9: MAURICIO | E9: FLÁVIO
B10: RETIRAR MATERIAIS OBSOLETOS DA ELEVATÓRIA MARACANÃ | C10: RETIRAR BOMBA DE CONSELHEIRO PARANAGUÁ - CL | D10: RETIRAR BOMBAS DA EAT SIQUEIRA CAMPOS E ALMIRANTE ALEXANDRINO
B11: RETIRAR BOMBA DA FARME DE AMOEDO G2 | C11: RETIRAR BOMBA DE ANDRÉ AZEVEDO - CL
B12: COLETAR INVERSOR DE FREQUÊNCIA NA ETE ALEGRIA E DEIXAR NA MENDES DE MORAIS
A15: 06/10/2026 | B15: 07/10/2027 | C15: 47034 | D15: 46304 | E15: 46670 | F15: 47037 | G15: 47038
A16: SEGUNDA | B16: TERÇA | C16: QUARTA | D16: QUINTA | E16: SEXTA | F16: SÁBADO | G16: DOMINGO
A17: PARAFUSO,MOVIMENTAR BOMBA G2 - EDER X ODILON | B17: INSTALAÇÃO CAIXA REDUTORA - PARAFUSO | C17: FARME DE AMOEDO: RETIRAR BOMBA E LEVAR PARA WORKMEC - JEFFERSON X RIVAL
A18: FARME DE AMOEDO: RETIRAR BOMBA E LEVAR PARA WORKMEC - JEFFERSON X RIVAL | B18: SIQUEIRA CAMPOS: RETIRAR EQUIPAMENTOS
A19: SIQUEIRA CAMPOS: RETIRAR EQUIPAMENTOS
A20: RETIRAR MOTOBOMBA ANFIBIA DO CL
A21: RETIRAR BOMBA CENTRÍFUGA DO CL
A22: RETIRAR VARA DE MANOBRA DO CL

Sheet ESCALA EQUIPES
A1: INFORMAÇÕES TIME EMEC - BAIXADA 2 | H1: ESCALA DE TRABALHO
A4: EQUIPE | B4: HORARIO | C4: COLABORADOR | D4: LOGIN SAP | E4: Login Field | F4: FUNÇÃO | G4: ESCALA | H4: =UPPER(TEXT(H5,"DDD")) -> QUI | I4: =UPPER(TEXT(I5,"DDD")) -> SEX | J4: =UPPER(TEXT(J5,"DDD")) -> SÁB | K4: =UPPER(TEXT(K5,"DDD")) -> DOM | L4: =UPPER(TEXT(L5,"DDD")) -> SEG | M4: =UPPER(TEXT(M5,"DDD")) -> TER | N4: =UPPER(TEXT(N5,"DDD")) -> QUA | O4: =UPPER(TEXT(O5,"DDD")) -> QUI | ... AD4: =UPPER(TEXT(AD5,"DDD")) -> SEX
H5: 46205 | I5: =H5+1 -> 46206 | J5: =I5+1 -> 46207 | K5: =J5+1 -> 46208 | L5: =K5+1 -> 46209 | M5: =L5+1 -> 46210 | N5: =M5+1 -> 46211 | O5: =N5+1 -> 46212 | P5: =O5+1 -> 46213 | ... AD5: =AC5+1 -> 46227
A6: C2 | C6: LUIZ CLAUDIO FERREIRA DE SOUZA | D6: LSOUZA04 | F6: TEC. ELETROMECANICA I | G6: COMERCIAL | H6: =IF(OR(TEXT(H$4,"DDD")="SÁB",TEXT(H$4,"DDD")="DOM"),"FOLGA","TRABALHA") -> TRABALHA | I6: =IF(OR(TEXT(I$4,"DDD")="SÁB",TEXT(I$4,"DDD")="DOM"),"FOLGA","TRABALHA") -> TRABALHA | J6: =IF(OR(TEXT(J$4,"DDD")="SÁB",TEXT(J$4,"DDD")="DOM"),"FOLGA","TRABALHA") -> FOLGA | K6: =IF(OR(TEXT(K$4,"DDD")="SÁB",TEXT(K$4,"DDD")="DOM"),"FOLGA","TRABALHA") -> FOLGA | L6: =IF(OR(TEXT(L$4,"DDD")="SÁB",TEXT(L$4,"DDD")="DOM"),"FOLGA","TRABALHA") -> TRABALHA
A7: C1 | B7: DIURNO | C7: CLOVIS DE SOUZA BOAVENTURA | D7: =_xlfn.XLOOKUP($C$7,Planilha2!A:A,Planilha2!B:B) -> CBOAVENTURA | E7: =_xlfn.XLOOKUP(D7,Planilha2!B:B,Planilha2!D:D) -> clovis.boaventura@aguasdorio.com.br | F7: TEC. ELETROMECANICA I | G7: COMERCIAL | H7: =IF(OR(TEXT(H$4,"DDD")="SÁB",TEXT(H$4,"DDD")="DOM"),"FOLGA","TRABALHA") -> TRABALHA | I7: =IF(OR(TEXT(I$4,"DDD")="SÁB",TEXT(I$4,"DDD")="DOM"),"FOLGA","TRABALHA") -> TRABALHA | J7: =IF(OR(TEXT(J$4,"DDD")="SÁB",TEXT(J$4,"DDD")="DOM"),"FOLGA","TRABALHA") -> FOLGA | K7: =IF(OR(TEXT(K$4,"DDD")="SÁB",TEXT(K$4,"DDD")="DOM"),"FOLGA","TRABALHA") -> FOLGA | L7: =IF(OR(TEXT(L$4,"DDD")="SÁB",TEXT(L$4,"DDD")="DOM"),"FOLGA","TRABALHA") -> TRABALHA | M7: =IF(OR(TEXT(M$4,"DDD")="SÁB",TEXT(M$4,"DDD")="DOM"),"FOLGA","TRABALHA") -> TRABALHA | N7: =IF(OR(TEXT(N$4,"DDD")="SÁB",TEXT(N$4,"DDD")="DOM"),"FOLGA","TRABALHA") -> TRABALHA | O7: =IF(OR(TEXT(O$4,"DDD")="SÁB",TEXT(O$4,"DDD")="DOM"),"FOLGA","TRABALHA") -> TRABALHA | ... AD7: =IF(OR(TEXT(AD$4,"DDD")="SÁB",TEXT(AD$4,"DDD")="DOM"),"FOLGA","TRABALHA") -> TRABALHA
A8: C1 | B8: DIURNO | C8: VAGNER LIMA BATISTA | D8: =_xlfn.XLOOKUP(C8,Planilha2!A:A,Planilha2!B:B) -> VBATISTA02 | E8: =_xlfn.XLOOKUP(D8,Planilha2!B:B,Planilha2!D:D) -> vagner.batista@aguasdorio.com.br | F8: TEC. ELETROMECANICA I | G8: COMERCIAL | H8: =IF(OR(TEXT(H$4,"DDD")="SÁB",TEXT(H$4,"DDD")="DOM"),"FOLGA","TRABALHA") -> TRABALHA | I8: =IF(OR(TEXT(I$4,"DDD")="SÁB",TEXT(I$4,"DDD")="DOM"),"FOLGA","TRABALHA") -> TRABALHA | J8: FOLGA | K8: =IF(OR(TEXT(K$4,"DDD")="SÁB",TEXT(K$4,"DDD")="DOM"),"FOLGA","TRABALHA") -> FOLGA | L8: =IF(OR(TEXT(L$4,"DDD")="SÁB",TEXT(L$4,"DDD")="DOM"),"FOLGA","TRABALHA") -> TRABALHA | M8: =IF(OR(TEXT(M$4,"DDD")="SÁB",TEXT(M$4,"DDD")="DOM"),"FOLGA","TRABALHA") -> TRABALHA | N8: =IF(OR(TEXT(N$4,"DDD")="SÁB",TEXT(N$4,"DDD")="DOM"),"FOLGA","TRABALHA") -> TRABALHA | O8: =IF(OR(TEXT(O$4,"DDD")="SÁB",TEXT(O$4,"DDD")="DOM"),"FOLGA","TRABALHA") -> TRABALHA | P8: =IF(OR(TEXT(P$4,"DDD")="SÁB",TEXT(P$4,"DDD")="DOM"),"FOLGA","TRABALHA") -> TRABALHA | Q8: =IF(OR(TEXT(Q$4,"DDD")="SÁB",TEXT(Q$4,"DDD")="DOM"),"FOLGA","TRABALHA") -> FOLGA | R8: =IF(OR(TEXT(R$4,"DDD")="SÁB",TEXT(R$4,"DDD")="DOM"),"FOLGA","TRABALHA") -> FOLGA | ... AD8: =IF(OR(TEXT(AD$4,"DDD")="SÁB",TEXT(AD$4,"DDD")="DOM"),"FOLGA","TRABALHA") -> TRABALHA
A9: C1 | B9: DIURNO | C9: VAGO | D9: - | E9: - | F9: TEC. ELETROMECANICA I | G9: COMERCIAL | H9: =IF(OR(TEXT(H$4,"DDD")="SÁB",TEXT(H$4,"DDD")="DOM"),"FOLGA","TRABALHA") -> TRABALHA | I9: =IF(OR(TEXT(I$4,"DDD")="SÁB",TEXT(I$4,"DDD")="DOM"),"FOLGA","TRABALHA") -> TRABALHA | J9: FOLGA | K9: =IF(OR(TEXT(K$4,"DDD")="SÁB",TEXT(K$4,"DDD")="DOM"),"FOLGA","TRABALHA") -> FOLGA | L9: =IF(OR(TEXT(L$4,"DDD")="SÁB",TEXT(L$4,"DDD")="DOM"),"FOLGA","TRABALHA") -> TRABALHA | M9: =IF(OR(TEXT(M$4,"DDD")="SÁB",TEXT(M$4,"DDD")="DOM"),"FOLGA","TRABALHA") -> TRABALHA | N9: =IF(OR(TEXT(N$4,"DDD")="SÁB",TEXT(N$4,"DDD")="DOM"),"FOLGA","TRABALHA") -> TRABALHA | O9: =IF(OR(TEXT(O$4,"DDD")="SÁB",TEXT(O$4,"DDD")="DOM"),"FOLGA","TRABALHA") -> TRABALHA | P9: =IF(OR(TEXT(P$4,"DDD")="SÁB",TEXT(P$4,"DDD")="DOM"),"FOLGA","TRABALHA") -> TRABALHA | Q9: =IF(OR(TEXT(Q$4,"DDD")="SÁB",TEXT(Q$4,"DDD")="DOM"),"FOLGA","TRABALHA") -> FOLGA | R9: =IF(OR(TEXT(R$4,"DDD")="SÁB",TEXT(R$4,"DDD")="DOM"),"FOLGA","TRABALHA") -> FOLGA | ... AD9: =IF(OR(TEXT(AD$4,"DDD")="SÁB",TEXT(AD$4,"DDD")="DOM"),"FOLGA","TRABALHA") -> TRABALHA
A10: C2 | B10: DIURNO | C10: JORGE LUIZ DA SILVA DOS SANTOS | D10: =_xlfn.XLOOKUP(C10,Planilha2!A:A,Planilha2!B:B) -> JSANTOS121 | E10: =_xlfn.XLOOKUP('ESCALA EQUIPES'!D10,Planilha2!B:B,Planilha2!D:D) -> jorge.dsantos@aguasdorio.com.br | F10: TEC. ELETROMECANICA I | G10: COMERCIAL | H10: =IF(OR(TEXT(H$4,"DDD")="SÁB",TEXT(H$4,"DDD")="DOM"),"FOLGA","TRABALHA") -> TRABALHA | I10: =IF(OR(TEXT(I$4,"DDD")="SÁB",TEXT(I$4,"DDD")="DOM"),"FOLGA","TRABALHA") -> TRABALHA | J10: =IF(OR(TEXT(J$4,"DDD")="SÁB",TEXT(J$4,"DDD")="DOM"),"FOLGA","TRABALHA") -> FOLGA | K10: =IF(OR(TEXT(K$4,"DDD")="SÁB",TEXT(K$4,"DDD")="DOM"),"FOLGA","TRABALHA") -> FOLGA | L10: =IF(OR(TEXT(L$4,"DDD")="SÁB",TEXT(L$4,"DDD")="DOM"),"FOLGA","TRABALHA") -> TRABALHA | M10: =IF(OR(TEXT(M$4,"DDD")="SÁB",TEXT(M$4,"DDD")="DOM"),"FOLGA","TRABALHA") -> TRABALHA | N10: =IF(OR(TEXT(N$4,"DDD")="SÁB",TEXT(N$4,"DDD")="DOM"),"FOLGA","TRABALHA") -> TRABALHA | O10: =IF(OR(TEXT(O$4,"DDD")="SÁB",TEXT(O$4,"DDD")="DOM"),"FOLGA","TRABALHA") -> TRABALHA | ... AD10: =IF(OR(TEXT(AD$4,"DDD")="SÁB",TEXT(AD$4,"DDD")="DOM"),"FOLGA","TRABALHA") -> TRABALHA
A11: C2 | B11: DIURNO | C11: CLAUDIO SOUZA DE MELO | E11: claudio.smelo@aegea.com.br | F11: ELETRICISTA | G11: COMERCIAL | H11: =IF(OR(TEXT(H$4,"DDD")="SÁB",TEXT(H$4,"DDD")="DOM"),"FOLGA","TRABALHA") -> TRABALHA | I11: =IF(OR(TEXT(I$4,"DDD")="SÁB",TEXT(I$4,"DDD")="DOM"),"FOLGA","TRABALHA") -> TRABALHA | J11: =IF(OR(TEXT(J$4,"DDD")="SÁB",TEXT(J$4,"DDD")="DOM"),"FOLGA","TRABALHA") -> FOLGA | K11: =IF(OR(TEXT(K$4,"DDD")="SÁB",TEXT(K$4,"DDD")="DOM"),"FOLGA","TRABALHA") -> FOLGA | L11: =IF(OR(TEXT(L$4,"DDD")="SÁB",TEXT(L$4,"DDD")="DOM"),"FOLGA","TRABALHA") -> TRABALHA | M11: =IF(OR(TEXT(M$4,"DDD")="SÁB",TEXT(M$4,"DDD")="DOM"),"FOLGA","TRABALHA") -> TRABALHA | N11: =IF(OR(TEXT(N$4,"DDD")="SÁB",TEXT(N$4,"DDD")="DOM"),"FOLGA","TRABALHA") -> TRABALHA | O11: =IF(OR(TEXT(O$4,"DDD")="SÁB",TEXT(O$4,"DDD")="DOM"),"FOLGA","TRABALHA") -> TRABALHA | ... AD11: =IF(OR(TEXT(AD$4,"DDD")="SÁB",TEXT(AD$4,"DDD")="DOM"),"FOLGA","TRABALHA") -> TRABALHA
A12: C3 | B12: DIURNO | C12: VALMIR GONCALVES PIRES | D12: =_xlfn.XLOOKUP(C12,Planilha2!A:A,Planilha2!B:B) -> VPIRES | E12: =_xlfn.XLOOKUP(D12,Planilha2!B:B,Planilha2!D:D) -> valmir.pires@aguasdorio.com.br | F12: TEC. ELETROMECANICA I | G12: COMERCIAL | H12: =IF(OR(TEXT(H$4,"DDD")="SÁB",TEXT(H$4,"DDD")="DOM"),"FOLGA","TRABALHA") -> TRABALHA | I12: =IF(OR(TEXT(I$4,"DDD")="SÁB",TEXT(I$4,"DDD")="DOM"),"FOLGA","TRABALHA") -> TRABALHA | J12: FOLGA | K12: =IF(OR(TEXT(K$4,"DDD")="SÁB",TEXT(K$4,"DDD")="DOM"),"FOLGA","TRABALHA") -> FOLGA | L12: =IF(OR(TEXT(L$4,"DDD")="SÁB",TEXT(L$4,"DDD")="DOM"),"FOLGA","TRABALHA") -> TRABALHA | M12: =IF(OR(TEXT(M$4,"DDD")="SÁB",TEXT(M$4,"DDD")="DOM"),"FOLGA","TRABALHA") -> TRABALHA | N12: =IF(OR(TEXT(N$4,"DDD")="SÁB",TEXT(N$4,"DDD")="DOM"),"FOLGA","TRABALHA") -> TRABALHA | O12: =IF(OR(TEXT(O$4,"DDD")="SÁB",TEXT(O$4,"DDD")="DOM"),"FOLGA","TRABALHA") -> TRABALHA | P12: =IF(OR(TEXT(P$4,"DDD")="SÁB",TEXT(P$4,"DDD")="DOM"),"FOLGA","TRABALHA") -> TRABALHA | Q12: =IF(OR(TEXT(Q$4,"DDD")="SÁB",TEXT(Q$4,"DDD")="DOM"),"FOLGA","TRABALHA") -> FOLGA | R12: =IF(OR(TEXT(R$4,"DDD")="SÁB",TEXT(R$4,"DDD")="DOM"),"FOLGA","TRABALHA") -> FOLGA | ... AD12: =IF(OR(TEXT(AD$4,"DDD")="SÁB",TEXT(AD$4,"DDD")="DOM"),"FOLGA","TRABALHA") -> TRABALHA
A13: C3 | B13: DIURNO | C13: ALEXANDRE JOSE FERREIRA | D13: =_xlfn.XLOOKUP(C13,Planilha2!A:A,Planilha2!B:B) -> AFERREIRA17 | E13: =_xlfn.XLOOKUP(D13,Planilha2!B:B,Planilha2!D:D) -> alexandre.jose@aguasdorio.com.br | F13: TEC. ELETROMECANICA I | G13: COMERCIAL | H13: =IF(OR(TEXT(H$4,"DDD")="SÁB",TEXT(H$4,"DDD")="DOM"),"FOLGA","TRABALHA") -> TRABALHA | I13: =IF(OR(TEXT(I$4,"DDD")="SÁB",TEXT(I$4,"DDD")="DOM"),"FOLGA","TRABALHA") -> TRABALHA | J13: =IF(OR(TEXT(J$4,"DDD")="SÁB",TEXT(J$4,"DDD")="DOM"),"FOLGA","TRABALHA") -> FOLGA | K13: =IF(OR(TEXT(K$4,"DDD")="SÁB",TEXT(K$4,"DDD")="DOM"),"FOLGA","TRABALHA") -> FOLGA | L13: =IF(OR(TEXT(L$4,"DDD")="SÁB",TEXT(L$4,"DDD")="DOM"),"FOLGA","TRABALHA") -> TRABALHA | M13: =IF(OR(TEXT(M$4,"DDD")="SÁB",TEXT(M$4,"DDD")="DOM"),"FOLGA","TRABALHA") -> TRABALHA | N13: =IF(OR(TEXT(N$4,"DDD")="SÁB",TEXT(N$4,"DDD")="DOM"),"FOLGA","TRABALHA") -> TRABALHA | O13: =IF(OR(TEXT(O$4,"DDD")="SÁB",TEXT(O$4,"DDD")="DOM"),"FOLGA","TRABALHA") -> TRABALHA | ... AD13: =IF(OR(TEXT(AD$4,"DDD")="SÁB",TEXT(AD$4,"DDD")="DOM"),"FOLGA","TRABALHA") -> TRABALHA
A14: C4 | B14: DIURNO | C14: ANDREW VENANCIO DOS SANTOS SANTANA | D14: ASANTANA04 | E14: andrew.santana@aguasdorio.com.br | F14: TEC. AUTOMAÇÃO I | G14: COMERCIAL | H14: =IF(OR(TEXT(H$4,"DDD")="SÁB",TEXT(H$4,"DDD")="DOM"),"FOLGA","TRABALHA") -> TRABALHA | I14: =IF(OR(TEXT(I$4,"DDD")="SÁB",TEXT(I$4,"DDD")="DOM"),"FOLGA","TRABALHA") -> TRABALHA | J14: =IF(OR(TEXT(J$4,"DDD")="SÁB",TEXT(J$4,"DDD")="DOM"),"FOLGA","TRABALHA") -> FOLGA | K14: =IF(OR(TEXT(K$4,"DDD")="SÁB",TEXT(K$4,"DDD")="DOM"),"FOLGA","TRABALHA") -> FOLGA | L14: =IF(OR(TEXT(L$4,"DDD")="SÁB",TEXT(L$4,"DDD")="DOM"),"FOLGA","TRABALHA") -> TRABALHA | M14: =IF(OR(TEXT(M$4,"DDD")="SÁB",TEXT(M$4,"DDD")="DOM"),"FOLGA","TRABALHA") -> TRABALHA | N14: =IF(OR(TEXT(N$4,"DDD")="SÁB",TEXT(N$4,"DDD")="DOM"),"FOLGA","TRABALHA") -> TRABALHA | O14: =IF(OR(TEXT(O$4,"DDD")="SÁB",TEXT(O$4,"DDD")="DOM"),"FOLGA","TRABALHA") -> TRABALHA | ... AD14: =IF(OR(TEXT(AD$4,"DDD")="SÁB",TEXT(AD$4,"DDD")="DOM"),"FOLGA","TRABALHA") -> TRABALHA
A15: C4 | B15: DIURNO | C15: VINICIUS HENRIQUE GUIMARAES DA SILVA | D15: VHGDSILVA | E15: vinicius.hsilva@aegea.com.br | F15: OPERADOR MULTIFUNCIONAL | G15: COMERCIAL | H15: =IF(OR(TEXT(H$4,"DDD")="SÁB",TEXT(H$4,"DDD")="DOM"),"FOLGA","TRABALHA") -> TRABALHA | I15: =IF(OR(TEXT(I$4,"DDD")="SÁB",TEXT(I$4,"DDD")="DOM"),"FOLGA","TRABALHA") -> TRABALHA | J15: =IF(OR(TEXT(J$4,"DDD")="SÁB",TEXT(J$4,"DDD")="DOM"),"FOLGA","TRABALHA") -> FOLGA | K15: =IF(OR(TEXT(K$4,"DDD")="SÁB",TEXT(K$4,"DDD")="DOM"),"FOLGA","TRABALHA") -> FOLGA | L15: =IF(OR(TEXT(L$4,"DDD")="SÁB",TEXT(L$4,"DDD")="DOM"),"FOLGA","TRABALHA") -> TRABALHA | M15: =IF(OR(TEXT(M$4,"DDD")="SÁB",TEXT(M$4,"DDD")="DOM"),"FOLGA","TRABALHA") -> TRABALHA | N15: =IF(OR(TEXT(N$4,"DDD")="SÁB",TEXT(N$4,"DDD")="DOM"),"FOLGA","TRABALHA") -> TRABALHA | O15: =IF(OR(TEXT(O$4,"DDD")="SÁB",TEXT(O$4,"DDD")="DOM"),"FOLGA","TRABALHA") -> TRABALHA | ... AD15: =IF(OR(TEXT(AD$4,"DDD")="SÁB",TEXT(AD$4,"DDD")="DOM"),"FOLGA","TRABALHA") -> TRABALHA
A17: P1 | B17: DIURNO | C17: ANDRE LUIZ PEREIRA MACIEL FERNANDES | D17: =_xlfn.XLOOKUP(C17,Planilha2!A:A,Planilha2!B:B) -> AMACIEL1 | E17: =_xlfn.XLOOKUP(D17,Planilha2!B:B,Planilha2!D:D) -> andre.maciel@aguasdorio.com.br | F17: TEC. ELETROMECANICA I | G17: PLANTÃO 1 | H17: =IF(MOD($H$5 - DATE(2025,10,1),4)<2,"TRABALHA","FOLGA") -> FOLGA | I17: =IF(MOD(I5 - DATE(2025,10,1),4)<2,"TRABALHA","FOLGA") -> FOLGA | J17: =IF(MOD(J5 - DATE(2025,10,1),4)<2,"TRABALHA","FOLGA") -> TRABALHA | K17: =IF(MOD(K5 - DATE(2025,10,1),4)<2,"TRABALHA","FOLGA") -> TRABALHA | L17: =IF(MOD(L5 - DATE(2025,10,1),4)<2,"TRABALHA","FOLGA") -> FOLGA | M17: =IF(MOD(M5 - DATE(2025,10,1),4)<2,"TRABALHA","FOLGA") -> FOLGA | N17: =IF(MOD(N5 - DATE(2025,10,1),4)<2,"TRABALHA","FOLGA") -> TRABALHA | O17: =IF(MOD(O5 - DATE(2025,10,1),4)<2,"TRABALHA","FOLGA") -> TRABALHA | P17: =IF(MOD(P5 - DATE(2025,10,1),4)<2,"TRABALHA","FOLGA") -> FOLGA | ... AD17: =IF(MOD(AD5 - DATE(2025,10,1),4)<2,"TRABALHA","FOLGA") -> TRABALHA
A18: C2 | B18: DIURNO | C18: RONALDO GOMES BEZERRA | D18: RBEZERRA | E18: ronaldo.bezerra@aguasdorio.com.br | F18: TEC. ELETROMECANICA I | G18: PLANTÃO 1 | H18: =IF(MOD(H5 - DATE(2025,10,1),4)<2,"TRABALHA","FOLGA") -> FOLGA | I18: =IF(MOD(I5 - DATE(2025,10,1),4)<2,"TRABALHA","FOLGA") -> FOLGA | J18: =IF(MOD(J5 - DATE(2025,10,1),4)<2,"TRABALHA","FOLGA") -> TRABALHA | K18: =IF(MOD(K5 - DATE(2025,10,1),4)<2,"TRABALHA","FOLGA") -> TRABALHA | L18: =IF(MOD(L5 - DATE(2025,10,1),4)<2,"TRABALHA","FOLGA") -> FOLGA | M18: =IF(MOD(M5 - DATE(2025,10,1),4)<2,"TRABALHA","FOLGA") -> FOLGA | N18: =IF(MOD(N5 - DATE(2025,10,1),4)<2,"TRABALHA","FOLGA") -> TRABALHA | O18: =IF(MOD(O5 - DATE(2025,10,1),4)<2,"TRABALHA","FOLGA") -> TRABALHA | ... AD18: =IF(MOD(AD5 - DATE(2025,10,1),4)<2,"TRABALHA","FOLGA") -> TRABALHA
A19: P2 | B19: NOTURNO | C19: JHONATA SILVA VIEIRA | D19: JVIEIRA03 | E19: jhonata.vieira@aguasdorio.com.br | F19: ELETRICISTA | G19: PLANTÃO 1 | H19: =IF(MOD(H5 - DATE(2025,10,1),4)<2,"TRABALHA","FOLGA") -> FOLGA | I19: =IF(MOD(I5 - DATE(2025,10,1),4)<2,"TRABALHA","FOLGA") -> FOLGA | J19: =IF(MOD(J5 - DATE(2025,10,1),4)<2,"TRABALHA","FOLGA") -> TRABALHA | K19: =IF(MOD(K5 - DATE(2025,10,1),4)<2,"TRABALHA","FOLGA") -> TRABALHA | L19: =IF(MOD(L5 - DATE(2025,10,1),4)<2,"TRABALHA","FOLGA") -> FOLGA | M19: =IF(MOD(M5 - DATE(2025,10,1),4)<2,"TRABALHA","FOLGA") -> FOLGA | N19: =IF(MOD(N5 - DATE(2025,10,1),4)<2,"TRABALHA","FOLGA") -> TRABALHA | O19: =IF(MOD(O5 - DATE(2025,10,1),4)<2,"TRABALHA","FOLGA") -> TRABALHA | ... AD19: =IF(MOD(AD5 - DATE(2025,10,1),4)<2,"TRABALHA","FOLGA") -> TRABALHA
A20: P2 | B20: NOTURNO | C20: DIEGO SILVA SOUZA | D20: =_xlfn.XLOOKUP(C20,Planilha2!A:A,Planilha2!B:B) -> DSOUZA15 | E20: =_xlfn.XLOOKUP(D20,Planilha2!B:B,Planilha2!D:D) -> diego.ssilva@aguasdorio.com.br | F20: TEC. ELETROMECANICA I | G20: PLANTÃO 1 | H20: =IF(MOD(H5 - DATE(2025,10,1),4)<2,"TRABALHA","FOLGA") -> FOLGA | I20: =IF(MOD(I5 - DATE(2025,10,1),4)<2,"TRABALHA","FOLGA") -> FOLGA | J20: =IF(MOD(J5 - DATE(2025,10,1),4)<2,"TRABALHA","FOLGA") -> TRABALHA | K20: =IF(MOD(K5 - DATE(2025,10,1),4)<2,"TRABALHA","FOLGA") -> TRABALHA | L20: =IF(MOD(L5 - DATE(2025,10,1),4)<2,"TRABALHA","FOLGA") -> FOLGA | M20: =IF(MOD(M5 - DATE(2025,10,1),4)<2,"TRABALHA","FOLGA") -> FOLGA | N20: =IF(MOD(N5 - DATE(2025,10,1),4)<2,"TRABALHA","FOLGA") -> TRABALHA | O20: =IF(MOD(O5 - DATE(2025,10,1),4)<2,"TRABALHA","FOLGA") -> TRABALHA | ... AD20: =IF(MOD(AD5 - DATE(2025,10,1),4)<2,"TRABALHA","FOLGA") -> TRABALHA
A22: P1 | B22: DIURNO | C22: ERICK DO NASCIMENTO BARROS | D22: =_xlfn.XLOOKUP(C22,Planilha2!A:A,Planilha2!B:B) -> EBARROS04 | E22: =_xlfn.XLOOKUP('ESCALA EQUIPES'!D22,Planilha2!B:B,Planilha2!D:D) -> erick.barros@aguasdorio.com.br | F22: TEC. ELETROMECANICA I | G22: PLANTÃO 2 | H22: =IF(MOD(H5 - DATE(2025,10,1)+2,4)<2,"TRABALHA","FOLGA") -> TRABALHA | I22: =IF(MOD(I5 - DATE(2025,10,1)+2,4)<2,"TRABALHA","FOLGA") -> TRABALHA | J22: =IF(MOD(J5 - DATE(2025,10,1)+2,4)<2,"TRABALHA","FOLGA") -> FOLGA | K22: =IF(MOD(K5 - DATE(2025,10,1)+2,4)<2,"TRABALHA","FOLGA") -> FOLGA | L22: =IF(MOD(L5 - DATE(2025,10,1)+2,4)<2,"TRABALHA","FOLGA") -> TRABALHA | M22: =IF(MOD(M5 - DATE(2025,10,1)+2,4)<2,"TRABALHA","FOLGA") -> TRABALHA | N22: =IF(MOD(N5 - DATE(2025,10,1)+2,4)<2,"TRABALHA","FOLGA") -> FOLGA | O22: =IF(MOD(O5 - DATE(2025,10,1)+2,4)<2,"TRABALHA","FOLGA") -> FOLGA | ... AD22: =IF(MOD(AD5 - DATE(2025,10,1)+2,4)<2,"TRABALHA","FOLGA") -> FOLGA
A23: P1 | B23: DIURNO | C23: PAULO SERGIO VIEIRA QUIXABEIRA | D23: =_xlfn.XLOOKUP(C23,Planilha2!A:A,Planilha2!B:B) -> PQUIXABEIRA | E23: =_xlfn.XLOOKUP('ESCALA EQUIPES'!D23,Planilha2!B:B,Planilha2!D:D) -> paulo.quixabeira@aguasdorio.com.br | F23: MECÂNICO MANUTENÇÃO I | G23: PLANTÃO 2 | H23: =IF(MOD(H5 - DATE(2025,10,1)+2,4)<2,"TRABALHA","FOLGA") -> TRABALHA | I23: =IF(MOD(I5 - DATE(2025,10,1)+2,4)<2,"TRABALHA","FOLGA") -> TRABALHA | J23: =IF(MOD(J5 - DATE(2025,10,1)+2,4)<2,"TRABALHA","FOLGA") -> FOLGA | K23: =IF(MOD(K5 - DATE(2025,10,1)+2,4)<2,"TRABALHA","FOLGA") -> FOLGA | L23: =IF(MOD(L5 - DATE(2025,10,1)+2,4)<2,"TRABALHA","FOLGA") -> TRABALHA | M23: =IF(MOD(M5 - DATE(2025,10,1)+2,4)<2,"TRABALHA","FOLGA") -> TRABALHA | N23: =IF(MOD(N5 - DATE(2025,10,1)+2,4)<2,"TRABALHA","FOLGA") -> FOLGA | O23: =IF(MOD(O5 - DATE(2025,10,1)+2,4)<2,"TRABALHA","FOLGA") -> FOLGA | ... AD23: =IF(MOD(AD5 - DATE(2025,10,1)+2,4)<2,"TRABALHA","FOLGA") -> FOLGA
A24: P2 | B24: NOTURNO | C24: MAXWELL RODRIGUES BEDA | D24: =_xlfn.XLOOKUP(C24,Planilha2!A:A,Planilha2!B:B) -> MBEDA | E24: =_xlfn.XLOOKUP('ESCALA EQUIPES'!D24,Planilha2!B:B,Planilha2!D:D) -> maxwell.beda@aguasdorio.com.br | F24: TEC. ELETROMECANICA I | G24: PLANTÃO 2 | H24: =IF(MOD(H5 - DATE(2025,10,1)+2,4)<2,"TRABALHA","FOLGA") -> TRABALHA | I24: =IF(MOD(I5 - DATE(2025,10,1)+2,4)<2,"TRABALHA","FOLGA") -> TRABALHA | J24: =IF(MOD(J5 - DATE(2025,10,1)+2,4)<2,"TRABALHA","FOLGA") -> FOLGA | K24: =IF(MOD(K5 - DATE(2025,10,1)+2,4)<2,"TRABALHA","FOLGA") -> FOLGA | L24: =IF(MOD(L5 - DATE(2025,10,1)+2,4)<2,"TRABALHA","FOLGA") -> TRABALHA | M24: =IF(MOD(M5 - DATE(2025,10,1)+2,4)<2,"TRABALHA","FOLGA") -> TRABALHA | N24: =IF(MOD(N5 - DATE(2025,10,1)+2,4)<2,"TRABALHA","FOLGA") -> FOLGA | O24: =IF(MOD(O5 - DATE(2025,10,1)+2,4)<2,"TRABALHA","FOLGA") -> FOLGA | ... AD24: =IF(MOD(AD5 - DATE(2025,10,1)+2,4)<2,"TRABALHA","FOLGA") -> FOLGA
A25: P2 | B25: NOTURNO | C25: REINALDO BOTELHO GONÇALVES | D25: =_xlfn.XLOOKUP(C25,Planilha2!A:A,Planilha2!B:B) -> RGONCALVES | E25: =_xlfn.XLOOKUP('ESCALA EQUIPES'!D25,Planilha2!B:B,Planilha2!D:D) -> reinaldo.goncalves@aegea.com.br | F25: TEC. ELETROMECANICA I | G25: PLANTÃO 2 | H25: =IF(MOD(H5 - DATE(2025,10,1)+2,4)<2,"TRABALHA","FOLGA") -> TRABALHA | I25: =IF(MOD(I5 - DATE(2025,10,1)+2,4)<2,"TRABALHA","FOLGA") -> TRABALHA | J25: =IF(MOD(J5 - DATE(2025,10,1)+2,4)<2,"TRABALHA","FOLGA") -> FOLGA | K25: =IF(MOD(K5 - DATE(2025,10,1)+2,4)<2,"TRABALHA","FOLGA") -> FOLGA | L25: =IF(MOD(L5 - DATE(2025,10,1)+2,4)<2,"TRABALHA","FOLGA") -> TRABALHA | M25: =IF(MOD(M5 - DATE(2025,10,1)+2,4)<2,"TRABALHA","FOLGA") -> TRABALHA | N25: =IF(MOD(N5 - DATE(2025,10,1)+2,4)<2,"TRABALHA","FOLGA") -> FOLGA | O25: =IF(MOD(O5 - DATE(2025,10,1)+2,4)<2,"TRABALHA","FOLGA") -> FOLGA | ... AD25: =IF(MOD(AD5 - DATE(2025,10,1)+2,4)<2,"TRABALHA","FOLGA") -> FOLGA
A27: Férias | B27: NOTURNO | C27: MARCIO LEANDRO PEREIRA SILVA | D27: =_xlfn.XLOOKUP(C27,Planilha2!A:A,Planilha2!B:B) -> MLEANDRO | E27: =_xlfn.XLOOKUP(D27,Planilha2!B:B,Planilha2!D:D) -> marcio.leandro@aguasdorio.com.br | F27: TEC. ELETROMECANICA I | G27: PLANTÃO 1 | H27: FOLGA | I27: FOLGA | J27: =IF(MOD(J5 - DATE(2025,10,1),4)<2,"TRABALHA","FOLGA") -> TRABALHA | K27: FOLGA | L27: FOLGA | M27: FOLGA | N27: FOLGA | O27: FOLGA | P27: FOLGA | Q27: FOLGA | R27: FOLGA | S27: FOLGA | T27: FOLGA | U27: FOLGA | V27: FOLGA | W27: FOLGA | X27: FOLGA | Y27: FOLGA | Z27: FOLGA | AA27: FOLGA | AB27: FOLGA | AC27: FOLGA | AD27: FOLGA

Sheet Planilha3
A1: COLABORADOR | B1: LOGIN SAP | C1: Login Field | D1: FUNÇÃO
A2: CLOVIS DE SOUZA BOAVENTURA | B2: CBOAVENTURA | C2: clovis.boaventura@aguasdorio.com.br | D2: TEC. ELETROMECANICA I
A3: VAGNER LIMA BATISTA | B3: VBATISTA02 | C3: vagner.batista@aguasdorio.com.br | D3: TEC. ELETROMECANICA I
A4: VINICIUS HENRIQUE GUIMARAES DA SILVA | B4: VHGDSILVA | C4: vinicius.hsilva@aegea.com.br | D4: OPERADOR MULTIFUNCIONAL
A5: JORGE LUIZ DA SILVA DOS SANTOS | B5: JSANTOS121 | C5: jorge.dsantos@aguasdorio.com.br | D5: TEC. ELETROMECANICA I
A6: RONALDO GOMES BEZERRA | B6: RBEZERRA | C6: ronaldo.bezerra@aguasdorio.com.br | D6: TEC. ELETROMECANICA I
A7: JHONATA SILVA VIEIRA | B7: JVIEIRA03 | C7: jhonata.vieira@aguasdorio.com.br | D7: ELETRICISTA
A8: VALMIR GONCALVES PIRES | B8: VPIRES | C8: valmir.pires@aguasdorio.com.br | D8: TEC. ELETROMECANICA I
A9: ALEXANDRE JOSE FERREIRA | B9: AFERREIRA17 | C9: alexandre.jose@aguasdorio.com.br | D9: TEC. ELETROMECANICA I
A10: CLAUDIO SOUZA DE MELO | C10: claudio.smelo@aegea.com.br | D10: ELETRICISTA
A11: ANDRE LUIZ PEREIRA MACIEL FERNANDES | B11: AMACIEL1 | C11: andre.maciel@aguasdorio.com.br | D11: TEC. ELETROMECANICA I
A12: DOUGLAS BRUNO DOS SANTOS SILVA | B12: DSILVA55 | C12: douglas.bruno@aguasdorio.com.br | D12: TEC. ELETROMECANICA I
A13: MARCIO LEANDRO PEREIRA SILVA | B13: MLEANDRO | C13: marcio.leandro@aguasdorio.com.br | D13: TEC. ELETROMECANICA I
A14: DIEGO SILVA SOUZA | B14: DSOUZA15 | C14: diego.ssilva@aguasdorio.com.br | D14: TEC. ELETROMECANICA I
A15: ERICK DO NASCIMENTO BARROS | B15: EBARROS04 | C15: erick.barros@aguasdorio.com.br | D15: TEC. ELETROMECANICA I
A16: PAULO SERGIO VIEIRA QUIXABEIRA | B16: PQUIXABEIRA | C16: paulo.quixabeira@aguasdorio.com.br | D16: MECÂNICO MANUTENÇÃO I
A17: MAXWELL RODRIGUES BEDA | B17: MBEDA | C17: maxwell.beda@aguasdorio.com.br | D17: TEC. ELETROMECANICA I
A18: REINALDO BOTELHO GONÇALVES | B18: RGONCALVES | C18: reinaldo.goncalves@aegea.com.br | D18: TEC. ELETROMECANICA I
A19: ANDREW VENANCIO DOS SANTOS SANTANA | B19: ASANTANA04 | C19: andrew.santana@aguasdorio.com.br | D19: TEC. AUTOMAÇÃO I

Sheet Planilha2
A1: CLOVIS DE SOUZA BOAVENTURA | B1: CBOAVENTURA | C1: TEC. ELETROMECANICA I | D1: clovis.boaventura@aguasdorio.com.br | E1: COMERCIAL | F1: 21 99508-1150
A2: JHONATA SILVA VIEIRA | B2: JVIEIRA03 | C2: ELETRICISTA I | D2: jhonata.vieira@aguasdorio.com.br | E2: COMERCIAL | F2: 21 99653-9956
A3: ANDREW VENANCIO DOS SANTOS SANTANA | B3: ASANTANA04 | C3: TEC. AUTOMAÇÃO I | D3: andrew.santana@aguasdorio.com.br | E3: COMERCIAL | F3: 21 99653-9956
A4: VINICIUS HENRIQUE GUIMARAES DA SILVA | B4: VHGDSILVA | C4: OPERADOR MULTIFUNCIONAL | D4: vinicius.hsilva@aegea.com.br | E4: COMERCIAL | F4: 21 99897-8785
A5: ALEXANDRE JOSE FERREIRA | B5: AFERREIRA17 | C5: TEC. ELETROMECANICA I | D5: alexandre.jose@aguasdorio.com.br | E5: PLANTÃO 2 | F5: 21 97126-8976
A6: MARCELO DE SOUZA LIMA | C6: MOTORISTA MAQ. PESADA | D6: marcelo.dlima@aguasdorio.com.br | E6: COMERCIAL | F6: 21 99705-0724
A8: MARCIO LEANDRO PEREIRA SILVA | B8: MLEANDRO | C8: TEC. ELETROMECANICA I | D8: marcio.leandro@aguasdorio.com.br | E8: PLANTÃO 1 | F8: 21 97241-9524
A9: DIEGO SILVA SOUZA | B9: DSOUZA15 | C9: TEC. ELETROMECANICA I | D9: diego.ssilva@aguasdorio.com.br | E9: PLANTÃO 1 | F9: 21 97241-9524
A10: ANDRE LUIZ PEREIRA MACIEL FERNANDES | B10: AMACIEL1 | C10: TEC. ELETROMECANICA I | D10: andre.maciel@aguasdorio.com.br | E10: PLANTÃO 1 | F10: 21 96775-8413
A11: DOUGLAS BRUNO DOS SANTOS SILVA | B11: DSILVA55 | C11: TEC. ELETROMECANICA I | D11: douglas.bruno@aguasdorio.com.br | E11: PLANTÃO 1 | F11: 21 97241-9524
A12: VALMIR GONCALVES PIRES | B12: VPIRES | C12: TEC. ELETROMECANICA I | D12: valmir.pires@aguasdorio.com.br | E12: PLANTÃO 1 | F12: 21 97188-6799
A14: RONALDO GOMES BEZERRA | B14: RBEZERRA | C14: TEC. ELETROMECANICA I | D14: ronaldo.bezerra@aguasdorio.com.br | E14: PLANTÃO 2 | F14: 21 97188-6799
A15: JORGE LUIZ DA SILVA DOS SANTOS | B15: JSANTOS121 | C15: TEC. ELETROMECANICA I | D15: jorge.dsantos@aguasdorio.com.br | E15: PLANTÃO 2 | F15: 21 97126-8976
A16: ERICK DO NASCIMENTO BARROS | B16: EBARROS04 | C16: TEC. ELETROMECANICA I | D16: erick.barros@aguasdorio.com.br | E16: PLANTÃO 2 | F16: 21 99578-3656
A17: PAULO SERGIO VIEIRA QUIXABEIRA | B17: PQUIXABEIRA | C17: MECÂNICO MANUTENÇÃO I | D17: paulo.quixabeira@aguasdorio.com.br | E17: PLANTÃO 2 | F17: 21 99578-3656
A18: MAXWELL RODRIGUES BEDA | B18: MBEDA | C18: TEC. ELETROMECANICA I | D18: maxwell.beda@aguasdorio.com.br | E18: PLANTÃO 2 | F18: 21 97221-7726
A19: VAGNER LIMA BATISTA | B19: VBATISTA02 | C19: TEC. ELETROMECANICA I | D19: vagner.batista@aguasdorio.com.br | E19: PLANTÃO 2 | F19: 21 99508-1150
A20: REINALDO BOTELHO GONÇALVES | B20: RGONCALVES | C20: TEC. ELETROMECANICA I | D20: reinaldo.goncalves@aegea.com.br | E20: PLANTÃO 2 | F20: 21 97221-7726

Sheet Planilha1
A1: QUANT. | B1: VALOR UNITÁRIO | C1: TOTAL
A2: 1 | B2: 3000 | C2: =B2*A2 -> 3000
A3: 1 | B3: 3000 | C3: =B3*A3 -> 3000
A4: 4 | B4: 4200 | C4: =B4*A4 -> 16800
A5: 4 | B5: 400 | C5: =B5*A5 -> 1600
A6: 4 | B6: 635.95 | C6: =B6*A6 -> 2543.8
A7: 2 | B7: 69.2 | C7: =B7*A7 -> 138.4
A8: 1 | B8: 3000 | C8: =B8*A8 -> 3000
A9: 10 | B9: 87.31 | C9: =B9*A9 -> 873.1
A10: 13 | B10: 58.02 | C10: =B10*A10 -> 754.26
A11: 15 | B11: 58.02 | C11: =B11*A11 -> 870.3
A12: 15 | B12: 47.9 | C12: =B12*A12 -> 718.5
A13: 15 | B13: 53.32 | C13: =B13*A13 -> 799.8
... A110: 1 | B110: 1215550 | C110: =B110*A110 -> 1215550
B113: TOTAL GERAL: | C113: =SUM(C2:C110) -> 5609840.8

Sheet Pesquisa de nome
A1: Esta planilha preenche a lista suspensa de nomes na planilha Agenda da célula H3. Qualquer alteração feita nesta planilha pode resultar em erro.
A2: NOME EXCLUSIVO | B2: NÚMERO DA LINHA
A3: {=IFERROR(INDEX(CampoQuem,MATCH(0,COUNTIF($A$2:A2,CampoQuem),0)),"")} -> 0 | B3: =IF(A3="","",ROW()) -> 3
A4: {=IFERROR(INDEX(CampoQuem,MATCH(0,COUNTIF($A$2:A3,CampoQuem),0)),"")} | B4: =IF(A4="","",ROW())
A5: {=IFERROR(INDEX(CampoQuem,MATCH(0,COUNTIF($A$2:A4,CampoQuem),0)),"")} | B5: =IF(A5="","",ROW())
A6: {=IFERROR(INDEX(CampoQuem,MATCH(0,COUNTIF($A$2:A5,CampoQuem),0)),"")} | B6: =IF(A6="","",ROW())
A7: {=IFERROR(INDEX(CampoQuem,MATCH(0,COUNTIF($A$2:A6,CampoQuem),0)),"")} | B7: =IF(A7="","",ROW())
A8: {=IFERROR(INDEX(CampoQuem,MATCH(0,COUNTIF($A$2:A7,CampoQuem),0)),"")} | B8: =IF(A8="","",ROW())
A9: {=IFERROR(INDEX(CampoQuem,MATCH(0,COUNTIF($A$2:A8,CampoQuem),0)),"")} | B9: =IF(A9="","",ROW())
A10: {=IFERROR(INDEX(CampoQuem,MATCH(0,COUNTIF($A$2:A9,CampoQuem),0)),"")} | B10: =IF(A10="","",ROW())
A11: {=IFERROR(INDEX(CampoQuem,MATCH(0,COUNTIF($A$2:A10,CampoQuem),0)),"")} | B11: =IF(A11="","",ROW())
A12: {=IFERROR(INDEX(CampoQuem,MATCH(0,COUNTIF($A$2:A11,CampoQuem),0)),"")} | B12: =IF(A12="","",ROW())
A13: {=IFERROR(INDEX(CampoQuem,MATCH(0,COUNTIF($A$2:A12,CampoQuem),0)),"")} | B13: =IF(A13="","",ROW())
A14: {=IFERROR(INDEX(CampoQuem,MATCH(0,COUNTIF($A$2:A13,CampoQuem),0)),"")} | B14: =IF(A14="","",ROW())
... A131: {=IFERROR(INDEX(CampoQuem,MATCH(0,COUNTIF($A$2:A130,CampoQuem),0)),"")} | B131: =IF(A131="","",ROW())
