Workbook

Sheet COORDENADAS
A1: COD_PLANTA | B1: COD_LATITUDE | C1: COD_LONGITUDE
A2: PL-RJB-CTE0002 | B2: -22.8 | C2: -43.4271
A3: PL-RJB-CTE0003 | B3: -22.7883 | C3: -43.4116
A4: PL-RJB-ECT0201 | B4: -22.6565 | C4: -43.6641
A5: PL-RJB-ECT0202 | B5: -22.6859 | C5: -43.4399
A6: PL-RJB-ECT0203 | B6: -22.6541 | C6: -43.5368
A7: PL-RJB-ECT0204 | B7: -22.7084 | C7: -43.4288
A8: PL-RJB-ECT0207 | B8: -22.7972 | C8: -43.5713
A9: PL-RJB-ECT0212 | B9: -22.7778 | C9: -43.3977
A10: PL-RJB-ECT0216 | B10: -22.7969 | C10: -43.5561
A11: PL-RJB-ECT0227 | B11: -22.7639 | C11: -43.4983
A12: PL-RJB-ECT0228 | B12: -22.8098 | C12: -43.5894
A13: PL-RJB-ECT0230 | B13: -22.7163 | C13: -43.5519
... A225: PL-RJB-EEE1100 | B225: -22.7892 | C225: -43.4099
A226: PL-RJB-EEE0073 | C226: -43.4273
A227: PL-RJB-EEE0080 | B227: -22.7792 | C227: -43.433
A228: PL-RJB-EEE0081 | B228: -22.7828 | C228: -43.433
A229: PL-RJB-EEE0082 | B229: -22.7962 | C229: -43.5912
A230: PL-RJB-EEE0083 | B230: -22.8027 | C230: -43.5901
A231: PL-RJB-LJA0003 | B231: -22.7828 | C231: -43.4302
A232: PL-RJB-LJA0005 | B232: -22.644 | C232: -43.6565
A233: PL-RJB-LJA0006 | B233: -22.8095 | C233: -43.4158
A234: PL-RJB-LJA0007 | B234: -22.7154 | C234: -43.5569
A235: PL-RJB-SDA1003 | B235: -22.8113 | C235: -43.4101

Sheet NOVAS ELEVATÓRIAS
B1: Tipo EEAT | C1: Segmento | D1: EEAT | F1: Cidade | G1: População | H1: Status | I1: Fase Atual | J1: Etapas restantes | K1: Observações / Inconformidades
B2: EEAT | C2: Água | D2: Baixo Pedreira | F2: Nova Iguaçu | G2: 1421
B3: Elevatória | C3: Água | D3: Camburi | F3: Queimados | G3: 24707
B4: Elevatória | C4: Água | D4: Nélio Chambarelli | F4: Queimados | G4: 596
B5: Elevatória | C5: Água | D5: Messias | F5: Japeri | G5: 581
B6: Booster | C6: Água | D6: Boa Esperança | F6: Nova Iguaçu
B7: Booster | C7: Água | D7: Tinguazinho | F7: Nova Iguaçu
B8: Elevatória | C8: Água | D8: Bela Vista | F8: Nova Iguaçu
B9: Booster | C9: Água | D9: Comendador Soares | F9: Nova Iguaçu
B10: Booster | C10: Água | D10: Chacrinha | F10: Japeri | G10: 1642
B11: Elevatória | C11: Água | D11: Manoel Dias | F11: Nova Iguaçu
B12: Elevatória | C12: Água | D12: Morro do Tinguazinho | F12: Nova Iguaçu | G12: 3249
C13: Água | D13: Iara
C14: Água | D14: São Joaquim
C15: Água | D15: Bento Rubião
B16: Elevatória | C16: Água | D16: Santa Rita / Corumbá | E16: JÁ INSTALADA
C17: Água | D17: Ambaí
C18: Água | D18: Nova Cidade
B19: Container | C19: Água | D19: Liberdade | E19: JÁ INSTALADA
C20: Água | D20: Beira Linha
B21: Container | C21: Água | D21: BNH | E21: JÁ INSTALADA
C22: Água | D22: Jaqueira
C23: Água | D23: Morro da Paz
C24: Água | D24: Colombo
C25: Água | D25: Beira Rio
C26: Água | D26: Dona Afra
C27: Água | D27: Carlos Monsante
B28: Container | C28: Água | D28: Biquinha | E28: JÁ INSTALADA
C29: Água | D29: São Simão
C30: Água | D30: Adibe Saad

Sheet RELAÇÃO DE ELEVATÓRIAS
A1: DADOS INFORMATIVOS | O1: DADOS DO EQUIPAMENTO INSTALADO | AN1: ALIMENTAÇÃO | AP1: DADOS DA CONCESSIONÁRIA DE ENERGIA | AU1: DIAMETRO DA TUBULACAO | AY1: DADOS GEOGRÁFICOS | BA1: PAINÉIS | BJ1: AUTOMAÇÃO | BR1: SETPOINT | BU1: TOMADA DE RETAGUARDA | BV1: TOMADA DE RECALQUE | BW1: ELETRODO SUPERIOR | BX1: ELETRODO INFERIOR | BY1: TIPO DE RECALQUE | BZ1: COTA NA ELEVATORIA | CA1: COTA MAXIMA | CB1: DISTANCIA DA ELEV. A COORDENACAO | CC1: COMUNIDADES / HOSPITAIS / LOCALIDADES IMPORTANTES ABASTECIDAS | CD1: AREA DE INFLUENCIA
A2: ELEVATORIAS | B2: PLANTA | C2: TIPO | D2: SUPERINTENDÊNCIA | E2: ENDEREÇO | F2: BAIRRO | G2: MUNICIPIO | H2: CEP | I2: LATITUDE | J2: LONGITUDE | K2: Inicio de Operação | L2: CARACTERÍSTICAS DA ÁREA | M2: GRUPO | N2: FUNÇÃO | O2: POTÊNCIA DO MOTOR (CV) | P2: RPM | Q2: MARCA DO MOTOR | R2: CARCAÇA DO MOTOR | S2: TAG DO MOTOR | T2: TENSÃO (V) | U2: CORRENTE (A) | V2: MANCAIS (LA) | W2: MANCAIS (LOA) | X2: MODELO DA BOMBA | Y2: TAG DA BOMBA | Z2: MARCA DA BOMBA | AA2: Ø ROTOR (pol) | AB2: Ø ROTOR (mm) | AC2: TIPO CONSTRUTIVO DA ELEVATORIA | AD2: BOMBA DRENO (SIM/NÃO) | AE2: PONTA DO EIXO DO MOTOR | AF2: SENTIDO DE MONTAGEM DO MOTOR | AG2: FLANGE | AH2: FORMA CONSTRUTIVA DA BOMBA | AI2: VAZÃO APROXIMADA (M³/H) | AJ2: AMT APROXIMADA | AK2: Capacidade de tratamento | AL2: Procedência do MCA | AM2: CÓD SAP | AN2: BT/MT | AO2: TRAFO (KVA) | AP2: N° CLIENTE | AQ2: MEDIDOR | AR2: MEDIDOR APURADO + DATA | AS2: UNIDADE DE CONSUMO | AT2: ENDEREÇO | AU2: SUCCAO | AV2: RECALQUE | AW2: TRONCO | AX2: DISTACIA ATE A ELEV. | AY2: POPULAÇÃO BENEFICIADA EM HABITANTES | AZ2: DOMICILIOS | BA2: FUSÍVEL (PC) | BB2: DISJUNTOR (PC) | BC2: REGULAGEM DO RELE TÉRMICO BIMETÁLICO | BD2: RELÉ DE TEMPO ΔY | BE2: RELÉ DE ELETRODO (NÍVEL) | BF2: MONITOR DE CORRENTE | BG2: TAMANHO DO FUSÍVEL NH | BH2: CORRENTE DO FUSÍVEL NH | BI2: CORRENTE DO FUSÍVEL DZ | BJ2: TAG PAINEL | BK2: TIPO DE ACIONAMENTO | BL2: FABRICANTE DO ACIONAMENTO | BM2: MODELO DE ACIONAMENTO | BN2: Corrente (A) | BO2: TAG DO ACIONAMENTO | BP2: CLP | BQ2: PCP | BR2: RETAGUARDA LIGA | BS2: RETAGUARDA DESLIGA | BT2: RECALQUE
A3: ADOLFO BERGAMINI / ALTO MILITÂO | B3: =_xlfn.XLOOKUP(A:A,'Dados Elevatórias'!D:D,'Dados Elevatórias'!B:B) -> PL-RJB-EAT0093 | C3: =_xlfn.XLOOKUP(B:B,'Dados Elevatórias'!B:B,'Dados Elevatórias'!C:C) -> EAT | D3: BAIXADA 2 | E3: Estr. Gen. Mena Barreto, 821 - Novo Horizonte, Nilópolis - RJ, 26535-330 | F3: Novo Horizonte | G3: NILÓPOLIS | H3: =_xlfn.XLOOKUP(B:B,'Dados Elevatórias'!B:B,'Dados Elevatórias'!G:G) -> 26535-330 | I3: =_xlfn.XLOOKUP(B3,COORDENADAS!A:A,COORDENADAS!B:B) -> -22.8035 | J3: =_xlfn.XLOOKUP(B3,COORDENADAS!A:A,COORDENADAS!C:C) -> -43.4081 | L3: FORMAL | M3: 1 | N3: OPERACIONAL | O3: 25CV | P3: 3480rpm | T3: 220 | U3: 68.4 | X3: HAR25195B1 | Y3: RJB-21219 | Z3: HELBOMBAS | AA3: 3 | AB3: 142mm | AC3: TUBULÂO | AD3: NÃO | AI3: 100m³/h | AN3: =_xlfn.XLOOKUP(A:A,'RELAÇÃO ANTIGA'!A:A,'RELAÇÃO ANTIGA'!AC:AC,X) -> 220V | AP3: 420150274 | AQ3: 5241361 | AR3: 0 | AS3: AGUA - BOOSTER - ADOLFO BERGAMINI | AT3: R JOAO RODRIGUES DA CUNHA SN PX1195 | AU3: 100 | AV3: 150 | AW3: 0 | AX3: 0 | AY3: 0 | AZ3: 0 | BJ3: RJB-14411 | BK3: INVERSOR DE FREQUÊNCIA | BL3: DANFOSS | BM3: VLT Aqua Drive | BN3: 88A | BO3: RJA-03553 | BP3: SIM | BR3: 1 MCA | BS3: < 1 MCA | BT3: 22 MCA | BU3: 1\2º | BV3: 1\2º | BW3: SIM | BY3: EM MARCHA | BZ3: 24 | CA3: 53 | CB3: 0 | CC3: 0 | CD3: Area 1: Rua Adolfo Bergamin (Trecho Rua Mena Barreto A Rua JoAo da Mata Peixoto), Rua Natividade (Trecho Rua Adolfo Bergamin A Rua MArio Valadares), Rua Romilda Alves, Rua Embaixador Von Spritt, Rua Aurea P. Farjado, Rua GenEsio de Barros e pequenas Vilas desse trecho. Area 2: Rua JoAo da Mata Peixoto (Trecho do nº 182 A Rua MArio Valadares), Rua Adolfo Bergamin (Trecho Rua JoAo da Mata Peixoto A Rua Antonio J. Bittencourt), Rua JoAo F. da Silva, Rua Maria InEs QueirOs, Rua AmErico Diamantino Lopes, Rua JosE da Silva Braga (Trecho Rua MArio Valadares A Rua AntOnio J. Bittencourt), Rua Francisco M. da Silva. Area 3: Rua JoAo da Mata Peixoto (Trecho Rua Otacilio Pessoa), Rua JoAo da Cruz Saldanha, Rua Lauro Machado e pequenas Vilas desse trecho.
A4: ADOLFO BERGAMINI / ALTO MILITÂO | B4: =_xlfn.XLOOKUP(A:A,'Dados Elevatórias'!D:D,'Dados Elevatórias'!B:B) -> PL-RJB-EAT0093 | C4: =_xlfn.XLOOKUP(B:B,'Dados Elevatórias'!B:B,'Dados Elevatórias'!C:C) -> EAT | D4: BAIXADA 2 | E4: Estr. Gen. Mena Barreto, 821 - Novo Horizonte, Nilópolis - RJ, 26535-330 | F4: Novo Horizonte | G4: NILÓPOLIS | H4: =_xlfn.XLOOKUP(B:B,'Dados Elevatórias'!B:B,'Dados Elevatórias'!G:G) -> 26535-330 | I4: =_xlfn.XLOOKUP(B4,COORDENADAS!A:A,COORDENADAS!B:B) -> -22.8035 | J4: =_xlfn.XLOOKUP(B4,COORDENADAS!A:A,COORDENADAS!C:C) -> -43.4081 | L4: FORMAL | M4: 2 | N4: OPERACIONAL | O4: 25CV | P4: 3550rpm | Q4: WEG | R4: 160M | S4: RJB-21217 | T4: 220V / 380V / 440V | U4: 60.8 / 35.2 / 30.4A | Y4: RJB-25854 | AA4: 3 | AC4: CONTAINER | AF4: HORIZONTAL | AH4: CONVENSIONAL | AN4: =_xlfn.XLOOKUP(A:A,'RELAÇÃO ANTIGA'!A:A,'RELAÇÃO ANTIGA'!AC:AC,X) -> 220V | AP4: 420150274 | AQ4: 5241361 | AR4: 0 | AS4: AGUA - BOOSTER - ADOLFO BERGAMINI | AT4: R JOAO RODRIGUES DA CUNHA SN PX1195 | AU4: 100 | AV4: 150 | AW4: 0 | AX4: 0 | AY4: 0 | AZ4: 0 | BJ4: RJB-26852 | BK4: INVERSOR DE FREQUÊNCIA | BL4: SIEMENS | BM4: PM240-2 | BN4: 68A | BO4: RJB-30606 | BP4: SIM | BR4: 1 MCA | BS4: < 1 MCA | BT4: 22 MCA | BU4: 1\2º | BV4: 1\2º | BW4: SIM | BY4: EM MARCHA | BZ4: 24 | CA4: 53 | CB4: 0 | CC4: 0 | CD4: Area 1: Rua Adolfo Bergamin (Trecho Rua Mena Barreto A Rua JoAo da Mata Peixoto), Rua Natividade (Trecho Rua Adolfo Bergamin A Rua MArio Valadares), Rua Romilda Alves, Rua Embaixador Von Spritt, Rua Aurea P. Farjado, Rua GenEsio de Barros e pequenas Vilas desse trecho. Area 2: Rua JoAo da Mata Peixoto (Trecho do nº 182 A Rua MArio Valadares), Rua Adolfo Bergamin (Trecho Rua JoAo da Mata Peixoto A Rua Antonio J. Bittencourt), Rua JoAo F. da Silva, Rua Maria InEs QueirOs, Rua AmErico Diamantino Lopes, Rua JosE da Silva Braga (Trecho Rua MArio Valadares A Rua AntOnio J. Bittencourt), Rua Francisco M. da Silva. Area 3: Rua JoAo da Mata Peixoto (Trecho Rua Otacilio Pessoa), Rua JoAo da Cruz Saldanha, Rua Lauro Machado e pequenas Vilas desse trecho.
A5: AMAURI GUIMARAES | B5: =_xlfn.XLOOKUP(A:A,'Dados Elevatórias'!D:D,'Dados Elevatórias'!B:B) -> PL-RJB-EAT0687 | C5: =_xlfn.XLOOKUP(B:B,'Dados Elevatórias'!B:B,'Dados Elevatórias'!C:C) -> EAT | D5: BAIXADA 2 | E5: R. Ângela Maria, 2 - Posse, Nova Iguaçu - RJ, 26089-175 | F5: Floresta | G5: NOVA IGUAÇU | H5: =_xlfn.XLOOKUP(B:B,'Dados Elevatórias'!B:B,'Dados Elevatórias'!G:G) -> 26031-200 | I5: =_xlfn.XLOOKUP(B5,COORDENADAS!A:A,COORDENADAS!B:B) -> -22.736 | J5: =_xlfn.XLOOKUP(B5,COORDENADAS!A:A,COORDENADAS!C:C) -> -43.4782 | L5: FORMAL | M5: 1 | N5: OPERACIONAL | O5: 7.5cv | AC5: TUBULÂO | AF5: ANFÍBIA | AH5: SUBMERSIVEL | AN5: =_xlfn.XLOOKUP(A:A,'RELAÇÃO ANTIGA'!A:A,'RELAÇÃO ANTIGA'!AC:AC,X) -> 220V | AP5: 430248796 | AQ5: 169005 | AR5: 0 | AS5: AGUA - ELEV - AMAURI GUIMARÃES | AT5: RUA GENI SARAIVA E/F 1998 | AU5: 0 | AV5: 0 | AW5: 0 | AX5: 0 | AY5: 0 | AZ5: 0 | BK5: SOFT STARTER | BP5: NÃO | BR5: 0 | BS5: 0 | BT5: 0 | BU5: 0 | BV5: 0 | BW5: SIM | BY5: EM MARCHA | BZ5: 0 | CA5: 0 | CB5: 0 | CC5: 0 | CD5: 0
A6: ÂNGELA MARIA | B6: =_xlfn.XLOOKUP(A:A,'Dados Elevatórias'!D:D,'Dados Elevatórias'!B:B) -> PL-RJB-EAT0088 | C6: =_xlfn.XLOOKUP(B:B,'Dados Elevatórias'!B:B,'Dados Elevatórias'!C:C) -> EAT | D6: BAIXADA 2 | E6: R. Oliveiros Rodrigues Alves, 130 - Jardim da Posse, Nova Iguaçu - RJ, 26030-010 | F6: Jardim da Posse | G6: NOVA IGUAÇU | H6: =_xlfn.XLOOKUP(B:B,'Dados Elevatórias'!B:B,'Dados Elevatórias'!G:G) -> 26030-010 | I6: =_xlfn.XLOOKUP(B6,COORDENADAS!A:A,COORDENADAS!B:B) -> -22.7388 | J6: =_xlfn.XLOOKUP(B6,COORDENADAS!A:A,COORDENADAS!C:C) -> -43.4551 | L6: FORMAL | M6: 1 | N6: OPERACIONAL | O6: 3vc | AC6: CASINHA | AN6: 220V | AP6: 420594529 | AQ6: 73520772 | AR6: 0 | AS6: AGUA - ELEV - ANGELA MARIA | AT6: R ANGELA MARIA SN EF127 | AU6: DN 50 / 2 POL | AV6: DN 50 / 2 POL | AW6: 0 | AX6: 0 | AY6: 0 | AZ6: 0 | BK6: PARTIDA DIRETA | BP6: NÃO | BR6: 0 | BS6: 0 | BT6: 0 | BU6: 1\2º | BV6: 1\2º | BW6: SIM | BY6: EM MARCHA | BZ6: - | CA6: - | CB6: - | CC6: 0 | CD6: 0
A7: ANTONIO VALDIGEM | B7: =_xlfn.XLOOKUP(A:A,'Dados Elevatórias'!D:D,'Dados Elevatórias'!B:B) -> PL-RJB-EAT0736 | C7: =_xlfn.XLOOKUP(B:B,'Dados Elevatórias'!B:B,'Dados Elevatórias'!C:C) -> EAT | D7: BAIXADA 2 | E7: R. Antonio Valdigem, 51 - Queimados, RJ, 26385-300 | F7: Vila das porteiras | G7: QUEIMADOS | H7: =_xlfn.XLOOKUP(B:B,'Dados Elevatórias'!B:B,'Dados Elevatórias'!G:G) -> 26385-300 | I7: =_xlfn.XLOOKUP(B7,COORDENADAS!A:A,COORDENADAS!B:B) -> -22.704 | J7: =_xlfn.XLOOKUP(B7,COORDENADAS!A:A,COORDENADAS!C:C) -> -43.5529 | L7: INFORMAL | M7: 1 | N7: OPERACIONAL | O7: 20cv | P7: 3535rpm | Q7: Weg | R7: 160m | S7: RJB-21457 | T7: 220V / 380V / 440V | U7: 49.8 / 28.8 / 24.9 | X7: GSD-32/200 20.0 | Y7: RJB-21458 | Z7: Ebara | AA7: 2 | AB7: 197mm | AC7: ABRIGADA | AD7: NÃO | AF7: HORIZONTAL | AH7: CONVENSIONAL | AI7: 40M3/h | AJ7: 54mca | AN7: =_xlfn.XLOOKUP(A:A,'RELAÇÃO ANTIGA'!A:A,'RELAÇÃO ANTIGA'!AC:AC,X) -> 220V | AP7: 420630267 | AQ7: 8663425 | AR7: 0 | AS7: AGUA - BVOLANTE - ANTONIO WEINSCHENK | AT7: R ANTONIO VALDIGEM SN CA1 EF25 | AU7: 2 | AV7: 1.1/4 | AW7: 0 | AX7: 0 | AY7: 0 | AZ7: 0 | BJ7: RJB-23520 | BK7: INVERSOR DE FREQUÊNCIA | BL7: ABB | BM7: ACO580-01-089A-2 | BN7: 89/74,8 A | BO7: RJB-23544 | BP7: SIM | BR7: 1 MCA | BS7: 0,2 MCA | BT7: 43 MCA | BU7: NÃO | BV7: NÃO | BW7: NÃO | BX7: NÃO | BY7: EM MARCHA | BZ7: 0 | CA7: 0 | CB7: 0 | CC7: MORRO AZUL | CD7: 0
A8: BEIRA LINHA | B8: =_xlfn.XLOOKUP(A:A,'Dados Elevatórias'!D:D,'Dados Elevatórias'!B:B) -> PL-RJB-EAT0688 | C8: =_xlfn.XLOOKUP(B:B,'Dados Elevatórias'!B:B,'Dados Elevatórias'!C:C) -> EAT | D8: BAIXADA 2 | E8: Av Beira Linha 275 - Miguel Couto - Nova Iguaçu | F8: Miguel Couto | G8: NOVA IGUAÇU | H8: 26070-320 | I8: =_xlfn.XLOOKUP(B8,COORDENADAS!A:A,COORDENADAS!B:B) -> -22.7027 | J8: =_xlfn.XLOOKUP(B8,COORDENADAS!A:A,COORDENADAS!C:C) -> -43.4311 | L8: INFORMAL | M8: 1 | N8: OPERACIONAL | O8: 25cv | P8: 3550rpm | Q8: Weg | R8: 160M | S8: RJB-26491 | T8: 220V / 380V / 440V | U8: 60.9/35/2/30.4 | V8: 6209-ZZ-C3 | W8: 6209-ZZ-C3 | Y8: RJB-26976 | AH8: CONVENSIONAL | AP8: 430086325 | AQ8: 8552185 | BK8: PARTIDA DIRETA | BP8: SIM
A9: BELO HORIZONTE | B9: =_xlfn.XLOOKUP(A:A,'Dados Elevatórias'!D:D,'Dados Elevatórias'!B:B) -> PL-RJB-EAT0083 | C9: =_xlfn.XLOOKUP(B:B,'Dados Elevatórias'!B:B,'Dados Elevatórias'!C:C) -> EAT | D9: BAIXADA 2 | E9: R. Jequitia, 300 - Nova América, Nova Iguaçu - RJ, 26021-630 | F9: Nova América | G9: NOVA IGUAÇU | H9: =_xlfn.XLOOKUP(B:B,'Dados Elevatórias'!B:B,'Dados Elevatórias'!G:G) -> 26021-630 | I9: =_xlfn.XLOOKUP(B9,COORDENADAS!A:A,COORDENADAS!B:B) -> -22.7237 | J9: =_xlfn.XLOOKUP(B9,COORDENADAS!A:A,COORDENADAS!C:C) -> -43.4358 | L9: =_xlfn.XLOOKUP(A:A,'RELAÇÃO ANTIGA'!A:A,'RELAÇÃO ANTIGA'!J:J) -> FORMAL | M9: 1 | N9: OPERACIONAL | O9: 25cv | P9: 3500rpm | S9: RJB-05419 | Y9: RJB-05571 | Z9: WORTHINGTON | AA9: 2 | AC9: ABRIGADA | AF9: VERTICAL | AH9: INLINE | AN9: =_xlfn.XLOOKUP(A:A,'RELAÇÃO ANTIGA'!A:A,'RELAÇÃO ANTIGA'!AC:AC,X) -> 220V | AP9: 412787475 | AQ9: 5241353 | AR9: 0 | AS9: AGUA - BOOSTER - BELO HORIZONTE | AT9: AV BELO HORIZONTE SN FT840 | AU9: 100MM | AV9: 50MM | AW9: 0 | AX9: 0 | AY9: 0 | AZ9: 0 | BK9: INVERSOR DE FREQUÊNCIA | BP9: NÃO | BR9: 1 MCA | BS9: <1MCA | BT9: 0 | BU9: 0 | BV9: 0 | BW9: SIM | BY9: EM MARCHA | BZ9: 0 | CA9: 0 | CB9: 0 | CC9: 0 | CD9: Rua Angico - Rua Belo Horizonte - Rua Brasil - Rua Francisco Alves - Rua General Canraberi - Rua GonCalo Alves - Rua Iris - Rua JequitibA - Rua Leopoldo Machado - Rua Passos - Rua Saudade (parte)
A10: BOOSTER AUSTIN | B10: =_xlfn.XLOOKUP(A:A,'Dados Elevatórias'!D:D,'Dados Elevatórias'!B:B) -> PL-RJB-EAT0695 | C10: =_xlfn.XLOOKUP(B:B,'Dados Elevatórias'!B:B,'Dados Elevatórias'!C:C) -> EAT | D10: BAIXADA 2 | E10: R. Araicas, 27 - Austin, Nova Iguaçu - RJ, 26086-320 | F10: Largo dos peixes | G10: QUEIMADOS | H10: 26086-320 | I10: =_xlfn.XLOOKUP(B10,COORDENADAS!A:A,COORDENADAS!B:B) -> -22.7238 | J10: =_xlfn.XLOOKUP(B10,COORDENADAS!A:A,COORDENADAS!C:C) -> -43.53 | M10: 1 | N10: OPERACIONAL | O10: 400cv | P10: 1190rpm | Q10: WEG | R10: 315S/M | S10: RJB-12396 | T10: 440 | U10: 413 | X10: ZW | Y10: RJB-26840 | Z10: RP | AA10: 6 | AB10: 505mm | AC10: ABRIGADA | AD10: SIM | AE10: CONVENSIONAL | AF10: VERTICAL | AG10: FF | AH10: VERTICAL | AI10: 1908,6 m³/h | AJ10: 47,46 m | AN10: 13.8KV | AO10: 1000kvar | AP10: 0 | AQ10: 0 | AR10: 0 | AS10: 0 | AT10: 0 | BB10: 800A | BJ10: RJB-08633 | BK10: INVERSOR DE FREQUÊNCIA | BL10: WEG | BM10: CFW11 | BN10: 630A | BP10: SIM | BR10: 15 MCA | BS10: 10 MCA | BT10: 45 MCA | BU10: 0 | BV10: 0 | BY10: 0 | BZ10: 0 | CA10: 0 | CB10: 0 | CC10: 0 | CD10: 0
A11: BOOSTER AUSTIN | B11: =_xlfn.XLOOKUP(A:A,'Dados Elevatórias'!D:D,'Dados Elevatórias'!B:B) -> PL-RJB-EAT0695 | C11: =_xlfn.XLOOKUP(B:B,'Dados Elevatórias'!B:B,'Dados Elevatórias'!C:C) -> EAT | D11: BAIXADA 2 | E11: R. Araicas, 27 - Austin, Nova Iguaçu - RJ, 26086-320 | F11: Largo dos peixes | G11: QUEIMADOS | H11: 26086-320 | I11: =_xlfn.XLOOKUP(B11,COORDENADAS!A:A,COORDENADAS!B:B) -> -22.7238 | J11: =_xlfn.XLOOKUP(B11,COORDENADAS!A:A,COORDENADAS!C:C) -> -43.53 | M11: 2 | N11: OPERACIONAL | O11: 400cv | P11: 1190rpm | Q11: WEG | R11: 315S/M | S11: RJB-12370 | T11: 440 | U11: 413 | X11: ZW | Y11: RJB-12362 | Z11: RP | AA11: 6 | AB11: 505mm | AC11: CONTAINER | AD11: SIM | AE11: CONVENSIONAL | AF11: VERTICAL | AG11: FF | AH11: VERTICAL | AI11: 1908,6 m³/h | AJ11: 47,46 m | AN11: 13.8KV | AO11: 1000kvar | AP11: 0 | AQ11: 0 | AR11: 0 | AS11: 0 | AT11: 0 | BJ11: RJB-12356 | BK11: INVERSOR DE FREQUÊNCIA | BL11: WEG | BM11: CFW11 | BN11: 630A | BP11: SIM | BR11: 15 MCA | BS11: 10 MCA | BT11: 45 MCA | BU11: 0 | BV11: 0 | BY11: 0 | BZ11: 0 | CA11: 0 | CB11: 0 | CC11: 0 | CD11: 0
A12: BOOSTER AUSTIN | B12: =_xlfn.XLOOKUP(A:A,'Dados Elevatórias'!D:D,'Dados Elevatórias'!B:B) -> PL-RJB-EAT0695 | C12: =_xlfn.XLOOKUP(B:B,'Dados Elevatórias'!B:B,'Dados Elevatórias'!C:C) -> EAT | D12: BAIXADA 2 | E12: R. Araicas, 27 - Austin, Nova Iguaçu - RJ, 26086-320 | F12: Largo dos peixes | G12: QUEIMADOS | H12: 26086-320 | I12: =_xlfn.XLOOKUP(B12,COORDENADAS!A:A,COORDENADAS!B:B) -> -22.7238 | J12: =_xlfn.XLOOKUP(B12,COORDENADAS!A:A,COORDENADAS!C:C) -> -43.53 | M12: 3 | N12: OPERACIONAL | O12: 400cv | P12: 1190rpm | Q12: WEG | R12: 315S/M | S12: RJB-12392 | T12: 440 | U12: 413 | X12: ZW | Y12: RJB-12376 | Z12: RP | AA12: 6 | AB12: 505mm | AC12: CONTAINER | AD12: SIM | AE12: CONVENSIONAL | AF12: VERTICAL | AG12: FF | AH12: VERTICAL | AI12: 1908,6 m³/h | AJ12: 47,46 m | AN12: 13.8KV | AO12: 1000kvar | AP12: 0 | AQ12: 0 | AR12: 0 | AS12: 0 | AT12: 0 | BJ12: RJB-08630 | BK12: INVERSOR DE FREQUÊNCIA | BL12: WEG | BM12: CFW11 | BN12: 630A | BO12: RJB-30634 | BP12: SIM | BR12: 15 MCA | BS12: 10 MCA | BT12: 45 MCA | BU12: 0 | BV12: 0 | BY12: 0 | BZ12: 0 | CA12: 0 | CB12: 0 | CC12: 0 | CD12: 0
A13: BOOSTER BRASÍLIA | B13: =_xlfn.XLOOKUP(A:A,'Dados Elevatórias'!D:D,'Dados Elevatórias'!B:B) -> PL-RJB-EAT1005 | C13: =_xlfn.XLOOKUP(B:B,'Dados Elevatórias'!B:B,'Dados Elevatórias'!C:C) -> EAT | D13: BAIXADA 2 | E13: R. Prof. Venina Correa Torres, 23 - Centro, Nova Iguaçu - RJ, 26220-100 | F13: Centro | G13: NOVA IGUAÇU | H13: =_xlfn.XLOOKUP(B:B,'Dados Elevatórias'!B:B,'Dados Elevatórias'!G:G) -> 26220-100 | I13: =_xlfn.XLOOKUP(B13,COORDENADAS!A:A,COORDENADAS!B:B) -> -22.7596 | J13: =_xlfn.XLOOKUP(B13,COORDENADAS!A:A,COORDENADAS!C:C) -> -43.4455 | L13: FORMAL | M13: 1 | N13: OPERACIONAL | O13: 100cv | P13: 1783 rpm | Q13: WEG PREMIUM W22 | R13: 250S/M | S13: RJB-23564 | T13: 220V / 380V / 440V | U13: 246A / 142A / 123A | V13: 6314-C3 | W13: 6314-C3 | X13: OMEGA 150-290A | Y13: RJB-23599 | Z13: KSB | AA13: 7 | AB13: 1780mm | AC13: ABRIGADA | AF13: HORIZONTAL | AH13: HORIZONTAL | AI13: 504,0M³/H | AJ13: 33,0MCA | AN13: =_xlfn.XLOOKUP(A:A,'RELAÇÃO ANTIGA'!A:A,'RELAÇÃO ANTIGA'!AC:AC,X) -> 220v | AP13: 0 | AQ13: 0 | AR13: 0 | AS13: 0 | AT13: 0 | BK13: INVERSOR DE FREQUÊNCIA | BP13: SIM | BR13: 6 mca | BS13: 4 mca | BT13: 100 MCA | BU13: 0 | BV13: 0 | BY13: 0 | BZ13: 0 | CA13: 0 | CB13: 0 | CC13: 0 | CD13: 0
A14: BOOSTER BRASÍLIA | B14: =_xlfn.XLOOKUP(A:A,'Dados Elevatórias'!D:D,'Dados Elevatórias'!B:B) -> PL-RJB-EAT1005 | C14: =_xlfn.XLOOKUP(B:B,'Dados Elevatórias'!B:B,'Dados Elevatórias'!C:C) -> EAT | D14: BAIXADA 2 | E14: R. Prof. Venina Correa Torres, 23 - Centro, Nova Iguaçu - RJ, 26220-100 | F14: Centro | G14: NOVA IGUAÇU | H14: =_xlfn.XLOOKUP(B:B,'Dados Elevatórias'!B:B,'Dados Elevatórias'!G:G) -> 26220-100 | I14: =_xlfn.XLOOKUP(B14,COORDENADAS!A:A,COORDENADAS!B:B) -> -22.7596 | J14: =_xlfn.XLOOKUP(B14,COORDENADAS!A:A,COORDENADAS!C:C) -> -43.4455 | L14: FORMAL | M14: 2 | N14: OPERACIONAL | O14: 100cv | P14: 1783 rpm | Q14: WEG PREMIUM W22 | R14: 250S/M | S14: RJB-23528 | T14: 220V / 380V / 440V | U14: 246A / 142A / 123A | V14: 6314-C3 | W14: 6314-C3 | X14: OMEGA 150-290A | Y14: RJB-23577 | Z14: KSB | AA14: 7 | AB14: 1780mm | AC14: ABRIGADA | AF14: HORIZONTAL | AH14: HORIZONTAL | AI14: 504,0M³/H | AJ14: 33,0MCA | AN14: =_xlfn.XLOOKUP(A:A,'RELAÇÃO ANTIGA'!A:A,'RELAÇÃO ANTIGA'!AC:AC,X) -> 220v | AP14: 0 | AQ14: 0 | AR14: 0 | AS14: 0 | AT14: 0 | BK14: INVERSOR DE FREQUÊNCIA | BP14: SIM | BR14: 6 mca | BS14: 4 mca | BT14: 100 MCA | BU14: 0 | BV14: 0 | BY14: 0 | BZ14: 0 | CA14: 0 | CB14: 0 | CC14: 0 | CD14: 0
A15: BOOSTER BRASÍLIA | B15: =_xlfn.XLOOKUP(A:A,'Dados Elevatórias'!D:D,'Dados Elevatórias'!B:B) -> PL-RJB-EAT1005 | C15: =_xlfn.XLOOKUP(B:B,'Dados Elevatórias'!B:B,'Dados Elevatórias'!C:C) -> EAT | D15: BAIXADA 2 | E15: R. Prof. Venina Correa Torres, 23 - Centro, Nova Iguaçu - RJ, 26220-100 | F15: Centro | G15: NOVA IGUAÇU | H15: =_xlfn.XLOOKUP(B:B,'Dados Elevatórias'!B:B,'Dados Elevatórias'!G:G) -> 26220-100 | I15: =_xlfn.XLOOKUP(B15,COORDENADAS!A:A,COORDENADAS!B:B) -> -22.7596 | J15: =_xlfn.XLOOKUP(B15,COORDENADAS!A:A,COORDENADAS!C:C) -> -43.4455 | L15: FORMAL | M15: 3 | N15: OPERACIONAL | O15: 100cv | P15: 1783 rpm | Q15: WEG PREMIUM W22 | R15: 250S/M | S15: RJB-23592 | T15: 220V / 380V / 440V | U15: 246A / 142A / 123A | V15: 6314-C3 | W15: 6314-C3 | X15: OMEGA 150-290A | Y15: RJB-23551 | Z15: KSB | AA15: 7 | AB15: 1780mm | AC15: ABRIGADA | AF15: HORIZONTAL | AH15: HORIZONTAL | AI15: 504,0M³/H | AJ15: 33,0MCA | AN15: =_xlfn.XLOOKUP(A:A,'RELAÇÃO ANTIGA'!A:A,'RELAÇÃO ANTIGA'!AC:AC,X) -> 220v | AP15: 0 | AQ15: 0 | AR15: 0 | AS15: 0 | AT15: 0 | BK15: INVERSOR DE FREQUÊNCIA | BP15: SIM | BR15: 6 mca | BS15: 4 mca | BT15: 100 MCA | BU15: 0 | BV15: 0 | BY15: 0 | BZ15: 0 | CA15: 0 | CB15: 0 | CC15: 0 | CD15: 0
A16: BOOSTER CABUÇU ALTO | B16: =_xlfn.XLOOKUP(A:A,'Dados Elevatórias'!D:D,'Dados Elevatórias'!B:B) -> PL-RJB-EAT0689 | C16: =_xlfn.XLOOKUP(B:B,'Dados Elevatórias'!B:B,'Dados Elevatórias'!C:C) -> EAT | D16: BAIXADA 2 | E16: R. José Cabral, 448 - Cabuçu, Nova Iguaçu - RJ, 26290-048 | F16: Cabuçu | G16: NOVA IGUAÇU | H16: =_xlfn.XLOOKUP(B:B,'Dados Elevatórias'!B:B,'Dados Elevatórias'!G:G) -> 26290-048 | I16: =_xlfn.XLOOKUP(B16,COORDENADAS!A:A,COORDENADAS!B:B) -> -22.764 | J16: =_xlfn.XLOOKUP(B16,COORDENADAS!A:A,COORDENADAS!C:C) -> -43.537 | L16: FORMAL | M16: 1 | N16: OPERACIONAL | O16: 50CV | P16: 1770rpm | Q16: WEG | R16: 200L | S16: RJB-06856 | T16: 220V / 380V / 440V | U16: 122/70.6/61.0 | V16: 6312-C3 | W16: 6212-Z-C3 | X16: OMEGA 150-290A | Y16: RJB-06880 | Z16: KSB | AA16: 4 | AB16: 247mm | AC16: ABRIGADA | AD16: NÃO | AF16: HORIZONTAL | AH16: HORIZONTAL | AI16: 360m³/h | AJ16: 26.1MCA | AN16: 440V | AP16: 430053078 | AQ16: 7891998 | AR16: 0 | AS16: AGUA - ELEV - CABUCU ALTO G1 | AT16: RUA JOSE CABRAL S/NJOSE CABRAL S/N | BK16: INVERSOR DE FREQUÊNCIA | BP16: SIM | BR16: 16 MCA | BS16: 14 MCA | BT16: 45 MCA | BU16: 0 | BV16: 0 | BY16: 0 | BZ16: 0 | CA16: 0 | CB16: 0 | CC16: 0 | CD16: 0
A17: BOOSTER CABUÇU ALTO | B17: =_xlfn.XLOOKUP(A:A,'Dados Elevatórias'!D:D,'Dados Elevatórias'!B:B) -> PL-RJB-EAT0689 | C17: =_xlfn.XLOOKUP(B:B,'Dados Elevatórias'!B:B,'Dados Elevatórias'!C:C) -> EAT | D17: BAIXADA 2 | E17: R. José Cabral, 448 - Cabuçu, Nova Iguaçu - RJ, 26290-048 | F17: Cabuçu | G17: NOVA IGUAÇU | H17: =_xlfn.XLOOKUP(B:B,'Dados Elevatórias'!B:B,'Dados Elevatórias'!G:G) -> 26290-048 | I17: =_xlfn.XLOOKUP(B17,COORDENADAS!A:A,COORDENADAS!B:B) -> -22.764 | J17: =_xlfn.XLOOKUP(B17,COORDENADAS!A:A,COORDENADAS!C:C) -> -43.537 | L17: FORMAL | M17: 2 | N17: OPERACIONAL | O17: 50CV | P17: 1770rpm | Q17: WEG | R17: 200L | S17: RJB-06865 | T17: 220V / 380V / 440V | U17: 122/70.6/61.0 | V17: 6312-C3 | W17: 6212-Z-C3 | X17: OMEGA 150-290A | Y17: SEM INFRA | Z17: KSB | AA17: 4 | AB17: 247mm | AC17: ABRIGADA | AD17: NÃO | AF17: HORIZONTAL | AH17: HORIZONTAL | AI17: 360m³/h | AJ17: 26.1MCA | AN17: 440V | AP17: 430053078 | AQ17: 7891998 | AR17: 0 | AS17: AGUA - ELEV - CABUCU ALTO G1 | AT17: RUA JOSE CABRAL S/NJOSE CABRAL S/N | BK17: INVERSOR DE FREQUÊNCIA | BP17: SIM | BR17: 16 MCA | BS17: 14 MCA | BT17: 45 MCA | BU17: 0 | BV17: 0 | BY17: 0 | BZ17: 0 | CA17: 0 | CB17: 0 | CC17: 0 | CD17: 0
A18: BOOSTER CABUÇU ALTO | B18: =_xlfn.XLOOKUP(A:A,'Dados Elevatórias'!D:D,'Dados Elevatórias'!B:B) -> PL-RJB-EAT0689 | C18: =_xlfn.XLOOKUP(B:B,'Dados Elevatórias'!B:B,'Dados Elevatórias'!C:C) -> EAT | D18: BAIXADA 2 | E18: R. José Cabral, 448 - Cabuçu, Nova Iguaçu - RJ, 26290-048 | F18: Cabuçu | G18: NOVA IGUAÇU | H18: =_xlfn.XLOOKUP(B:B,'Dados Elevatórias'!B:B,'Dados Elevatórias'!G:G) -> 26290-048 | I18: =_xlfn.XLOOKUP(B18,COORDENADAS!A:A,COORDENADAS!B:B) -> -22.764 | J18: =_xlfn.XLOOKUP(B18,COORDENADAS!A:A,COORDENADAS!C:C) -> -43.537 | L18: FORMAL | M18: 3 | N18: RESERVA | O18: 50CV | P18: 1770rpm | Q18: WEG | R18: 200L | S18: RJB-06888 | T18: 220V / 380V / 440V | U18: 122/70.6/61.0 | V18: 6312-C3 | W18: 6212-Z-C3 | X18: OMEGA 150-290A | Y18: RJB-06864 | Z18: KSB | AA18: 4 | AB18: 247mm | AC18: ABRIGADA | AD18: NÃO | AF18: HORIZONTAL | AH18: HORIZONTAL | AI18: 360m³/h | AJ18: 26.1MCA | AN18: 440V | AP18: 430053078 | AQ18: 7891998 | AR18: 0 | AS18: AGUA - ELEV - CABUCU ALTO G1 | AT18: RUA JOSE CABRAL S/NJOSE CABRAL S/N | BK18: INVERSOR DE FREQUÊNCIA | BP18: SIM | BR18: 16 MCA | BS18: 14 MCA | BT18: 45 MCA | BU18: 0 | BV18: 0 | BY18: 0 | BZ18: 0 | CA18: 0 | CB18: 0 | CC18: 0 | CD18: 0
A19: BOOSTER ENGENHEIRO PEDREIRA | B19: =_xlfn.XLOOKUP(A:A,'Dados Elevatórias'!D:D,'Dados Elevatórias'!B:B) -> PL-RJB-EAT0122 | C19: =_xlfn.XLOOKUP(B:B,'Dados Elevatórias'!B:B,'Dados Elevatórias'!C:C) -> EAT | D19: BAIXADA 2 | E19: Cidade Jardim Marajoara, Japeri - RJ, 26420-243 | F19: Jardim Marajoara | G19: JAPERI | H19: =_xlfn.XLOOKUP(B:B,'Dados Elevatórias'!B:B,'Dados Elevatórias'!G:G) -> 26420-243 | I19: =_xlfn.XLOOKUP(B19,COORDENADAS!A:A,COORDENADAS!B:B) -> -22.7075 | J19: =_xlfn.XLOOKUP(B19,COORDENADAS!A:A,COORDENADAS!C:C) -> -43.6287 | M19: 1 | N19: OPERACIONAL | O19: 200cv | P19: 1790rpm | Q19: W22 PREMIUM | R19: 315S/M | S19: RJB-20410 | T19: 220V / 380V / 440V | U19: 476 / 278 / 238A | V19: 6319-C3 | W19: 6316-C3 | X19: OMEGA 150-460B | Y19: RJB-20411 | Z19: KSB | AA19: 4 | AC19: ABRIGADA | AD19: NÃO | AF19: HORIZONTAL | AH19: HORIZONTAL | AI19: 360 m³/h | AJ19: 110MCA | AL19: placa | AN19: 220V | AO19: 250 | AP19: 0 | AQ19: 0 | AR19: 0 | AS19: 0 | AT19: 0 | BK19: INVERSOR DE FREQUÊNCIA | BL19: POWER ELETRONICS | BM19: SD750 | BN19: 250KW | BO19: RJB-18851 | BP19: SIM | BR19: 7 MCA | BS19: 5 MCA | BT19: 99.9 | BU19: 0 | BV19: 0 | BY19: 0 | BZ19: 0 | CA19: 0 | CB19: 0 | CC19: 0 | CD19: 0
A20: BOOSTER ENGENHEIRO PEDREIRA | B20: =_xlfn.XLOOKUP(A:A,'Dados Elevatórias'!D:D,'Dados Elevatórias'!B:B) -> PL-RJB-EAT0122 | C20: =_xlfn.XLOOKUP(B:B,'Dados Elevatórias'!B:B,'Dados Elevatórias'!C:C) -> EAT | D20: BAIXADA 2 | E20: Cidade Jardim Marajoara, Japeri - RJ, 26420-243 | F20: Jardim Marajoara | G20: JAPERI | H20: =_xlfn.XLOOKUP(B:B,'Dados Elevatórias'!B:B,'Dados Elevatórias'!G:G) -> 26420-243 | I20: =_xlfn.XLOOKUP(B20,COORDENADAS!A:A,COORDENADAS!B:B) -> -22.7075 | J20: =_xlfn.XLOOKUP(B20,COORDENADAS!A:A,COORDENADAS!C:C) -> -43.6287 | M20: 2 | N20: OPERACIONAL | O20: 200cv | P20: 1790rpm | Q20: W22 PREMIUM | R20: 315S/M | S20: RJB-20459 | T20: 220V / 380V / 440V | U20: 476 / 276 / 238A | V20: 6319-C3 | W20: 6318-C3 | X20: OMEGA 150-460 B | Y20: RJB-20499 | Z20: KSB | AA20: 4 | AC20: ABRIGADA | AD20: NÃO | AF20: HORIZONTAL | AH20: HORIZONTAL | AI20: 360 m³/h | AJ20: 110MCA | AL20: placa | AN20: 220V | AO20: 250 | AP20: 0 | AQ20: 0 | AR20: 0 | AS20: 0 | AT20: 0 | BK20: INVERSOR DE FREQUÊNCIA | BL20: POWER ELETRONICS | BM20: SD750 | BN20: 400KW | BO20: RJB-26831 | BP20: SIM | BR20: 7 MCA | BS20: 5 MCA | BT20: 99.9 | BU20: 0 | BV20: 0 | BY20: 0 | BZ20: 0 | CA20: 0 | CB20: 0 | CC20: 0 | CD20: 0
A21: BOOSTER JK | B21: =_xlfn.XLOOKUP(A:A,'Dados Elevatórias'!D:D,'Dados Elevatórias'!B:B) -> PL-RJB-EAT0746 | C21: =_xlfn.XLOOKUP(B:B,'Dados Elevatórias'!B:B,'Dados Elevatórias'!C:C) -> EAT | D21: BAIXADA 2 | E21: R. da Cascata, 60 - Pres. Juscelino, Mesquita - RJ, 26557-700 | F21: Pres. Juscelino | G21: MESQUITA | H21: =_xlfn.XLOOKUP(B:B,'Dados Elevatórias'!B:B,'Dados Elevatórias'!G:G) -> 26557-700 | I21: =_xlfn.XLOOKUP(B21,COORDENADAS!A:A,COORDENADAS!B:B) -> -22.7702 | J21: =_xlfn.XLOOKUP(B21,COORDENADAS!A:A,COORDENADAS!C:C) -> -43.4356 | M21: 1 | N21: OPERACIONAL | O21: 450CV | P21: 1793rpm | Q21: WEG | R21: 355.4L | S21: RJB-02539 | T21: 440 | U21: 515 | X21: RDL 250-400 A | Y21: RJB-07474 | Z21: KSB | AA21: 4 | AC21: ABRIGADA | AD21: NÃO | AF21: HORIZONTAL | AH21: HORIZONTAL | AI21: 1070M3/H | AJ21: 85MCA | AN21: 440V | AO21: 1000kvar | AP21: 0 | AQ21: 0 | AR21: 0 | AS21: 0 | AT21: 0 | BK21: INVERSOR DE FREQUÊNCIA | BL21: POWER ELETRONICS | BM21: SD750 | BP21: SIM | BR21: 2 | BS21: 2 | BT21: 0 | BU21: 0 | BV21: 0 | BY21: 0 | BZ21: 0 | CA21: 0 | CB21: 0 | CC21: 0 | CD21: 0
A22: BOOSTER JK | B22: =_xlfn.XLOOKUP(A:A,'Dados Elevatórias'!D:D,'Dados Elevatórias'!B:B) -> PL-RJB-EAT0746 | C22: =_xlfn.XLOOKUP(B:B,'Dados Elevatórias'!B:B,'Dados Elevatórias'!C:C) -> EAT | D22: BAIXADA 2 | E22: R. da Cascata, 60 - Pres. Juscelino, Mesquita - RJ, 26557-700 | F22: Pres. Juscelino | G22: MESQUITA | H22: =_xlfn.XLOOKUP(B:B,'Dados Elevatórias'!B:B,'Dados Elevatórias'!G:G) -> 26557-700 | I22: =_xlfn.XLOOKUP(B22,COORDENADAS!A:A,COORDENADAS!B:B) -> -22.7702 | J22: =_xlfn.XLOOKUP(B22,COORDENADAS!A:A,COORDENADAS!C:C) -> -43.4356 | M22: 2 | N22: OPERACIONAL | O22: 450CV | P22: 1793rpm | Q22: WEG | R22: 355M | S22: RJB-07405 | T22: 440 | U22: 515 | X22: RDL 250-400 A | Y22: RJB-07403 | Z22: KSB | AA22: 4 | AC22: ABRIGADA | AD22: NÃO | AF22: HORIZONTAL | AH22: HORIZONTAL | AI22: 1070M3/H | AJ22: 85MCA | AN22: 440V | AO22: 1000kvar | AP22: 0 | AQ22: 0 | AR22: 0 | AS22: 0 | AT22: 0 | BK22: INVERSOR DE FREQUÊNCIA | BL22: POWER ELETRONICS | BM22: SD750 | BP22: SIM | BR22: 2 | BS22: 2 | BT22: 0 | BU22: 0 | BV22: 0 | BY22: 0 | BZ22: 0 | CA22: 0 | CB22: 0 | CC22: 0 | CD22: 0
A23: BOOSTER JK | B23: =_xlfn.XLOOKUP(A:A,'Dados Elevatórias'!D:D,'Dados Elevatórias'!B:B) -> PL-RJB-EAT0746 | C23: =_xlfn.XLOOKUP(B:B,'Dados Elevatórias'!B:B,'Dados Elevatórias'!C:C) -> EAT | D23: BAIXADA 2 | E23: R. da Cascata, 60 - Pres. Juscelino, Mesquita - RJ, 26557-700 | F23: Pres. Juscelino | G23: MESQUITA | H23: =_xlfn.XLOOKUP(B:B,'Dados Elevatórias'!B:B,'Dados Elevatórias'!G:G) -> 26557-700 | I23: =_xlfn.XLOOKUP(B23,COORDENADAS!A:A,COORDENADAS!B:B) -> -22.7702 | J23: =_xlfn.XLOOKUP(B23,COORDENADAS!A:A,COORDENADAS!C:C) -> -43.4356 | M23: 3 | N23: OPERACIONAL | O23: 250CV | P23: 1790rpm | Q23: WEG | S23: RJB-03614 | T23: 220 / 380 / 440 | U23: 584 / 338 / 292 | Y23: RJB-26813 | Z23: WHORTHINGTON | AA23: 4 | AC23: ABRIGADA | AD23: NÃO | AF23: HORIZONTAL | AH23: HORIZONTAL | AN23: 440V | AO23: 1000kvar | AP23: 0 | AQ23: 0 | AR23: 0 | AS23: 0 | AT23: 0 | BK23: INVERSOR DE FREQUÊNCIA | BL23: POWER ELETRONICS | BM23: SD75070055 | BN23: 315kW | BO23: RJB-20155 | BP23: SIM | BR23: 2 | BS23: 2 | BT23: 0 | BU23: 0 | BV23: 0 | BY23: 0 | BZ23: 0 | CA23: 0 | CB23: 0 | CC23: 0 | CD23: 0
A24: BOOSTER JK | B24: =_xlfn.XLOOKUP(A:A,'Dados Elevatórias'!D:D,'Dados Elevatórias'!B:B) -> PL-RJB-EAT0746 | C24: =_xlfn.XLOOKUP(B:B,'Dados Elevatórias'!B:B,'Dados Elevatórias'!C:C) -> EAT | D24: BAIXADA 2 | E24: R. da Cascata, 60 - Pres. Juscelino, Mesquita - RJ, 26557-700 | F24: Pres. Juscelino | G24: MESQUITA | H24: =_xlfn.XLOOKUP(B:B,'Dados Elevatórias'!B:B,'Dados Elevatórias'!G:G) -> 26557-700 | I24: =_xlfn.XLOOKUP(B24,COORDENADAS!A:A,COORDENADAS!B:B) -> -22.7702 | J24: =_xlfn.XLOOKUP(B24,COORDENADAS!A:A,COORDENADAS!C:C) -> -43.4356 | M24: 4 | N24: OPERACIONAL | O24: 250CV | P24: 1793 a 1850 rpm | Q24: WEG | S24: RJB-18296 | T24: 220V / 380V / 440V | Y24: RJB-07453 | Z24: RJA-08472 | AA24: 4 | AC24: ABRIGADA | AD24: NÃO | AF24: HORIZONTAL | AH24: HORIZONTAL | AN24: 440V | AO24: 1000kvar | AP24: 0 | AQ24: 0 | AR24: 0 | AS24: 0 | AT24: 0 | BK24: INVERSOR DE FREQUÊNCIA | BL24: POWER ELETRONICS | BM24: SD75032055 | BN24: 320A | BO24: RJB-22128 | BP24: SIM | BR24: 2 | BS24: 2 | BT24: 0 | BU24: 0 | BV24: 0 | BY24: 0 | BZ24: 0 | CA24: 0 | CB24: 0 | CC24: 0 | CD24: 0
A25: BOOSTER POSSE | B25: =_xlfn.XLOOKUP(A:A,'Dados Elevatórias'!D:D,'Dados Elevatórias'!B:B) -> PL-RJB-EAT0042 | C25: =_xlfn.XLOOKUP(B:B,'Dados Elevatórias'!B:B,'Dados Elevatórias'!C:C) -> EAT | D25: BAIXADA 2 | E25: Estrada velha de Iguaçu, 812 - Miguel Couto , Belford Roxo - RJ | F25: Miguel Couto | G25: NOVA IGUAÇU | H25: 26145-420 | I25: =_xlfn.XLOOKUP(B25,COORDENADAS!A:A,COORDENADAS!B:B) -> -22.7096 | J25: =_xlfn.XLOOKUP(B25,COORDENADAS!A:A,COORDENADAS!C:C) -> -43.4287 | L25: FORMAL | M25: 1 | N25: OPERACIONAL | O25: 175cv | P25: 1791rpm | Q25: WEG | S25: VERIFICAR | T25: 220 / 380 / 440 | U25: 424 / 245 / 212 | X25: OMEGA 150-460 B | Y25: VERIFICAR | Z25: KSB | AA25: 4 | AB25: Sem Dados | AC25: ABRIGADA | AD25: NÃO | AE25: CONVENSIONAL | AF25: HORIZONTAL | AG25: CONVENSIONAL | AH25: HORIZONTAL | AI25: 450 M³/H | AJ25: 82MCA | AN25: 440V | AO25: 750kva | AP25: 0 | AQ25: 0 | AR25: 0 | AS25: 0 | AT25: 0 | BK25: INVERSOR DE FREQUÊNCIA | BL25: ABB | BM25: ACQ580-430A | BN25: 430A | BP25: SIM | BR25: 4 mca | BS25: 3mca | BT25: 80MCA | BU25: 0 | BV25: 0 | BY25: 0 | BZ25: 0 | CA25: 0 | CB25: 0 | CC25: 0 | CD25: 0
A26: BOOSTER POSSE | B26: =_xlfn.XLOOKUP(A:A,'Dados Elevatórias'!D:D,'Dados Elevatórias'!B:B) -> PL-RJB-EAT0042 | C26: =_xlfn.XLOOKUP(B:B,'Dados Elevatórias'!B:B,'Dados Elevatórias'!C:C) -> EAT | D26: BAIXADA 2 | E26: Estrada velha de Iguaçu, 812 - Miguel Couto , Belford Roxo - RJ | F26: Miguel Couto | G26: NOVA IGUAÇU | H26: 26145-420 | I26: =_xlfn.XLOOKUP(B26,COORDENADAS!A:A,COORDENADAS!B:B) -> -22.7096 | J26: =_xlfn.XLOOKUP(B26,COORDENADAS!A:A,COORDENADAS!C:C) -> -43.4287 | L26: FORMAL | M26: 2 | N26: OPERACIONAL | O26: 175cv | P26: 1791rpm | Q26: WEG | S26: RJB-23844 | T26: 220 / 380 / 440 | U26: 424 / 245 / 212 | X26: OMEGA 150-460 B | Y26: RJB-23847 | Z26: KSB | AA26: 4 | AB26: Sem Dados | AC26: ABRIGADA | AD26: NÃO | AE26: CONVENSIONAL | AF26: HORIZONTAL | AG26: CONVENSIONAL | AH26: HORIZONTAL | AI26: 450 M³/H | AJ26: 82MCA | AN26: 440V | AO26: 750kva | AP26: 0 | AQ26: 0 | AR26: 0 | AS26: 0 | AT26: 0 | BJ26: RJB-23834 | BK26: INVERSOR DE FREQUÊNCIA | BL26: ABB | BM26: ACQ580-430A | BN26: 430A | BO26: RJB-23834 | BP26: SIM | BR26: 6 mca | BS26: 3mca | BT26: 80MCA | BU26: 0 | BV26: 0 | BY26: 0 | BZ26: 0 | CA26: 0 | CB26: 0 | CC26: 0 | CD26: 0
A27: BOOSTER POSSE | B27: =_xlfn.XLOOKUP(A:A,'Dados Elevatórias'!D:D,'Dados Elevatórias'!B:B) -> PL-RJB-EAT0042 | C27: =_xlfn.XLOOKUP(B:B,'Dados Elevatórias'!B:B,'Dados Elevatórias'!C:C) -> EAT | D27: BAIXADA 2 | E27: Estrada velha de Iguaçu, 812 - Miguel Couto , Belford Roxo - RJ | F27: Miguel Couto | G27: NOVA IGUAÇU | H27: 26145-420 | I27: =_xlfn.XLOOKUP(B27,COORDENADAS!A:A,COORDENADAS!B:B) -> -22.7096 | J27: =_xlfn.XLOOKUP(B27,COORDENADAS!A:A,COORDENADAS!C:C) -> -43.4287 | L27: FORMAL | M27: 3 | N27: OPERACIONAL | O27: 175cv | P27: 1791rpm | Q27: WEG | S27: VERIFICAR | T27: 220 / 380 / 440 | U27: 424 / 245 / 212 | X27: OMEGA 150-460 B | Y27: RJB-26816 | Z27: KSB | AA27: 4 | AB27: Sem Dados | AC27: ABRIGADA | AD27: NÃO | AE27: CONVENSIONAL | AF27: HORIZONTAL | AG27: CONVENSIONAL | AH27: HORIZONTAL | AI27: 450 M³/H | AJ27: 82MCA | AN27: 440V | AO27: 750kva | AP27: 0 | AQ27: 0 | AR27: 0 | AS27: 0 | AT27: 0 | BJ27: RJB-23424 | BK27: INVERSOR DE FREQUÊNCIA | BL27: POWER ELETRONICS | BM27: SD 750 | BO27: RJB-23424 | BP27: SIM | BR27: 8 mca | BS27: 3mca | BT27: 80MCA | BU27: 0 | BV27: 0 | BY27: 0 | BZ27: 0 | CA27: 0 | CB27: 0 | CC27: 0 | CD27: 0
A28: BOOSTER POSSE | B28: =_xlfn.XLOOKUP(A:A,'Dados Elevatórias'!D:D,'Dados Elevatórias'!B:B) -> PL-RJB-EAT0042 | C28: =_xlfn.XLOOKUP(B:B,'Dados Elevatórias'!B:B,'Dados Elevatórias'!C:C) -> EAT | D28: BAIXADA 2 | E28: Estrada velha de Iguaçu, 812 - Miguel Couto , Belford Roxo - RJ | F28: Miguel Couto | G28: NOVA IGUAÇU | H28: 26145-420 | I28: =_xlfn.XLOOKUP(B28,COORDENADAS!A:A,COORDENADAS!B:B) -> -22.7096 | J28: =_xlfn.XLOOKUP(B28,COORDENADAS!A:A,COORDENADAS!C:C) -> -43.4287 | L28: FORMAL | M28: 4 | N28: OPERACIONAL | O28: 175cv | P28: 1791rpm | Q28: WEG | S28: VERIFICAR | T28: 220 / 380 / 440 | U28: 424 / 245 / 212 | X28: OMEGA 150-460 B | Y28: VERIFICAR | Z28: KSB | AA28: 4 | AB28: Sem Dados | AC28: ABRIGADA | AD28: NÃO | AE28: CONVENSIONAL | AF28: HORIZONTAL | AG28: CONVENSIONAL | AH28: HORIZONTAL | AI28: 450 M³/H | AJ28: 82MCA | AN28: 440V | AO28: 750kva | AP28: 0 | AQ28: 0 | AR28: 0 | AS28: 0 | AT28: 0 | BK28: INVERSOR DE FREQUÊNCIA | BL28: DANFOSS | BN28: MANUTENÇÃO | BP28: SIM | BS28: 3mca | BT28: 80MCA | BU28: 0 | BV28: 0 | BY28: 0 | BZ28: 0 | CA28: 0 | CB28: 0 | CC28: 0 | CD28: 0
A29: BURITI | B29: =_xlfn.XLOOKUP(A:A,'Dados Elevatórias'!D:D,'Dados Elevatórias'!B:B) -> PL-RJB-EAT0684 | C29: =_xlfn.XLOOKUP(B:B,'Dados Elevatórias'!B:B,'Dados Elevatórias'!C:C) -> EAT | D29: BAIXADA 2 | E29: R. Freitas De Aguiar, 13 - Eucalipto, Japeri - RJ, 26453-325 | F29: Eucalipto | G29: JAPERI | H29: =_xlfn.XLOOKUP(B:B,'Dados Elevatórias'!B:B,'Dados Elevatórias'!G:G) -> 26453-325 | I29: =_xlfn.XLOOKUP(B29,COORDENADAS!A:A,COORDENADAS!B:B) -> -22.6731 | J29: =_xlfn.XLOOKUP(B29,COORDENADAS!A:A,COORDENADAS!C:C) -> -43.6112 | L29: =_xlfn.XLOOKUP(A:A,'RELAÇÃO ANTIGA'!A:A,'RELAÇÃO ANTIGA'!J:J) -> INFORMAL | M29: 1 | N29: OPERACIONAL | O29: 7.5 cv | S29: RJB-17524 | V29: / | X29: 050-032-160 | Y29: RJB-17563 | Z29: SCHNEIDER | AA29: 2 | AB29: 150mm | AC29: ABRIGADA | AF29: HORIZONTAL | AH29: CONVENSIONAL | AI29: 41m3/h | AJ29: 46mca | AN29: =_xlfn.XLOOKUP(A:A,'RELAÇÃO ANTIGA'!A:A,'RELAÇÃO ANTIGA'!AC:AC,X) -> 220V | AP29: 0 | AQ29: 0 | AR29: 0 | AS29: 0 | AT29: 0 | AU29: 2POL | AV29: 1.1/4 | AW29: 0 | AX29: 0 | AY29: 0 | AZ29: 0 | BJ29: RJB-01927 | BK29: PARTIDA DIRETA | BP29: NÃO | BR29: 0 | BS29: 0 | BT29: 0 | BU29: X | BV29: 0 | BY29: EM MARCHA | BZ29: 0 | CA29: 0 | CB29: 0 | CC29: 0 | CD29: 0
A30: CAIÇARA | B30: =_xlfn.XLOOKUP(A:A,'Dados Elevatórias'!D:D,'Dados Elevatórias'!B:B) -> PL-RJB-EAT0048 | C30: =_xlfn.XLOOKUP(B:B,'Dados Elevatórias'!B:B,'Dados Elevatórias'!C:C) -> EAT | D30: BAIXADA 2 | E30: Tv. Benjamim Chanbarelli, 30 - Caonze, Nova Iguaçu - RJ, 26250-120 | F30: Jardim da Posse | G30: NOVA IGUAÇU | H30: =_xlfn.XLOOKUP(B:B,'Dados Elevatórias'!B:B,'Dados Elevatórias'!G:G) -> 26021-072 | I30: =_xlfn.XLOOKUP(B30,COORDENADAS!A:A,COORDENADAS!B:B) -> -22.7284 | J30: =_xlfn.XLOOKUP(B30,COORDENADAS!A:A,COORDENADAS!C:C) -> -43.4433 | L30: =_xlfn.XLOOKUP(A:A,'RELAÇÃO ANTIGA'!A:A,'RELAÇÃO ANTIGA'!J:J) -> FORMAL | M30: 1 | N30: OPERACIONAL | O30: 20cv | P30: 3535rpm | Q30: WEG | S30: RJB-05451 | T30: 220 / 380 | U30: 50.3 / 29.1 | X30: MONOBLOCO | Y30: RJB-05513 | Z30: Ingersoll-Dresser Pumps | AA30: 2 | AB30: 165,1 mm | AC30: ABRIGADA | AD30: NÃO | AF30: HORIZONTAL | AH30: CONVENSIONAL | AP30: 413110570 | AQ30: 5028144 | AR30: 0 | AS30: AGUA - BOOSTER - CAICARA | AT30: PCA OITICICA SN FT52 | AU30: 100MM | AV30: 75MMM | AW30: 0 | AX30: 0 | AY30: 0 | AZ30: 0 | BJ30: RJB-18806 | BK30: INVERSOR DE FREQUÊNCIA | BL30: DANFOSS | BM30: FC-101 | BN30: 22KW/30HP | BO30: RJB-18807 | BP30: NÃO | BR30: 1 MCA | BS30: 1 MCA | BU30: 0 | BV30: 0 | BW30: SIM | BY30: EM MARCHA | BZ30: 0 | CA30: 0 | CB30: 0 | CC30: 0 | CD30: Rua AnambA - Rua Angelina - Rua Bacuri - Rua Eucalipto - Rua GoiAs - Rua Jaras - Rua JatobA - Rua JequitibA Rosa - Rua JequitibA - Rua Leopoldo Machado - Rua Massaranduba - Rua Ocabu - Rua Oiti - Rua Pequim
A31: CAIXA VELHA | B31: =_xlfn.XLOOKUP(A:A,'Dados Elevatórias'!D:D,'Dados Elevatórias'!B:B) -> PL-RJB-EAT0011 | C31: =_xlfn.XLOOKUP(B:B,'Dados Elevatórias'!B:B,'Dados Elevatórias'!C:C) -> EAT | D31: BAIXADA 2 | E31: R. Tab. Murilo Costa, 140 - Centro | F31: Centro | G31: NOVA IGUAÇU | H31: 26255-130 | I31: =_xlfn.XLOOKUP(B31,COORDENADAS!A:A,COORDENADAS!B:B) -> -22.7631 | J31: =_xlfn.XLOOKUP(B31,COORDENADAS!A:A,COORDENADAS!C:C) -> -43.4531 | L31: =_xlfn.XLOOKUP(A:A,'RELAÇÃO ANTIGA'!A:A,'RELAÇÃO ANTIGA'!J:J) -> FORMAL | M31: 1 | N31: OPERACIONAL | O31: 40cv | P31: 3550rpm | Q31: WEG | S31: RJB-12016 | T31: 220 / 380 | U31: 97.6 / 56.5 | Y31: RJB-04532 | AA31: 2 | AC31: ABRIGADA | AD31: NÃO | AF31: VERTICAL | AH31: INLINE | AN31: =_xlfn.XLOOKUP(A:A,'RELAÇÃO ANTIGA'!A:A,'RELAÇÃO ANTIGA'!AC:AC,X) -> 220V | AP31: 411457794 | AQ31: 7516646 | AR31: 0 | AS31: AGUA - ELEV - BRASILIA | AT31: R TABE MURILO COSTA 141 | AU31: 100MM | AV31: 150MM | AW31: 0 | AX31: 0 | AY31: 0 | AZ31: 0 | BJ31: RJB-00159 | BK31: INVERSOR DE FREQUÊNCIA | BL31: DANFOSS | BM31: VLT Aqua Drive | BO31: RJB-16854 | BP31: SIM | BR31: 1 MCA | BS31: 1 MCA | BT31: 80MCA | BU31: 0 | BV31: 0 | BW31: SIM | BY31: EM MARCHA | BZ31: 0 | CA31: 0 | CB31: 0 | CC31: 0 | CD31: Rua 15 de Agosto - Rua 1º de Maio - Rua 23 de Abril - Rua 25 de Dezembro - Rua AntOnio de Almeida - Rua da Liberdade - Rua das Mangueiras - Rua do GDRM-11tAo - Rua Dona Rita - Rua Dr. Tibau - Rua Juiz Antonio Belot de Souza - Rua Rangel Pestana - Rua Rejane Pedro Equi - Rua SebastiAo dos Reis - Rua SebastiAo Herculano de Matos (parte) - Rua TabeliAo Murilo Costa (parte) - Rua Zilda - Travessa Dr. Tibau - Travessa Maria JosE - Travessa Shirley - Travessa Soares
A32: CABUÇU BAIXO | B32: =_xlfn.XLOOKUP(A:A,'Dados Elevatórias'!D:D,'Dados Elevatórias'!B:B) -> PL-RJB-EAT0847 | C32: =_xlfn.XLOOKUP(B:B,'Dados Elevatórias'!B:B,'Dados Elevatórias'!C:C) -> EAT | D32: BAIXADA 2 | E32: Av. Abílio Augusto Távora, 5157 - Vl Valverde, Nova Iguaçu - RJ, 26290-717 | F32: Vl Valverde | G32: NOVA IGUAÇU | H32: =_xlfn.XLOOKUP(B:B,'Dados Elevatórias'!B:B,'Dados Elevatórias'!G:G) -> 26290-717 | I32: =_xlfn.XLOOKUP(B32,COORDENADAS!A:A,COORDENADAS!B:B) -> -22.7759 | J32: =_xlfn.XLOOKUP(B32,COORDENADAS!A:A,COORDENADAS!C:C) -> -43.5315 | M32: 1 | N32: OPERACIONAL | O32: 75CV | P32: 3500rpm | Q32: HELIBOMBAS | T32: 220V / 380V | U32: 187,1A/108,3A | X32: HAM-75/305-1 | Z32: HELIBOMAS | AC32: ABRIGADA | AD32: SIM | AF32: ANFÍBIA | AI32: 750M³/H | AJ32: 16,5MCA | AN32: 380V | AP32: 0 | AQ32: 0 | AR32: 0 | AS32: 0 | AT32: 0 | AU32: 0 | AV32: 0 | AW32: 0 | AX32: 0 | AY32: 0 | AZ32: 0 | BJ32: RJB-23752 | BK32: INVERSOR DE FREQUÊNCIA | BL32: ABB | BN32: 145/124 A | BO32: RJB-24088 | BP32: SIM | BR32: 0 | BS32: 0 | BT32: 0 | BU32: 0 | BV32: 0 | BY32: 0 | BZ32: 0 | CA32: 0 | CB32: 0 | CC32: 0 | CD32: 0
A33: CANADENSE | B33: =_xlfn.XLOOKUP(A:A,'Dados Elevatórias'!D:D,'Dados Elevatórias'!B:B) -> PL-RJB-EAT0056 | C33: =_xlfn.XLOOKUP(B:B,'Dados Elevatórias'!B:B,'Dados Elevatórias'!C:C) -> EAT | D33: BAIXADA 2 | E33: Rua Gen. Olímpio da Fonseca, 917 - Paiol de Pólvora, Nilópolis - RJ, 26545-470 | F33: Paiol de Pólvora | G33: NILÓPOLIS | H33: =_xlfn.XLOOKUP(B:B,'Dados Elevatórias'!B:B,'Dados Elevatórias'!G:G) -> 26545-470 | I33: =_xlfn.XLOOKUP(B33,COORDENADAS!A:A,COORDENADAS!B:B) -> -22.8137 | J33: =_xlfn.XLOOKUP(B33,COORDENADAS!A:A,COORDENADAS!C:C) -> -43.3945 | L33: =_xlfn.XLOOKUP(A:A,'RELAÇÃO ANTIGA'!A:A,'RELAÇÃO ANTIGA'!J:J) -> INFORMAL | M33: 1 | N33: OPERACIONAL | O33: 4,5CV | P33: 3450RPM | Q33: VANBRO | R33: VMSP | T33: 220V / 380V / 440V | U33: 13.8/8.0 | X33: VBSP.67X.02.045.Y | Z33: VANBRO | AA33: 2 | AB33: 140mm | AC33: SUBMERSA | AF33: SUBMERSA VERTICAL | AH33: SUBMERSA | AI33: 24m³/h | AJ33: 33,5mca | AL33: RESERVA FRIA | AM33: 5501608 | AN33: 220V | AP33: 420149824 | AQ33: 5404178 | AR33: 0 | AS33: AGUA - BOOSTER - UNIVERSAL CANADENSE | AT33: R JOAO DIEZ LIMA 97 | AU33: 0 | AV33: 0 | AW33: 0 | AX33: 0 | AY33: 0 | AZ33: 0 | BK33: SOFT STARTER | BL33: WEG | BM33: SSW07 | BP33: NÃO | BR33: 0 | BS33: 0 | BT33: 0 | BU33: 0 | BV33: 0 | BW33: SIM | BY33: EM MARCHA | BZ33: 0 | CA33: 0 | CB33: 0 | CC33: PAIOL | CD33: Rua OlImpio da Fonseca (Trecho Rua Major Leite de Castro A Rua Canadense), Rua Dona Vicentina (Trecho Rua Carlos de S. Fernandes A Rua Manoel Pinto), Rua Canadense (Trecho Rua JosE Couto GuimarAes A Rua Manoel Pinto, Rua Jorge LOssio, Rua Carlos de S. Fernandes (Trecho Rua Dona Vicentina A Rua Canadense) e pequenas Vilas desse trecho.
A34: CARAMUJOS | B34: =_xlfn.XLOOKUP(A:A,'Dados Elevatórias'!D:D,'Dados Elevatórias'!B:B) -> PL-RJB-EAT0835 | C34: =_xlfn.XLOOKUP(B:B,'Dados Elevatórias'!B:B,'Dados Elevatórias'!C:C) -> EAT | D34: BAIXADA 2 | E34: R. Cruz Alta, 2-8 - Parque do Ipanema, Queimados - RJ, 26320-330 | F34: Parque do Ipanema | G34: QUEIMADOS | H34: =_xlfn.XLOOKUP(B:B,'Dados Elevatórias'!B:B,'Dados Elevatórias'!G:G) -> 26320-330 | I34: =_xlfn.XLOOKUP(B34,COORDENADAS!A:A,COORDENADAS!B:B) -> -22.7063 | J34: =_xlfn.XLOOKUP(B34,COORDENADAS!A:A,COORDENADAS!C:C) -> -43.5825 | M34: 1 | N34: OPERACIONAL | O34: 12.5CV | P34: 3535rpm | Q34: WEG | R34: 132M | S34: RJB-21905 | T34: 220 / 380 / 440 | U34: 30.2 / 17.5 / 15.1 | Y34: RJB-21906 | Z34: W22 premium | AA34: 2 | AB34: 132mm | AC34: ABRIGADA | AD34: NÃO | AF34: ANFÍBIA | AH34: CONVENSIONAL | AN34: =_xlfn.XLOOKUP(A:A,'RELAÇÃO ANTIGA'!A:A,'RELAÇÃO ANTIGA'!AC:AC,X) -> 220v | AP34: 0 | AQ34: 0 | AR34: 0 | AS34: 0 | AT34: 0 | AU34: 0 | AV34: 0 | AW34: 0 | AX34: 0 | AY34: 0 | AZ34: 0 | BK34: INVERSOR DE FREQUÊNCIA | BP34: SIM | BR34: 0 | BS34: 0 | BT34: 0 | BU34: 0 | BV34: 0 | BY34: 0 | BZ34: 0 | CA34: 0 | CB34: 0 | CC34: 0 | CD34: 0
A35: CARLOS SAMPAIO | B35: =_xlfn.XLOOKUP(A:A,'Dados Elevatórias'!D:D,'Dados Elevatórias'!B:B) -> PL-RJB-EAT0822 | C35: =_xlfn.XLOOKUP(B:B,'Dados Elevatórias'!B:B,'Dados Elevatórias'!C:C) -> EAT | D35: BAIXADA 2 | E35: R. Lúcia Maria Piper, 50 - Adrianópolis, Nova Iguaçu - RJ, 26053-075 | F35: Adrianopolis | G35: NOVA IGUAÇU | H35: =_xlfn.XLOOKUP(B:B,'Dados Elevatórias'!B:B,'Dados Elevatórias'!G:G) -> 0 | I35: =_xlfn.XLOOKUP(B35,COORDENADAS!A:A,COORDENADAS!B:B) -> -22.6594 | J35: =_xlfn.XLOOKUP(B35,COORDENADAS!A:A,COORDENADAS!C:C) -> -43.4876 | M35: 1 | N35: OPERACIONAL | O35: 100CV | P35: 1785rpm | Q35: SEW EURODRIVE | S35: RJB-20145 | T35: 220/380/440 | U35: 200 / 131 / 151 | V35: 6317-2Z-C4 | W35: 6315-2RS-C3 | X35: CONJ.GS - 125/400 | Y35: RJB-23961 | Z35: EBARA | AA35: 4 | AB35: 356 | AC35: ABRIGADA | AD35: NÃO | AF35: HORIZONTAL | AH35: CONVENSIONAL | AI35: 275.0 m³/h | AJ35: 55MCA | AL35: Placa | AN35: =_xlfn.XLOOKUP(A:A,'RELAÇÃO ANTIGA'!A:A,'RELAÇÃO ANTIGA'!AC:AC,X) -> 220v | AP35: 0 | AQ35: 0 | AR35: 0 | AS35: 0 | AT35: 0 | AU35: 0 | AV35: 0 | AW35: 0 | AX35: 0 | AY35: 0 | AZ35: 0 | BJ35: RJB-23645 | BK35: INVERSOR DE FREQUÊNCIA | BL35: ABB | BM35: ACO580-01-145A-4 | BN35: 145A | BO35: RJB-23646 | BP35: SIM | BR35: 15 MCA | BS35: 8MCA | BT35: 70 MCA | BU35: 0 | BV35: 0 | BY35: 0 | BZ35: 0 | CA35: 0 | CB35: 0 | CC35: 0 | CD35: 0
A36: CAONZE | B36: =_xlfn.XLOOKUP(A:A,'Dados Elevatórias'!D:D,'Dados Elevatórias'!B:B) -> PL-RJB-EAT0821 | C36: =_xlfn.XLOOKUP(B:B,'Dados Elevatórias'!B:B,'Dados Elevatórias'!C:C) -> EAT | D36: BAIXADA 2 | E36: R. Ver. Hélcio Chambarelli - Caonze, Nova Iguaçu - RJ, 26250-170 | F36: Caonze | G36: NOVA IGUAÇU | H36: =_xlfn.XLOOKUP(B:B,'Dados Elevatórias'!B:B,'Dados Elevatórias'!G:G) -> 26250-170 | I36: =_xlfn.XLOOKUP(B36,COORDENADAS!A:A,COORDENADAS!B:B) -> -22.7665 | J36: =_xlfn.XLOOKUP(B36,COORDENADAS!A:A,COORDENADAS!C:C) -> -43.4429 | M36: 1 | N36: OPERACIONAL | O36: 15cv | P36: 3530rpm | S36: RJB-18613 | AC36: ABRIGADA | AF36: HORIZONTAL | AH36: CONVENSIONAL | AP36: 0 | AQ36: 0 | AR36: 0 | AS36: 0 | AT36: 0 | AU36: 0 | AV36: 0 | AW36: 0 | AX36: 0 | AY36: 0 | AZ36: 0 | BK36: INVERSOR DE FREQUÊNCIA | BP36: NÃO | BR36: 0 | BS36: 0 | BT36: 0 | BU36: 0 | BV36: 0 | BY36: 0 | BZ36: 0 | CA36: 0 | CB36: 0 | CC36: 0 | CD36: 0
A37: CASA DE CUSTÓDIA COTRIN NETO | B37: =_xlfn.XLOOKUP(A:A,'Dados Elevatórias'!D:D,'Dados Elevatórias'!B:B) -> PL-RJB-EAT1016 | C37: =_xlfn.XLOOKUP(B:B,'Dados Elevatórias'!B:B,'Dados Elevatórias'!C:C) -> EAT | D37: BAIXADA 2 | E37: R. Assul, Jd Belo Horizonte, Japeri - RJ, 26480-400 | F37: Jd Belo Horizonte | G37: JAPERI | H37: =_xlfn.XLOOKUP(B:B,'Dados Elevatórias'!B:B,'Dados Elevatórias'!G:G) -> 26480-400 | I37: =_xlfn.XLOOKUP(B37,COORDENADAS!A:A,COORDENADAS!B:B) -> -22.673 | J37: =_xlfn.XLOOKUP(B37,COORDENADAS!A:A,COORDENADAS!C:C) -> -43.5826 | M37: 1 | N37: OPERACIONAL | O37: 12.5CV | P37: 3460rpm | Q37: WEG | R37: E56J | S37: RJB-30668 | T37: 220 / 380 | U37: 7.81 / 4.52 | AC37: ABRIGADA | AF37: HORIZONTAL | AH37: CONVENSIONAL | AP37: 0 | AQ37: 0 | AR37: 0 | AS37: 0 | AT37: 0 | AU37: 0 | AV37: 0 | AW37: 0 | AX37: 0 | AY37: 0 | AZ37: 0 | BK37: PARTIDA DIRETA | BP37: NÃO | BR37: 0 | BS37: 0 | BT37: 0 | BU37: 0 | BV37: 0 | BY37: 0 | BZ37: 0 | CA37: 0 | CB37: 0 | CC37: 0 | CD37: 0
A38: CEFET | B38: PL-RJB-EAT0108 | C38: EAT | D38: BAIXADA 2 | E38: R. Ademar Guimarães, 17 - Jardim Monte Castelo, Nova Iguaçu - RJ, 26041-600 | F38: Santa Rita | G38: NOVA IGUAÇU | H38: =_xlfn.XLOOKUP(B:B,'Dados Elevatórias'!B:B,'Dados Elevatórias'!G:G) -> 26041-271 | I38: =_xlfn.XLOOKUP(B38,COORDENADAS!A:A,COORDENADAS!B:B) -> -22.7009 | J38: =_xlfn.XLOOKUP(B38,COORDENADAS!A:A,COORDENADAS!C:C) -> -43.4645 | L38: =_xlfn.XLOOKUP(A:A,'RELAÇÃO ANTIGA'!A:A,'RELAÇÃO ANTIGA'!J:J) -> FORMAL | M38: 1 | N38: OPERACIONAL | O38: 7,5cv | P38: 3515rpm | AC38: SUBMERSA | AN38: 220V | AP38: 420268697 | AQ38: 6617672-7 | AR38: 0 | AS38: AGUA - BOOSTER - CEFET | AT38: EST ADRIANOPOLIS SN EF2174 | AU38: 0 | AV38: 0 | AW38: 0 | AX38: 0 | AY38: 1800 | AZ38: 0 | BK38: SOFT STARTER | BL38: WEG | BM38: SSW07 | BP38: NÃO | BR38: 0 | BS38: 0 | BT38: 0 | BU38: 0 | BV38: 0 | BW38: SIM | BY38: EM MARCHA | BZ38: 35 | CA38: 46 | CB38: 0 | CC38: 0 | CD38: 0
A39: CHATUBA | B39: =_xlfn.XLOOKUP(A:A,'Dados Elevatórias'!D:D,'Dados Elevatórias'!B:B) -> PL-RJB-EAT0741 | C39: =_xlfn.XLOOKUP(B:B,'Dados Elevatórias'!B:B,'Dados Elevatórias'!C:C) -> EAT | D39: BAIXADA 2 | E39: Rua Marques Canário, 667 - Chatuba - Mesquita - RJ, 26585-520 | F39: Chatuba | G39: MESQUITA | H39: =_xlfn.XLOOKUP(B:B,'Dados Elevatórias'!B:B,'Dados Elevatórias'!G:G) -> 26585-520 | I39: =_xlfn.XLOOKUP(B39,COORDENADAS!A:A,COORDENADAS!B:B) -> -22.804 | J39: =_xlfn.XLOOKUP(B39,COORDENADAS!A:A,COORDENADAS!C:C) -> -43.4408 | L39: =_xlfn.XLOOKUP(A:A,'RELAÇÃO ANTIGA'!A:A,'RELAÇÃO ANTIGA'!J:J) -> INFORMAL | M39: 1 | N39: OPERACIONAL | O39: 100cv | P39: 3500 | R39: 250S/M | S39: RJB-21052 | T39: 220V / 380V | X39: 4x3x10 | Y39: RJB-30605 | AA39: 10 | AB39: 254mm | AC39: TUBULÂO | AD39: SIM | AE39: JM | AF39: VERTICAL | AG39: FC | AH39: INLINE | AI39: 129,25 M³/H | AJ39: 80MCA | AN39: MT | AP39: 400139840 | AQ39: 1999622 | AR39: 0 | AS39: AGUA - BOOSTER - CHATUBA | AT39: R MARQUES DE CANARIO SN LT8 | AU39: 0 | AV39: 0 | AW39: 0 | AX39: 0 | AY39: 0 | AZ39: 0 | BJ39: RJB-11687 | BK39: INVERSOR DE FREQUÊNCIA | BL39: WEG | BM39: SSW 11 | BN39: 89A | BO39: RJB-11695 | BP39: SIM | BR39: < 1 MCA | BS39: 0 | BT39: 0 | BU39: 0 | BV39: 0 | BY39: EM MARCHA | BZ39: 0 | CA39: 0 | CB39: 0 | CC39: CHATUBA | CD39: Rua atendidas: Arizona, Plaza, AstOria, Toneleiros, AssU, Adolfo de Albuquerque, IcaraI, Aquidauana, Itaqui, AbaetE e Boatafogo. Comunidade da Chatuba
A40: CITROPOLIS | B40: =_xlfn.XLOOKUP(A:A,'Dados Elevatórias'!D:D,'Dados Elevatórias'!B:B) -> PL-RJB-EAT0833 | C40: =_xlfn.XLOOKUP(B:B,'Dados Elevatórias'!B:B,'Dados Elevatórias'!C:C) -> EAT | D40: BAIXADA 2 | E40: R. Tóquio, 38 - Citrópolis, Japeri - RJ, 26425-340 | F40: Citrópolis | G40: JAPERI | H40: =_xlfn.XLOOKUP(B:B,'Dados Elevatórias'!B:B,'Dados Elevatórias'!G:G) -> 26425-340 | I40: =_xlfn.XLOOKUP(B40,COORDENADAS!A:A,COORDENADAS!B:B) -> -22.682 | J40: =_xlfn.XLOOKUP(B40,COORDENADAS!A:A,COORDENADAS!C:C) -> -43.6049 | M40: 1 | N40: OPERACIONAL | O40: 10CV | P40: 3535 RPM | Q40: WEG | R40: 132S | S40: RJB-21460 | T40: 220V / 380V / 440V | U40: 25.0 / 14.5 / 12.5 | V40: 6309-Z-C3 | W40: 6207-ZZ | X40: THS-18 TRIF IP5 | Y40: RJB-21480 | Z40: EBARA | AA40: 2 | AB40: 179mm | AC40: ABRIGADA | AF40: HORIZONTAL | AH40: CONVENSIONAL | AI40: 30m3/h | AJ40: 55mca | AL40: placa | AN40: VERIFICAR | AO40: VERIFICAR | AU40: 0 | AV40: 0 | AW40: 0 | AX40: 0 | AY40: 0 | AZ40: 0 | BJ40: RJB-23511 | BK40: INVERSOR DE FREQUÊNCIA | BL40: ABB | BM40: ACS310-03E-34A1-2 | BN40: 7,5KW - 10HP | BO40: RJB-23515 | BP40: SIM | BR40: 0 | BS40: 0 | BT40: 0 | BU40: 0 | BV40: 0 | BY40: 0 | BZ40: 0 | CA40: 0 | CB40: 0 | CC40: 0 | CD40: 0
...

Sheet Planilha1
A2: SÃO SIMÃO | B2: Cadastrar
A3: Praça do Cabuçu | B3: Cadastrar
A4: Paulo Miranda | B4: Cadastrar
A5: CAIXA VELHA | B5: PL-RJB-EAT0011 | C5: =B5&" - "&A5 -> PL-RJB-EAT0011 - CAIXA VELHA
A6: SANTO ANTÔNIO | B6: PL-RJB-EAT0014 | C6: =B6&" - "&A6 -> PL-RJB-EAT0014 - SANTO ANTÔNIO
A7: ROLDAO GONCALVES | B7: PL-RJB-EAT0017 | C7: =B7&" - "&A7 -> PL-RJB-EAT0017 - ROLDAO GONCALVES
A8: PADRE VIEIRA | B8: PL-RJB-EAT0022 | C8: =B8&" - "&A8 -> PL-RJB-EAT0022 - PADRE VIEIRA
A9: NILO PECANHA (CEMITERIO) | B9: PL-RJB-EAT0024 | C9: =B9&" - "&A9 -> PL-RJB-EAT0024 - NILO PECANHA (CEMITERIO)
A10: MENA BARRETO | B10: PL-RJB-EAT0030 | C10: =B10&" - "&A10 -> PL-RJB-EAT0030 - MENA BARRETO
A11: MELVIN JONES | B11: PL-RJB-EAT0031 | C11: =B11&" - "&A11 -> PL-RJB-EAT0031 - MELVIN JONES
A12: MAURICIA BORGES | B12: PL-RJB-EAT0032 | C12: =B12&" - "&A12 -> PL-RJB-EAT0032 - MAURICIA BORGES
A13: MORRO DA MOENDA | B13: PL-RJB-EAT0039 | C13: =B13&" - "&A13 -> PL-RJB-EAT0039 - MORRO DA MOENDA
A14: MANOEL REIS | B14: PL-RJB-EAT0040 | C14: =B14&" - "&A14 -> PL-RJB-EAT0040 - MANOEL REIS
A15: BOOSTER POSSE | B15: PL-RJB-EAT0042 | C15: =B15&" - "&A15 -> PL-RJB-EAT0042 - BOOSTER POSSE
A16: LUCIO TAVARES | B16: PL-RJB-EAT0043 | C16: =B16&" - "&A16 -> PL-RJB-EAT0043 - LUCIO TAVARES
... A122: RESERVATÓRIO CABUÇU ALTO | B122: PL-RJB-RES0113 | C122: =B122&" - "&A122 -> PL-RJB-RES0113 - RESERVATÓRIO CABUÇU ALTO
A123: AMBAÍ
A124: MORRO DA PAZ
A125: COLOMBO
A126: DONA AFRA
A127: CARLOS MONSANTE
A128: BEIRA RIO
A129: NÉLIO CHAMBARELLI
A130: MESSIAS
A131: CHACRINHA
A132: NOVA CIDADE
A133: BOA ESPERANÇA
A134: TINGUAZINHO
... A142: BNH 2

Sheet RELAÇÃO BOOSTERS
A1: ELEVATÓRIA | B1: PLANTA | C1: GRUPO | D1: INFLUÊNCIA | E1: VAZÃO APROXIMADA (m³/h) | F1: AMT (MCA) | G1: PRESSÃO DE SUCÇÃO | H1: PRESSÃO DE RECALQUE | I1: DIÂMETRO DA TUBULAÇÃO | J1: TAG DO MOTOR | K1: POTÊNCIA DO MOTOR (CV) | L1: RPM | M1: CARCAÇA DO MOTOR | N1: MANCAIS (LA / LOA) | O1: PONTA DO EIXO | P1: TAG DA BOMBA | Q1: MODELO DA BOMBA | R1: MARCA DA BOMBA | S1: Ø ROTOR | T1: FORMA CONSTRUTIVA DA BOMBA | U1: BOMBA DRENO (Sim/Não) | V1: TENSÃO (V) | W1: CORRENTE (A) | X1: TIPO DE ACIONAMENTO | Y1: FABRICANTE DO ACIONAMENTO | Z1: MODELO ACIONAMENTO
A2: BOOSTER AUSTIN | B2: =_xlfn.XLOOKUP(A:A,'Dados Elevatórias'!D:D,'Dados Elevatórias'!B:B) -> PL-RJB-EAT0695 | C2: 1 | K2: 400cv | L2: 1190rpm
A3: BOOSTER AUSTIN | B3: =_xlfn.XLOOKUP(A:A,'Dados Elevatórias'!D:D,'Dados Elevatórias'!B:B) -> PL-RJB-EAT0695 | C3: 2 | K3: 400cv | L3: 1190rpm
A4: BOOSTER AUSTIN | B4: =_xlfn.XLOOKUP(A:A,'Dados Elevatórias'!D:D,'Dados Elevatórias'!B:B) -> PL-RJB-EAT0695 | C4: 3 | K4: 400cv | L4: 1190rpm
A5: BOOSTER BRASÍLIA | B5: =_xlfn.XLOOKUP(A:A,'Dados Elevatórias'!D:D,'Dados Elevatórias'!B:B) -> PL-RJB-EAT1005 | C5: 1 | K5: 100cv | L5: 1783 rpm
A6: BOOSTER BRASÍLIA | B6: =_xlfn.XLOOKUP(A:A,'Dados Elevatórias'!D:D,'Dados Elevatórias'!B:B) -> PL-RJB-EAT1005 | C6: 2 | K6: 100cv | L6: 1783 rpm
A7: BOOSTER BRASÍLIA | B7: =_xlfn.XLOOKUP(A:A,'Dados Elevatórias'!D:D,'Dados Elevatórias'!B:B) -> PL-RJB-EAT1005 | C7: 3 | K7: 100cv | L7: 1783 rpm
A8: BOOSTER CABUÇU ALTO | B8: =_xlfn.XLOOKUP(A:A,'Dados Elevatórias'!D:D,'Dados Elevatórias'!B:B) -> PL-RJB-EAT0689 | C8: 1 | K8: 50CV | L8: 1770rpm
A9: BOOSTER CABUÇU ALTO | B9: =_xlfn.XLOOKUP(A:A,'Dados Elevatórias'!D:D,'Dados Elevatórias'!B:B) -> PL-RJB-EAT0689 | C9: 2 | K9: 50CV | L9: 1770rpm
A10: BOOSTER CABUÇU ALTO | B10: =_xlfn.XLOOKUP(A:A,'Dados Elevatórias'!D:D,'Dados Elevatórias'!B:B) -> PL-RJB-EAT0689 | C10: 3 | K10: 50CV | L10: 1770rpm
A11: BOOSTER ENGENHEIRO PEDREIRA | B11: =_xlfn.XLOOKUP(A:A,'Dados Elevatórias'!D:D,'Dados Elevatórias'!B:B) -> PL-RJB-EAT0122 | C11: 1 | K11: 200cv | L11: 1790rpm
A12: BOOSTER ENGENHEIRO PEDREIRA | B12: =_xlfn.XLOOKUP(A:A,'Dados Elevatórias'!D:D,'Dados Elevatórias'!B:B) -> PL-RJB-EAT0122 | C12: 2 | K12: 200cv | L12: 1790rpm
A13: BOOSTER JK | B13: =_xlfn.XLOOKUP(A:A,'Dados Elevatórias'!D:D,'Dados Elevatórias'!B:B) -> PL-RJB-EAT0746 | C13: 1 | K13: 450CV | L13: 1793rpm | P13: RJB-07474
A14: BOOSTER JK | B14: =_xlfn.XLOOKUP(A:A,'Dados Elevatórias'!D:D,'Dados Elevatórias'!B:B) -> PL-RJB-EAT0746 | C14: 2 | K14: 450CV | L14: 1793rpm
A15: BOOSTER JK | B15: =_xlfn.XLOOKUP(A:A,'Dados Elevatórias'!D:D,'Dados Elevatórias'!B:B) -> PL-RJB-EAT0746 | C15: 3 | K15: 250CV | L15: 1790rpm
A16: BOOSTER JK | B16: =_xlfn.XLOOKUP(A:A,'Dados Elevatórias'!D:D,'Dados Elevatórias'!B:B) -> PL-RJB-EAT0746 | C16: 4 | K16: 250CV | L16: 1793 a 1850 rpm
A17: BOOSTER POSSE | B17: =_xlfn.XLOOKUP(A:A,'Dados Elevatórias'!D:D,'Dados Elevatórias'!B:B) -> PL-RJB-EAT0042 | C17: 1 | K17: 175cv | L17: 1791rpm
A18: BOOSTER POSSE | B18: =_xlfn.XLOOKUP(A:A,'Dados Elevatórias'!D:D,'Dados Elevatórias'!B:B) -> PL-RJB-EAT0042 | C18: 2 | K18: 175cv | L18: 1791rpm
A19: BOOSTER POSSE | B19: =_xlfn.XLOOKUP(A:A,'Dados Elevatórias'!D:D,'Dados Elevatórias'!B:B) -> PL-RJB-EAT0042 | C19: 3 | K19: 175cv | L19: 1791rpm
A20: BOOSTER POSSE | B20: =_xlfn.XLOOKUP(A:A,'Dados Elevatórias'!D:D,'Dados Elevatórias'!B:B) -> PL-RJB-EAT0042 | C20: 4 | K20: 175cv | L20: 1791rpm
A21: MESQUITA G1 | B21: =_xlfn.XLOOKUP(A:A,'Dados Elevatórias'!D:D,'Dados Elevatórias'!B:B) -> PL-RJB-EAT0086 | C21: 1 | K21: 100cv | L21: 3510rpm
A22: MESQUITA G1 | B22: =_xlfn.XLOOKUP(A:A,'Dados Elevatórias'!D:D,'Dados Elevatórias'!B:B) -> PL-RJB-EAT0086 | C22: 2 | K22: 100CV | L22: 3560rpm

Sheet INFORMATIVO
C4: TABELAS
C5: CARACTERÍSTICAS DA ÁREA | D5: FORMAL | E5: INFORMAL | F5: NOVA
C6: TIPO DE ACIONAMENTO | D6: SOFT STARTER | E6: INVERSOR DE FREQUÊNCIA | F6: PARTIDA DIRETA | G6: ENT. TRIANGULO
C7: SIM OU NÃO | D7: SIM | E7: NÃO
C8: Ponta de eixo | D8: CONVENSIONAL | E8: JET PUMP | F8: JM | G8: JP | H8: ESP
C9: Tipo construtivo Elev. | D9: CONTAINER | E9: SUBMERSA | F9: TUBULÂO | G9: ABRIGADA | H9: CASINHA | I9: ANFÍBIA
C10: FLANGE | D10: CONVENSIONAL | E10: FC | F10: FF
C11: FORMA CONSTRUTIVA DA BOMBA | D11: CONVENSIONAL | E11: INLINE | F11: HORIZONTAL | G11: DELTA | H11: SUBMERSA | I11: SUBMERSIVEL | J11: AUTOESCORVANTE | K11: ANFÍBIA
C12: TIPO DE MONTAGEM MOTOR | D12: ANFÍBIA | E12: HORIZONTAL | F12: VERTICAL | G12: SUBMERSA VERTICAL
C13: FABRICANTE ACIONAMENTO | D13: DANFOSS | E13: ABB | F13: WEG | G13: POWER ELETRONICS | H13: SCHNEIDER | I13: SIEMENS
C14: TENSÃO | D14: 220V | E14: 380V | F14: 440V | G14: 380V / 440V | H14: 220V / 380V | I14: 220V / 440V | J14: 220V / 380V / 440V | K14: 440V / 760v

Sheet INDICADORES
A1: =COUNTIFS('RELAÇÃO DE ELEVATÓRIAS'!M:M, "2") -> 12 | B1: =COUNTIFS('RELAÇÃO DE ELEVATÓRIAS'!M:M, "3") -> 6 | C1: =COUNTIFS('RELAÇÃO DE ELEVATÓRIAS'!M:M, "4") -> 2 | D1: =COUNTIFS('RELAÇÃO DE ELEVATÓRIAS'!M:M, "5") -> 0 | E1: =SUM(A1:D1) -> 20
F9: Total de Elevatórias | G9: Elevatórias Novas | H9: Elevatórias de esgoto | I9: Com CLT | J9: Sem CLP
F10: =COUNTA('RELAÇÃO DE ELEVATÓRIAS'!A3:A191)-E1 -> 140 | G10: =COUNTA('NOVAS ELEVATÓRIAS'!D2:D87) -> 29 | H10: 10 | I10: 54 | J10: =COUNTIF('RELAÇÃO DE ELEVATÓRIAS'!BP:BP,"NÃO") -> 52

Sheet RELAÇÃO ANTIGA
A1: ELEVATORIAS | B1: PLANTA | C1: TIPO | D1: SUPERITENDENCIA | E1: ENDEREÇO | F1: BAIRRO | H1: MUNICIPIO | I1: CEP | J1: CARACTERÍSTICAS DA ÁREA | K1: GRUPO | L1: FUNÇÃO | M1: DADOS DO EQUIPAMENTO INSTALADO | AC1: ALIMENTAÇÃO | AE1: DADOS DA CONCESSIONÁRIA DE ENERGIA | AJ1: DIAMETRO DA TUBULACAO | AN1: POPULAÇÃO BENEFICIADA EM HABITANTES | AO1: DOMICILIOS | AP1: D A D O S E T E S T E S A T U A L I Z A D O | AY1: D A D O S E T E S T E S A N T I G O | BH1: PAINEL | CC1: AUTOMAÇÃO | CF1: TOMADA DE PRESSAO | CH1: ELETRODOS | CK1: TIPO DE RECALQUE | CL1: COTA NA ELEVATORIA | CM1: COTA MAXIMA | CN1: DISTANCIA DA ELEV. A COORDENACAO | CO1: COMUNIDADES / HOSPITAIS / LOCALIDADES IMPORTANTES ABASTECIDAS | CP1: AREA DE INFLUENCIA
